File: Data availability/00_STD_IN718_HT4X.xrdml
<?xml version="1.0" encoding="UTF-8"?>
<xrdMeasurements xmlns="http://www.xrdml.com/XRDMeasurement/1.6" xmlns:xsi="http://www.w3.org/2001/XMLSchema-instance" xsi:schemaLocation="http://www.xrdml.com/XRDMeasurement/1.6 http://www.xrdml.com/XRDMeasurement/1.6/XRDMeasurement.xsd" status="Completed">
	<comment>
		<entry>Configuration=reflection - transmission spinner, Owner=User-1, Creation date=10/26/2007 2:30:26 PM</entry>
		<entry>Goniometer=PW3050/60 (Theta/Theta); Minimum step size 2Theta:0.001; Minimum step size Omega:0.001</entry>
		<entry>Sample stage=Reflection-Transmission Spinner PW3064/60; Minimum step size Phi:0.1</entry>
		<entry>Diffractometer system=XPERT-PRO</entry>
		<entry>Measurement program=C:\PANalytical\Data Collector\Programs\00_STD_IN718.xrdmp, Identifier={28380439-0F33-476B-A426-78B1F912C0F4}</entry>
		<entry>Batch program=C:\PANalytical\Data Collector\Programs\00_patch_IN718.xrdmp, Identifier={40C978E3-ABC2-4E6C-9A3B-A5D759AE5D9D}</entry>
	</comment>
	<sample type="To be analyzed">
		<id></id>
		<name></name>
		<preparedBy></preparedBy>
	</sample>
	<xrdMeasurement measurementType="Scan" status="Completed" sampleMode="Reflection">
		<comment>
			<entry>20-130 angle .004 step 30s </entry>
			<entry>PHD Lower Level = 5.34 (keV), PHD Upper Level = 11.09 (keV)</entry>
		</comment>
		<usedWavelength intended="K-Alpha 1">
			<kAlpha1 unit="Angstrom">1.7890100</kAlpha1>
			<kAlpha2 unit="Angstrom">1.7929000</kAlpha2>
			<kBeta unit="Angstrom">1.6208300</kBeta>
			<ratioKAlpha2KAlpha1>0.5000</ratioKAlpha2KAlpha1>
		</usedWavelength>
		<incidentBeamPath>
			<radius unit="mm">240.00</radius>
			<xRayTube id="1010042" name="Empyrean Co LFF (9430 033 7600x) DK417097">
				<tension unit="kV">40.0</tension>
				<current unit="mA">45.0</current>
				<anodeMaterial>Co</anodeMaterial>
				<focus type="Line">
					<length unit="mm">12.0</length>
					<width unit="mm">0.4</width>
					<takeOffAngle unit="deg">6.0</takeOffAngle>
				</focus>
			</xRayTube>
			<filter id="20010003" name="Beta-filter Iron">
				<material>Fe</material>
				<thickness unit="mm">0.016</thickness>
			</filter>
			<sollerSlit id="21010002" name="Soller slits 0.04 rad.">
				<opening unit="rad">0.0400</opening>
			</sollerSlit>
			<mask id="22080002" name="Fixed incident beam mask 10 mm">
				<width unit="mm">6.60</width>
			</mask>
			<antiScatterSlit id="22010002" name="Fixed slit 2°" xsi:type="fixedAntiScatterSlitType">
				<height unit="mm">3.03</height>
			</antiScatterSlit>
			<divergenceSlit id="22010001" name="Fixed slit 4°" xsi:type="fixedDivergenceSlitType">
				<distanceToSample unit="mm">140.00</distanceToSample>
				<height unit="mm">5.88</height>
			</divergenceSlit>
		</incidentBeamPath>
		<sampleMovement xsi:type="spinningSampleMovementType">
			<spinnerRevolutionTime unit="seconds">4.0</spinnerRevolutionTime>
		</sampleMovement>
		<diffractedBeamPath>
			<radius unit="mm">240.00</radius>
			<antiScatterSlit id="22090005" name="AS slit 6.6 mm (X'Celerator)" xsi:type="fixedAntiScatterSlitType">
				<height unit="mm">6.60</height>
			</antiScatterSlit>
			<sollerSlit id="21010002" name="Soller slits 0.04 rad.">
				<opening unit="rad">0.0400</opening>
			</sollerSlit>
			<detector id="7010013" name="X'Celerator detector" xsi:type="rtmsDetectorType">
				<phd>
					<lowerLevel unit="%">38.5</lowerLevel>
					<upperLevel unit="%">80.0</upperLevel>
				</phd>
				<mode>Scanning</mode>
				<activeLength unit="deg">2.022</activeLength>
			</detector>
		</diffractedBeamPath>
		<scan appendNumber="0" mode="Continuous" scanAxis="Gonio" status="Completed">
			<header>
				<startTimeStamp>2020-03-10T05:15:48-07:00</startTimeStamp>
				<endTimeStamp>2020-03-10T07:07:35-07:00</endTimeStamp>
				<author>
					<name>User</name>
				</author>
				<source>
					<applicationSoftware version="5.4">Data Collector</applicationSoftware>
					<instrumentControlSoftware version="2.2D 20160920">XPERT-PRO</instrumentControlSoftware>
					<instrumentID>0000000011030022</instrumentID>
				</source>
			</header>
			<dataPoints>
				<positions axis="2Theta" unit="deg">
					<startPosition>20.00008891</startPosition>
					<endPosition>129.99783913</endPosition>
				</positions>
				<positions axis="Omega" unit="deg">
					<startPosition>10.00004445</startPosition>
					<endPosition>64.99891957</endPosition>
				</positions>
				<positions axis="Phi" unit="deg">
					<commonPosition>159.9</commonPosition>
				</positions>
				<commonCountingTime unit="seconds">30.250</commonCountingTime>
				<intensities 1186 1307 1230 1150 1202 1196 1229 1190 1228 1281 1242 1186 1219 1267 1253 1293 1228 1220 1261 1267 1218 1287 1250 1264 1213 1203 1230 1152 1234 1241 1244 1247 1243 1269 1253 1205 1292 1238 1259 1242 1255 1231 1230 1245 1213 1294 1271 1229 1248 1190 1227 1270 1190 1233 1201 1174 1178 1173 1204 1207 1202 1230 1221 1196 1177 1239 1186 1225 1253 1215 1232 1182 1252 1175 1192 1236 1236 1215 1271 1206 1238 1234 1242 1262 1252 1247 1204 1231 1190 1224 1232 1221 1199 1266 1298 1193 1208 1216 1211 1096 1204 1222 1205 1239 1283 1272 1192 1188 1210 1239 1241 1171 1232 1178 1175 1232 1204 1165 1228 1244 1225 1193 1207 1151 1222 1233 1143 1182 1188 1236 1252 1228 1205 1206 1215 1178 1229 1208 1215 1138 1283 1269 1222 1224 1192 1247 1280 1215 1209 1168 1258 1207 1197 1194 1172 1219 1227 1228 1165 1209 1195 1172 1223 1166 1177 1173 1233 1179 1178 1229 1215 1209 1221 1233 1262 1199 1222 1174 1173 1203 1229 1164 1194 1238 1251 1176 1098 1210 1195 1139 1187 1205 1241 1204 1248 1179 1176 1228 1179 1196 1209 1187 1123 1221 1232 1205 1182 1209 1176 1172 1220 1186 1165 1210 1178 1114 1184 1204 1128 1196 1153 1211 1154 1227 1175 1129 1274 1095 1262 1133 1196 1230 1150 1200 1151 1171 1225 1177 1204 1213 1182 1114 1201 1126 1161 1192 1223 1138 1208 1238 1185 1162 1214 1191 1199 1186 1195 1142 1187 1193 1165 1184 1149 1159 1249 1116 1133 1187 1151 1220 1190 1149 1140 1103 1242 1200 1195 1170 1182 1171 1142 1142 1195 1073 1179 1193 1128 1213 1167 1177 1179 1195 1156 1126 1136 1228 1223 1184 1130 1171 1171 1160 1211 1154 1211 1170 1160 1204 1174 1109 1199 1196 1125 1206 1162 1108 1078 1157 1163 1134 1177 1173 1160 1121 1122 1167 1174 1146 1128 1221 1206 1145 1139 1188 1202 1216 1157 1149 1215 1204 1147 1196 1181 1135 1108 1147 1101 1157 1140 1180 1150 1124 1222 1131 1221 1181 1124 1136 1194 1170 1173 1159 1179 1201 1194 1199 1192 1163 1167 1205 1103 1134 1119 1160 1154 1160 1152 1172 1164 1156 1124 1171 1165 1168 1241 1190 1179 1213 1210 1196 1209 1074 1147 1229 1152 1166 1140 1152 1158 1151 1179 1182 1150 1184 1125 1130 1053 1154 1128 1117 1143 1171 1064 1229 1219 1145 1156 1181 1174 1135 1206 1130 1176 1182 1156 1176 1168 1176 1200 1181 1199 1199 1090 1170 1173 1135 1194 1185 1100 1145 1143 1124 1138 1079 1105 1208 1136 1124 1096 1173 1151 1173 1177 1164 1193 1210 1188 1187 1243 1134 1196 1186 1185 1163 1163 1136 1142 1187 1195 1192 1167 1125 1171 1121 1189 1125 1138 1160 1210 1177 1095 1067 1197 1166 1181 1130 1149 1161 1202 1129 1158 1106 1129 1164 1100 1158 1156 1092 1161 1136 1138 1095 1146 1126 1107 1165 1109 1201 1143 1167 1188 1140 1123 1129 1074 1138 1200 1144 1109 1118 1176 1104 1144 1160 1167 1124 1115 1083 1163 1139 1171 1153 1124 1180 1172 1125 1178 1108 1145 1143 1110 1117 1172 1087 1125 1190 1119 1075 1241 1161 1125 1094 1032 1121 1149 1116 1194 1148 1137 1158 1164 1096 1122 1139 1135 1089 1102 1120 1102 1119 1102 1102 1092 1157 1200 1129 1093 1153 1102 1161 1131 1136 1128 1131 1148 1084 1142 1084 1073 1089 1180 1137 1150 1065 1146 1140 1066 1203 1129 1145 1172 1092 1130 1128 1133 1170 1115 1115 1120 1054 1122 1075 1089 1103 1093 1188 1163 1150 1143 1143 1093 1133 1153 1100 1138 1192 1161 1149 1130 1176 1173 1149 1075 1162 1159 1162 1132 1180 1200 1235 1100 1105 1125 1144 1117 1195 1079 1130 1136 1187 1103 1136 1120 1160 1188 1148 1098 1140 1146 1176 1093 1144 1142 1040 1162 1107 1104 1181 1117 1131 1161 1146 1140 1140 1094 1074 1081 1098 1186 1144 1153 1145 1164 1216 1087 1042 1142 1083 1152 1132 1094 1061 1115 1145 1120 1173 1102 1148 1181 1195 1145 1133 1164 1177 1091 1083 1130 1132 1140 1150 1201 1114 1150 1174 1175 1118 1100 1213 1095 1101 1166 1064 1168 1145 1132 1050 1139 1088 1139 1160 1116 1079 1080 1170 1164 1180 1122 1084 1197 1126 1140 1134 1096 1225 1144 1161 1097 1125 1137 1144 1111 1167 1162 1095 1194 1146 1098 1098 1178 1147 1117 1176 1130 1182 1152 1115 1134 1136 1103 1095 1147 1123 1145 1150 1117 1131 1070 1116 1100 1105 1171 1126 1152 1135 1176 1082 1189 1142 1060 1117 1105 1112 1051 1056 1074 1114 1104 1092 1079 1150 1101 1082 1147 1161 1097 1145 1158 1130 1143 1111 1118 1076 1121 1143 1158 1135 1077 1128 1174 1139 1159 1106 1073 1101 1067 1076 1215 1185 1102 1081 1205 1117 1108 1086 1180 1045 1160 1162 1160 1130 1120 1114 1078 1181 1144 1143 1178 1126 1096 1163 1189 1181 1115 1146 1136 1160 1154 1192 1165 1165 1103 1122 1130 1177 1165 1232 1148 1180 1158 1209 1102 1086 1138 1210 1190 1115 1144 1154 1214 1091 1174 1047 1161 1204 1235 1109 1118 1156 1134 1177 1095 1139 1138 1165 1152 1191 1151 1158 1154 1134 1204 1100 1164 1091 1118 1117 1167 1078 1173 1087 1148 1151 1095 1112 1194 1077 1173 1109 1150 1122 1135 1067 1121 1124 1150 1091 1130 1137 1102 1157 1175 1129 1190 1134 1153 1140 1122 1200 1200 1083 1172 1075 1090 1165 1138 1153 1170 1175 1188 1077 1117 1153 1100 1154 1161 1098 1137 1140 1089 1144 1165 1131 1157 1192 1139 1150 1166 1137 1171 1090 1084 1110 1136 1216 1135 1065 1186 1200 1120 1135 1108 1110 1190 1114 1144 1103 1143 1149 1142 1159 1158 1149 1128 1116 1123 1174 1133 1157 1117 1131 1133 1097 1120 1164 1218 1089 1148 1088 1111 1135 1065 1154 1105 1125 1038 1105 1098 1166 1102 1134 1126 1048 1095 1050 1117 1081 1142 1097 1126 1133 1111 1119 1145 1151 1138 1120 1144 1159 1114 1110 1102 1182 1101 1112 1088 1055 1124 1147 1143 1162 1089 1055 1138 1101 1139 1069 1078 1080 1140 1068 1123 1133 1056 1111 1131 1079 1095 1110 1115 1079 1084 1136 1100 1100 1114 1107 1124 1093 1070 1102 1115 1118 1149 1128 1084 1117 1091 1105 1165 1124 1070 1124 1152 1168 1093 1081 1174 1078 1148 1064 1129 1072 1084 1119 1083 1049 1123 1042 1139 1065 1135 1147 1167 1095 1080 1097 1101 1030 1095 1054 1115 1086 1047 1096 1079 1056 1139 1081 1076 1132 1064 1106 1191 1143 1066 1058 1175 1109 1142 1132 1092 1147 1041 1097 1087 1078 1129 1091 1102 1133 1097 1170 1073 1137 1117 1118 1076 1094 1112 1041 1005 1108 1122 1107 1106 1108 1062 1150 1105 1066 1097 1084 1095 1061 1024 1083 1055 1135 1052 1112 1092 1144 1078 1119 1149 1049 1059 1087 1091 1092 1056 1116 1093 1108 1132 1111 1112 1089 1093 1064 1149 1048 1081 1068 1092 1094 1179 1121 1047 1076 1061 1139 1111 1098 1067 1114 1146 1087 1174 1067 1125 1092 1049 1143 1065 1045 1081 1114 1093 1100 1072 1080 1063 1120 1104 1104 1177 1103 1156 1124 1188 1148 1167 1111 1094 1105 1078 1139 1131 1173 1116 1178 1111 1102 1110 1194 1052 1118 1132 1114 1179 1135 1157 1194 1140 1152 1119 1184 1205 1094 1132 1151 1136 1140 1229 1233 1109 1112 1164 1164 1174 1114 1171 1143 1157 1097 1175 1148 1173 1130 1177 1175 1231 1135 1236 1160 1128 1149 1165 1132 1163 1189 1203 1133 1162 1170 1139 1185 1142 1142 1176 1200 1070 1115 1173 1123 1163 1097 1207 1140 1066 1171 1196 1143 1151 1131 1159 1111 1083 1063 1168 1122 1223 1206 1209 1172 1193 1074 1185 1117 1172 1098 1201 1125 1096 1149 1092 1179 1152 1134 1131 1146 1147 1215 1103 1134 1269 1133 1122 1149 1168 1131 1204 1180 1167 1202 1218 1279 1105 1260 1134 1139 1173 1153 1204 1163 1170 1109 1231 1179 1207 1118 1168 1163 1164 1232 1184 1152 1219 1095 1190 1211 1163 1107 1159 1162 1165 1108 1129 1093 1148 1103 1116 1199 1154 1087 1132 1167 1177 1188 1178 1048 1204 1091 1119 1135 1100 1149 1172 1115 1122 1128 1202 1166 1149 1109 1116 1119 1068 1087 1145 1130 1122 1137 1147 1105 1112 1106 1092 1066 1102 1131 1125 1118 1087 1153 1074 1143 1095 1083 1133 1106 1091 1102 1100 1093 1137 1097 1086 1095 1166 1083 1090 1094 1056 1134 1048 1135 1088 1139 1090 1122 1105 1109 1042 1160 1143 1082 1139 1093 1083 1126 1084 1104 1090 1153 1055 1134 1148 1166 1125 1105 1118 1149 1138 1120 1149 1027 1103 1105 1134 1070 1083 1138 1131 1068 1146 1095 1093 1133 1075 1048 1080 1077 1172 1126 1117 1133 1114 1075 1048 1075 1118 1091 1108 1120 1117 1121 1038 1106 1083 1089 1125 1108 1083 1090 1095 1125 1038 1102 1055 1109 1087 1139 1086 1068 1089 1036 1096 1116 1100 1087 1050 1086 1118 1052 1074 1061 1055 1112 1123 1106 1069 1130 1123 1090 1107 1098 1098 1131 1066 1159 1123 1103 1121 1103 1103 1082 1068 1066 1193 1078 1089 1084 1124 1025 1059 1090 1103 1102 1156 1104 1073 1055 1109 1151 1105 1115 1103 1036 1062 1100 1125 1092 1102 1049 1072 1034 1020 1040 1100 1052 1065 1137 1094 1065 1055 1062 1103 1091 1112 1111 1106 1090 1120 1106 1072 1076 1087 1060 1083 1066 1117 1103 1049 1150 1105 1102 1055 1044 1131 1142 1104 1016 1081 1024 1052 1061 1061 1061 1137 1092 1050 1088 1039 1024 1076 1111 1063 1094 1114 1104 1143 1070 1106 1082 1079 1081 1081 1060 1061 1008 1142 1064 1077 1045 1075 1031 1080 1089 1040 1070 1089 1068 1023 1151 1132 1090 1059 1065 1152 1146 1091 1052 1070 1065 1084 1178 1055 1060 1103 1060 1080 1131 1074 1112 1076 1126 994 1095 1101 1075 1084 1089 1077 1132 1070 1060 1118 1082 1073 1084 1050 1083 1045 1081 1017 1048 1098 1080 1088 1079 1068 1109 1029 1036 1050 1045 1066 1090 1065 1037 1048 1108 1108 1066 1070 1069 1063 1058 1068 1011 1080 997 1086 1080 1094 1036 1031 1064 1092 1035 1090 1039 1089 1143 1107 1078 1047 1077 1100 1034 1055 1035 1058 1102 1101 1065 1067 1111 1108 1069 1025 1039 1047 1053 988 1050 1053 1007 1086 1076 1135 1067 1039 1020 1041 1033 1068 1097 1067 1086 1046 1058 1059 1021 999 1041 1061 1041 1074 1117 1105 1114 1017 1041 1016 1044 1048 1079 1117 1118 1097 1111 1056 1080 1108 1045 1033 1017 1038 1066 1020 1061 1006 1066 1059 1044 1053 1012 1030 1064 1015 1006 1086 1016 1067 1101 1103 1020 1017 1092 1004 1087 1041 1051 1125 1052 1041 974 1120 1083 1019 1095 1018 1079 1059 1080 1055 1119 1074 1122 1024 1096 1044 1073 1013 1061 1038 1062 1068 1080 1025 1095 1058 1064 1008 997 1073 1070 1007 1059 1070 1017 1040 1052 1101 1110 1007 1034 1009 1105 1115 1050 1040 1096 1109 1114 1048 1097 1089 1070 1098 1080 1073 1078 1042 1095 1079 1037 1070 1075 1132 1087 1096 1021 1064 1039 1080 1053 1095 1115 1052 1042 1058 1046 1093 1106 1069 990 1044 1046 973 1067 1110 1023 1058 1068 1010 1051 1069 1031 1112 1054 1112 1103 999 1093 1047 1067 1016 1083 1070 1030 1117 1064 1042 1052 1083 1040 1048 1073 1010 1066 1074 1105 1059 1108 1047 1004 999 1089 1038 1089 1104 1012 1095 1065 1059 1065 1096 1039 1086 1077 1052 1083 1027 1065 1072 1070 1005 1078 1048 1117 1045 1079 1091 1021 1054 1101 1044 1092 1015 1030 1035 1077 1048 1054 1097 1065 1055 1035 1062 1025 1054 1052 1052 1053 985 1103 1090 1073 1095 1029 1062 1094 1009 1063 1082 1047 1042 1066 1036 1065 1053 996 1079 1058 1072 1066 1031 1048 997 1058 1082 1072 1075 1078 1080 1032 1058 1032 1029 1104 1056 1094 1115 1073 1067 1088 1091 1064 1076 1095 1110 1098 1144 1067 1122 1069 1049 1160 1084 1142 1061 1048 1054 1021 1086 1035 984 1083 1074 1044 1018 1073 1093 1060 1064 1074 1064 1079 1039 1053 1036 1091 1032 1063 1010 1058 1022 1048 1047 1061 1052 1029 969 1098 1029 1067 1047 1012 1060 1107 1091 1038 978 1088 1125 1096 1084 1078 1105 1047 1049 1064 1026 1059 1064 1077 1034 1021 1036 1103 1073 1026 1044 1108 1080 1068 1041 1045 1073 1119 1051 1098 1109 1052 1091 1089 1030 1126 1069 1072 1070 1118 1035 1033 1142 1124 1066 1083 1079 1073 1045 1074 1046 1087 1036 1059 1074 1158 1046 1074 1044 1193 1102 1067 1033 1070 1053 1118 1023 1104 1126 1039 1124 1061 1013 1038 1064 1072 1068 1058 1143 1086 1078 1047 1106 1095 1076 1128 1039 1160 1055 1080 1089 1102 1166 1090 1097 1125 1086 1058 1088 1084 1117 1082 1055 1117 1069 1134 1079 1130 1137 1134 1053 1070 1068 1138 1090 1170 1119 1179 1115 1049 1142 1109 1117 1051 1050 1118 1096 1063 1052 1108 1084 1140 1040 1059 1118 1177 1111 1111 1143 1070 1019 1104 1158 1083 1088 1161 1095 1136 1118 1062 1105 1126 1063 1074 1002 1152 1032 1139 1058 1174 1061 1111 1132 1088 1109 1157 1058 1124 1047 1088 1148 1174 1129 1122 1086 1139 1087 1090 1131 1158 1061 1151 1055 1065 1126 1079 1044 1148 1100 1076 1077 1098 1098 1076 1139 1078 1063 1066 1110 1157 1009 1205 1122 1082 1103 1122 1036 1123 1114 1147 1117 1081 1072 1097 1066 1153 1063 1105 1142 1059 1062 1096 1104 1096 1146 1086 1145 1144 1084 1106 1132 1128 1112 1144 1075 1124 1051 1105 1070 1153 1106 1152 1125 1126 1136 1106 1131 1184 1074 1150 1093 1181 1218 1142 1116 1106 1108 1185 1149 1117 1166 1200 1158 1136 1152 1152 1101 1154 1098 1174 1163 1147 1168 1131 1137 1175 1187 1158 1194 1204 1213 1158 1103 1177 1208 1191 1238 1192 1194 1185 1202 1145 1190 1196 1229 1179 1209 1231 1264 1190 1177 1197 1239 1222 1213 1261 1230 1223 1312 1269 1237 1316 1270 1275 1235 1241 1252 1289 1332 1346 1342 1322 1298 1390 1213 1306 1356 1392 1382 1363 1355 1432 1462 1385 1516 1482 1499 1497 1481 1491 1496 1572 1696 1749 1833 1894 2185 2334 2606 3095 3710 4554 5577 7028 9745 9776 8831 6492 5066 4000 3606 4030 4590 4951 5275 6019 4210 3279 2554 2229 1999 1835 1773 1646 1589 1560 1612 1519 1489 1514 1547 1456 1429 1509 1466 1407 1362 1354 1323 1325 1347 1293 1355 1309 1311 1203 1309 1300 1206 1242 1236 1279 1138 1257 1216 1217 1258 1196 1241 1206 1247 1171 1228 1180 1098 1104 1209 1196 1134 1110 1185 1214 1118 1149 1140 1153 1130 1094 1110 1168 1170 1093 1102 1111 1140 1112 1107 1156 1121 1109 1087 1107 1148 1093 1167 1093 1047 1184 1135 1170 1142 1087 1078 1093 1134 1079 1092 1154 1093 1082 1107 1145 1078 1093 1027 1059 1125 1139 1034 1152 1146 1031 1076 1060 1112 1062 1118 1117 1098 1089 1104 1137 1073 1073 1104 1100 1061 1092 1124 1105 1075 1082 1137 1100 1132 1051 1029 1055 1095 1092 1161 1077 1066 1039 1117 1078 1153 1064 1131 1118 1107 1094 1136 1104 1061 1101 1165 1109 1094 1063 1156 1159 1158 1083 1082 1079 1162 1146 1098 1126 1091 1174 1119 1064 1112 1136 1167 1081 1065 1065 1100 1082 1118 1121 1167 1091 1171 1102 1159 1182 1160 1097 1167 1114 1152 1192 1130 1136 1106 1106 1171 1156 1159 1117 1129 1148 1108 1153 1154 1075 1185 1140 1112 1156 1151 1143 1133 1164 1172 1134 1064 1131 1175 1146 1120 1106 1107 1170 1172 1130 1088 1195 1092 1144 1140 1138 1110 1063 1182 1160 1125 1157 1150 1182 1180 1137 1140 1180 1139 1158 1111 1114 1178 1153 1147 1091 1174 1151 1151 1096 1156 1144 1167 1146 1122 1097 1086 1108 1106 1084 1131 1132 1110 1131 1079 1088 1107 1136 1060 1172 1041 1128 1073 1089 1138 1114 1167 1120 1073 1131 1093 1125 1091 1124 1105 1110 1117 1091 1133 1006 1086 1124 1192 1056 1093 1111 1097 1122 1081 1133 1067 1104 1024 1097 1074 1130 1035 1078 1051 1123 1098 1052 1123 1015 1078 1056 1034 1090 1053 1144 1086 1096 1132 1069 1138 1086 1136 1116 1052 1074 1105 1059 1230 1062 1126 1111 1112 1122 1033 1174 1124 1144 1040 1129 1142 1042 1149 1110 1201 1124 1116 1138 1151 1108 1153 1064 1115 1111 1049 1075 1080 1082 1001 1108 1103 1109 1119 1042 1049 1051 1130 1031 1136 1103 1060 1021 1069 1125 1176 1058 1102 1102 1054 1082 1138 1142 1102 1083 1171 1082 1151 1042 1092 1102 1104 1109 1103 1083 1081 1118 1134 1097 1059 1135 1068 1152 1084 1089 1165 1181 1093 1137 1145 1148 1128 1087 1096 1100 1152 1123 1037 1062 1081 1075 1070 1170 1116 1123 1089 1133 1143 1070 1062 1172 1092 1079 1076 1121 1091 1157 1105 1157 1139 1142 1197 1086 1156 1072 1096 1106 1122 1100 1172 1167 1101 1092 1118 1187 1129 1125 1067 1161 1045 1144 1098 1206 1185 1147 1118 1250 1100 1210 1158 1184 1186 1161 1142 1190 1143 1151 1139 1117 1156 1079 1191 1167 1209 1119 1087 1216 1159 1185 1158 1136 1073 1145 1052 1102 1151 1140 1152 1179 1107 1068 1053 1156 1091 1104 1078 1185 1146 1138 1076 1120 1070 1094 1092 1112 1128 1084 1128 1093 1079 1114 1135 1062 1126 1137 1087 1133 1116 1077 1117 1159 1135 1140 1083 1173 1123 1129 1079 1139 1160 1190 1128 1164 1176 1150 1111 1132 1115 1125 1101 1164 1086 1084 1112 1142 1132 1056 1228 1139 1122 1164 1158 1209 1145 1152 1087 1168 1130 1192 1131 1177 1168 1157 1106 1144 1125 1151 1159 1177 1146 1201 1110 1203 1188 1202 1185 1221 1227 1248 1230 1245 1204 1231 1182 1258 1213 1171 1215 1267 1188 1284 1139 1299 1237 1185 1231 1291 1234 1275 1167 1218 1239 1206 1239 1235 1275 1249 1242 1248 1286 1293 1263 1247 1269 1292 1275 1238 1233 1234 1225 1263 1256 1224 1375 1319 1343 1285 1236 1284 1284 1289 1376 1331 1379 1385 1418 1363 1454 1393 1521 1440 1492 1532 1610 1580 1659 1793 1919 1960 2217 2405 2478 2868 3522 3807 4181 4763 5455 6428 5961 4844 4320 4147 3272 3049 3089 3219 3250 3462 3778 3554 3131 2802 2526 2014 1825 1715 1684 1485 1427 1540 1461 1398 1405 1390 1332 1406 1331 1297 1304 1289 1357 1363 1219 1289 1304 1270 1371 1344 1338 1275 1400 1355 1262 1277 1275 1308 1301 1280 1253 1281 1262 1295 1328 1290 1213 1251 1222 1233 1219 1291 1252 1335 1173 1187 1158 1189 1224 1237 1161 1135 1170 1194 1156 1147 1119 1089 1144 1122 1178 1137 1116 1208 1139 1119 1129 1150 1089 1164 1114 1094 1137 1050 1081 1097 1110 1135 1066 1063 1123 1066 1137 1087 1069 1092 1069 1102 1061 1088 1038 1069 1052 1065 975 1021 1048 1058 1091 1086 1042 1109 1039 1041 1053 1097 1076 1082 1118 1052 1075 1092 1062 1070 1073 1048 1069 1158 1107 1067 1115 1061 1023 1064 1073 1133 1061 1009 1083 1011 1024 1083 1100 1081 1065 1073 1104 1060 1012 1078 1027 1019 1064 1081 1064 1013 1011 993 1024 1066 1049 1093 995 1054 1042 1072 1051 1098 1054 1053 1090 1046 1029 1002 1034 1091 1027 1005 1026 1038 1078 1023 997 1068 1048 1003 1069 1073 1041 1049 1052 1016 1073 1081 1047 1041 1048 1021 1018 1027 1088 1097 1080 1077 1024 1073 1044 1024 1020 1096 1101 1039 1031 1104 1016 1031 1082 998 1026 967 1015 1019 1102 1032 1044 1022 1021 1010 1027 1054 1037 978 967 1074 1035 1070 1037 1004 1053 1036 1032 1008 1090 1068 1032 1068 1033 1047 1104 1063 1091 1056 1006 1045 1029 1047 1008 1056 1048 1032 1103 1041 1002 990 1018 1067 1041 1049 1039 1063 1070 1005 1001 1016 1064 1083 1027 1097 1041 1031 1052 1040 1008 1024 1047 1020 960 1122 1070 1050 1020 1035 987 1021 1063 1005 974 1046 1006 1069 1090 1060 1004 1029 1029 1006 1011 1053 1052 1022 1074 1059 1007 1029 1042 1031 1030 1037 1045 1015 1097 1062 1037 1025 979 1065 1038 996 1078 1024 1008 1094 1082 1026 984 1078 1052 1036 973 998 1034 996 1018 1030 1035 1118 1087 1080 1050 1068 1053 1080 992 1096 1083 1013 1059 1064 1024 1055 1038 1070 1039 1086 1039 1049 1044 1016 961 1048 1032 1006 1067 1056 1087 978 1066 1036 1015 1056 1029 1064 1061 1053 1008 1017 1072 1090 975 982 1021 1041 1044 989 985 1041 1076 1038 1056 1052 1049 1022 1029 1041 1034 1008 977 1097 1001 1025 1026 1001 1034 1074 1002 1025 980 1069 1031 1046 1009 1084 1004 956 981 1040 1020 1006 1067 1063 1046 1025 987 1033 1061 1079 1025 1058 941 1054 1029 949 1050 1056 1023 1044 1030 1045 1065 1015 1009 985 1046 981 1048 1088 1059 1064 1064 1034 1042 1068 1077 1023 1016 1011 1008 1093 1018 1036 1008 1062 1093 1076 1013 994 1111 995 1078 1032 1012 1031 1025 1012 1090 1008 956 1037 963 1016 1049 1073 1004 1019 1083 1089 992 1025 1004 1060 1041 983 1059 1068 993 1035 1009 1087 1006 1027 1041 1073 1056 1070 1019 1035 1031 1049 1017 991 1077 1047 953 1075 1092 1039 999 969 978 1030 973 1008 1016 1017 1070 1022 1052 953 1061 967 1078 1097 1027 1025 991 959 1047 1024 1039 1090 1065 990 992 983 1075 988 1013 977 1065 1067 1008 1080 1047 997 1067 1020 1029 1038 987 1066 1027 1022 996 1052 1016 1008 1061 1019 1031 1032 1048 1030 1002 1036 1031 1091 998 1073 1022 1078 1055 1050 1080 1067 1041 1052 1019 1024 1069 1033 1053 1053 999 1021 1053 977 998 1102 1088 999 1029 978 1025 1031 1055 1095 1036 1017 1109 1023 1022 1005 1024 1049 1072 1019 1076 996 1044 1006 1042 1077 1096 1035 1041 1069 1034 1036 994 1044 1084 1023 1073 1037 1049 1047 1048 1012 1047 1046 1074 1035 1079 1083 1087 1090 1024 1059 1056 1048 973 1086 1042 1090 1055 1038 1026 1017 1089 1045 1042 1073 1083 1078 1079 1017 1066 1053 995 1083 1050 1031 1029 1102 1089 1074 1026 1073 992 1054 1039 1052 1012 995 1047 1081 1103 1020 1068 1078 1121 1050 1081 1012 1093 1082 1147 1087 1027 1068 1059 1045 1046 992 1080 1054 1052 1087 1088 1037 1066 1056 1040 1013 1048 1175 965 1125 1055 1069 1074 1093 1056 1067 1070 1056 1074 1084 1118 1088 1063 1060 1053 1117 1041 1097 1058 1120 1054 1079 1074 1077 1084 1087 1049 1153 1037 1084 1060 1134 1066 1077 1117 1069 1040 1087 1012 1158 1109 1118 1123 1066 1118 1138 1147 1036 1050 1097 1119 1131 1081 1064 1082 1118 1066 1116 1112 1117 1013 1066 1095 1095 1030 1088 1072 1095 1125 1096 1160 1091 1050 1079 1119 1097 1059 1139 1054 1077 1078 1076 1102 1054 1081 1037 1065 1072 1090 1116 1035 1115 1033 1094 1105 1126 1075 1087 1107 1104 1066 1027 1055 1048 1098 1013 1116 1147 1088 1077 1109 1105 1081 1094 1087 1128 1098 1060 1052 1091 1050 1048 1131 1091 1026 1081 1111 1135 1090 1013 1097 1050 1135 1046 1102 1130 1131 1119 1091 1087 1079 1105 1069 1119 1025 1013 1082 1126 1101 1033 1119 1023 1061 1105 1067 1095 1111 1049 1033 1134 1073 1042 1060 1070 1070 1063 1072 1035 1046 1023 1062 1102 992 1035 1034 1102 1036 1022 1078 1055 1084 1049 1050 1031 1006 1097 1054 1054 1049 1048 1073 1080 1060 1049 1011 1033 1039 951 988 1035 1065 1070 1016 962 1026 1100 1013 1079 1034 1052 1080 1087 1045 1063 1073 1070 1045 1094 1041 1048 1054 1061 990 995 960 1038 1067 1077 1045 1063 1077 964 1034 1106 1011 1023 980 1038 1037 1069 1041 1044 1067 1035 1064 1019 1026 1023 1087 984 1023 971 995 997 1032 1024 992 1038 1039 985 982 1094 980 1051 1019 1022 1080 1019 1044 1092 1048 1048 1055 1033 1060 1061 1027 1042 1077 1051 980 1072 971 984 947 1018 1049 1052 1038 1036 1049 999 992 1081 968 1046 965 988 1029 1049 1069 1029 1009 1027 1036 1031 995 1072 1035 1091 1044 999 1045 992 1067 969 1033 969 1015 1042 1083 1022 1003 1019 1025 1042 1081 1092 1052 1004 984 1048 1003 999 1089 1037 1077 989 997 999 1053 1060 974 1052 1029 1004 990 1036 995 1040 1073 1035 1080 999 1034 1029 1044 998 1038 1067 1060 1050 1005 1025 1004 1026 1088 1015 1003 993 979 968 1029 1023 1044 1063 1031 1062 963 1063 1037 1049 990 1018 1029 1050 1022 1033 1034 1044 1022 1045 1029 1046 999 1007 1032 1024 1024 1122 922 1062 1018 1049 1053 1048 1045 1016 990 1037 1020 1076 1027 1023 1022 1068 1023 1033 1003 980 1042 1041 1067 1016 1046 1082 1056 1008 1033 980 997 1052 1016 955 1001 1044 991 959 1055 1023 979 1023 1060 1083 1022 1005 1035 1019 1056 1079 1029 1063 1075 1021 947 1045 1016 1034 1069 1054 1046 1006 1068 1087 1070 1005 1035 1074 1054 1047 1065 1058 1081 1077 1049 1020 1011 1081 1078 1009 1059 1061 1010 1012 987 1008 1052 1017 1089 1109 1051 1072 1008 1040 1027 1021 1079 1097 1038 1008 1004 1121 1047 1100 1035 1023 1076 1018 1091 1140 1102 1121 1054 1076 1069 1090 1036 1093 1049 1069 1080 1051 1083 1094 1080 1096 1147 1153 1102 1038 1024 1072 1079 1053 1090 1094 1068 1089 1161 1107 1078 1047 1186 1076 1114 1070 1123 1126 1074 1044 1219 1104 1095 1041 1153 1168 1126 1144 1210 1088 1096 1120 1095 1080 1131 1124 1174 1158 1084 1122 1182 1110 1116 1133 1121 1108 1132 1157 1109 1147 1068 1159 1154 1086 1062 1131 1192 1112 1079 1154 1281 1109 1181 1108 1187 1188 1146 1100 1159 1089 1190 1146 1220 1080 1098 1144 1179 1134 1134 1102 1096 1103 1161 1160 1158 1047 1160 1163 1204 1156 1102 1161 1224 1133 1190 1174 1188 1046 1163 1135 1220 1143 1143 1153 1202 1076 1168 1108 1202 1161 1135 1122 1215 1164 1157 1150 1190 1175 1122 1090 1186 1223 1186 1109 1243 1144 1172 1147 1184 1157 1186 1122 1210 1167 1144 1163 1232 1117 1122 1118 1181 1222 1152 1159 1218 1181 1143 1165 1230 1117 1188 1207 1206 1176 1104 1137 1133 1086 1111 1117 1201 1097 1111 1056 1168 1130 1205 1126 1161 1194 1112 1066 1200 1130 1180 1167 1140 1069 1157 1158 1106 1196 1074 1074 1126 1079 1084 1132 1076 1179 1106 1110 1135 1126 1142 1172 1243 1084 1100 1102 1161 1108 1140 1056 1114 1097 1152 1094 1124 1132 1092 1105 1177 1121 1121 1088 1106 1145 1108 1149 1184 1067 1060 1080 1134 1048 1059 1080 1150 1096 1019 1109 1158 1133 1109 1094 1119 1041 1087 1106 1065 1115 1083 1089 1039 1160 1139 1059 1108 1052 1053 1133 1110 1072 1075 1093 1134 1051 1074 1102 1082 1051 1066 1089 1110 1158 1079 1095 1111 1163 1061 1093 1185 1114 1047 1109 1066 1110 1081 1040 1064 1080 1072 1088 1075 1056 1088 1095 1150 1019 1080 1088 1112 1088 1004 1084 1151 1106 1052 1055 1087 1060 1059 1083 1112 1030 1110 1064 1065 1004 980 1128 1105 1027 1096 1063 1079 1021 1066 1094 1142 1111 1092 1048 1118 1051 1078 1096 1068 1031 1042 1018 1075 1074 1034 1086 1065 1110 1066 1059 1114 1065 963 1021 1107 1087 968 1042 1114 1075 1031 1019 1050 1051 1079 1031 1093 1037 1100 980 1061 1011 1051 1079 1034 1093 1049 1066 1042 1100 1046 1049 1035 1089 1046 1080 1007 1065 1076 1055 1060 1103 1101 985 1082 1017 1050 1015 1055 1068 1023 1041 1067 1009 1008 1039 1080 1097 1025 1132 1100 1107 1025 1032 975 1002 1065 1087 1090 1013 1045 1054 1083 1078 1067 1037 994 1044 1117 1039 1090 1040 1069 1039 996 1031 1083 1055 1103 1107 1112 1102 1030 1027 1047 1032 1082 1103 1032 1084 1121 1062 1004 1104 1080 1047 1093 1063 1140 1022 1081 1131 1059 1073 1031 1060 1048 1125 1033 1146 1053 1030 1125 1054 1002 1031 1080 1079 1063 1047 1105 1025 1070 1039 1087 1056 1032 1032 1118 1048 1080 990 1047 1117 1037 1019 1031 1094 1076 1004 1078 1060 1117 1010 1011 1084 1112 1098 1012 1034 991 1073 1040 1068 997 985 1063 1041 1081 993 1015 1027 1055 1073 1111 1030 1055 1052 1060 1076 1086 1105 1039 1067 1051 1024 1054 1051 1020 1058 1035 1024 1039 1064 1051 1090 1051 1037 1096 1047 1068 1024 1046 1019 1008 1093 1052 1061 1049 1078 973 1034 1058 1101 1088 1047 1094 1039 1084 974 1089 1031 1050 1052 1068 981 1024 1029 1094 1011 1060 1052 1017 1086 1036 1012 1098 1056 1067 1044 1068 1038 1061 1029 1065 1031 1074 1035 1021 1038 1019 1078 1024 1068 1026 1079 1053 1036 1112 1092 1050 1025 1049 1047 1002 977 1005 1032 1044 1069 1103 1081 1093 1072 1088 1103 1062 1171 1124 1058 1053 1021 1048 1128 1089 1130 1069 1163 1096 1025 1108 1100 1038 1079 1049 1177 1117 1050 1131 1168 1102 1035 1020 1090 1053 1115 1142 1105 1097 1120 1174 1133 1055 1060 1131 1078 1053 1046 1077 1135 1086 1068 1137 1151 1060 1036 1129 1073 1046 1027 1134 1091 1097 1100 1138 1100 1075 1045 1082 1077 1140 1104 1097 1063 1102 1078 1036 1060 1042 1159 1129 1079 1078 1088 1143 1067 1123 1120 1109 1073 1132 1080 1068 1095 1119 1032 1107 1055 1079 1104 1111 1041 1098 1017 1060 1076 1098 1074 1174 1078 1070 1109 1091 1149 1047 1062 1051 1093 1086 1122 1177 1069 1116 1038 1090 1109 1066 1058 1098 1070 1033 988 1146 1079 1044 1070 1135 1090 1077 1073 1090 1072 1003 1094 1067 1056 1072 1029 1096 1126 1081 1052 1091 1106 1051 1034 1120 1086 1133 1083 1060 1106 985 1062 988 1025 1114 1011 1041 1048 1046 1003 1070 975 1050 1049 990 1025 999 1066 1041 1058 993 1015 1063 1006 1019 1011 985 1045 1082 1025 1065 934 1008 1044 1029 1030 1073 1021 1053 1069 1021 1029 1015 1038 1016 1032 977 1060 1015 1035 1020 1084 1061 1032 1015 1003 1042 1039 1042 1072 1008 1049 1049 1025 1001 1063 1033 1064 1068 1048 1009 989 1053 1080 1017 1054 1061 1003 1002 1044 971 1039 1011 1061 1101 1011 1049 1078 1058 1009 1022 1073 1051 1061 1052 1059 1083 1063 1061 1054 1027 1118 1045 1097 1023 1060 1015 1065 1076 1072 1060 1037 1130 1087 1068 1012 1060 1013 1040 995 1042 1050 1002 1080 1063 1088 1048 985 1061 1040 1055 1081 1051 1089 1038 1070 1042 1061 1097 1110 1030 1044 1161 1093 1031 1086 1031 1045 1082 1111 1080 1100 1072 1125 1061 1094 1038 1033 1075 1064 1052 1044 1077 1080 1070 1118 1041 1115 1036 1114 1124 1118 1117 1068 1041 1110 1078 1133 1091 1104 1052 1125 1095 1114 1061 1091 1106 1063 1139 1084 1162 1110 1117 1111 1096 1065 1102 1090 1120 1016 1059 1084 1110 1152 1145 1067 1131 1134 1134 1047 1118 1166 1096 1095 1102 1161 1082 1102 1108 1185 1079 1171 1072 1098 1080 1090 1128 1103 1156 1082 1165 1136 1132 1111 1156 1108 1112 1109 1163 1104 1093 1173 1167 1139 1136 1107 1101 1131 1154 1142 1164 1116 1117 1171 1185 1131 1211 1181 1158 1134 1238 1168 1158 1173 1207 1181 1234 1167 1193 1168 1257 1197 1160 1206 1247 1214 1177 1140 1243 1175 1199 1215 1229 1165 1188 1238 1273 1283 1230 1232 1210 1264 1246 1247 1267 1227 1244 1243 1206 1211 1273 1247 1288 1316 1321 1288 1341 1315 1359 1298 1305 1349 1338 1362 1425 1383 1474 1490 1601 1669 1752 1951 2047 2234 2514 3116 3111 3430 3500 4927 3302 2910 3076 2560 2155 2036 2099 1872 1792 1844 1984 1884 1930 2084 2230 2317 2411 3137 2543 2302 2376 2516 1941 1871 1873 1661 1602 1588 1653 1516 1533 1517 1509 1487 1460 1548 1476 1456 1461 1487 1333 1419 1352 1334 1416 1345 1329 1356 1374 1365 1319 1379 1370 1295 1344 1369 1298 1356 1317 1257 1304 1302 1278 1288 1228 1264 1253 1293 1178 1213 1224 1221 1180 1144 1132 1196 1205 1138 1153 1156 1150 1125 1121 1143 1160 1136 1225 1100 1079 1101 1107 1152 1098 1070 1040 1073 1075 1095 1091 1044 1082 1130 1104 1108 1098 1108 1120 1083 1068 1038 1101 1049 1021 1027 1078 1068 995 1060 1041 1039 1059 1088 1076 1080 1038 1082 1091 1029 1090 1049 1063 1109 1040 1108 1089 1078 1070 1058 1076 1032 1058 1047 1027 1040 1025 1068 1040 1038 1061 1075 1024 1029 1002 1096 973 999 1009 1037 1077 1106 1058 1040 1108 983 1025 1011 1109 1039 1068 1018 1084 1056 1046 1089 1051 1046 1044 969 1050 1049 1026 1050 1047 1060 1016 1054 1077 1060 1006 1041 1033 1038 1025 1020 995 1026 1073 1024 1047 1045 1065 981 1017 1089 992 1067 1030 1006 979 1064 1024 1047 1092 1087 1084 1040 1029 1073 1021 1022 1082 1033 1074 1097 1053 1027 1027 1095 1093 1079 1022 1001 984 1006 979 1106 1053 1041 1082 1059 994 1048 1142 1047 1042 1060 1005 1060 1042 994 1046 1050 1041 1046 1063 1032 1086 1032 1010 1052 1031 1013 1074 1108 1038 1009 981 1058 1111 1077 1060 1054 1022 1083 991 1060 1055 1079 1037 1066 1016 1082 989 1038 1032 970 993 1089 1038 1046 1051 1004 978 1038 1027 1050 1049 1094 1137 1023 1066 1095 1025 1123 1047 1092 1089 1126 1008 1083 1044 1105 1069 1116 1006 1097 1077 968 1072 1015 1049 1046 1041 1064 1052 1105 1074 999 1036 1064 1035 1047 987 1111 1059 1064 993 1044 1034 1036 969 992 980 1091 1035 1050 1059 1038 1019 1059 1080 1051 1031 1041 1063 1033 1058 1056 990 1051 965 1038 1095 1094 1041 1062 1056 1041 1034 1109 1047 1040 1080 1077 1035 1027 1036 1040 982 1059 1035 1015 1068 1044 1015 1002 1049 1019 1041 1077 1077 1056 1006 977 1006 1059 974 1074 1081 1033 1017 1020 1086 1056 1052 989 1101 1045 1047 1117 1091 1060 1047 1051 1059 997 989 1046 1063 1064 1017 1087 1010 1059 1010 1065 1035 998 1007 1068 1073 998 1062 1083 1106 1011 985 1032 1061 1048 1062 1003 1115 1027 1011 1117 1031 984 1005 1072 1051 1009 1045 1040 1055 1031 1042 1058 1049 1030 1007 1055 1103 1073 988 1102 1036 1047 1012 1055 1040 1079 1009 1090 1095 1026 1026 1069 1052 1018 1032 1002 1048 1025 1041 1011 1055 1053 1087 1047 1022 1022 1010 1054 1080 1016 1040 1061 971 1157 980 1031 1018 1032 1002 1060 1121 1022 985 1024 1005 1053 1091 1068 1050 1040 1052 980 1068 1023 953 1006 1067 1015 1021 1027 1036 992 1011 1006 1022 1050 996 1047 993 1074 1011 1042 1065 1024 1047 1052 1104 1042 982 1023 1027 994 1010 1033 1063 1115 1002 1049 1038 985 1022 1048 1021 1056 987 1018 1018 994 1026 988 1012 1095 997 1068 1102 1088 1042 987 960 1083 1050 1048 1072 1036 1033 948 1058 1052 1081 1026 1030 1037 1040 1082 1037 1003 1018 1035 1059 1010 1084 1024 1055 995 1033 1069 985 1039 998 993 1051 1019 1095 1052 1038 1034 987 964 1023 1046 1054 1019 1067 1100 1023 1005 1072 992 1064 1053 1039 1018 1083 1060 1054 1060 983 1031 1069 984 1048 1109 1075 1032 1079 1027 1035 997 1008 1054 1081 1048 1039 1021 917 1026 1006 1051 1114 1038 1037 1018 1020 1033 1051 1041 1068 1030 1066 1069 1008 1036 1080 1040 1076 1084 998 1067 1047 1060 1061 1008 1081 1016 1087 1090 1077 1054 1088 1150 1091 1124 1025 1108 1063 1079 1055 1039 1020 1138 1116 1092 1096 1056 1118 1101 1088 1047 1035 1081 1051 1016 1111 1050 1034 1063 1045 1008 1032 992 1040 1070 1104 1094 1059 1062 1063 1103 1131 1048 1109 1078 1084 1129 1068 1083 1091 1100 1010 1086 1091 1060 1017 1023 1073 1108 1101 1040 1091 1115 1009 1072 1075 1069 1084 1059 1098 1114 1082 1090 1086 1056 1084 1051 1108 1118 1033 1079 1011 1082 1032 1048 1095 1061 1056 1062 1104 1065 1084 1117 1115 1037 1084 1020 1101 1078 1165 1080 1053 1115 1077 1033 1081 1139 1077 1048 1117 1069 1116 1094 1094 1051 1063 1073 1100 1146 1040 1058 1017 1076 1103 1061 1081 1088 1151 1086 1077 1022 1066 1118 1098 1180 1106 1123 1111 1100 1090 1016 1131 1061 1044 1041 1072 1140 1082 1064 1074 1056 1090 1091 1074 1096 1130 1023 1067 983 1040 1091 1015 1033 1091 1045 982 1044 1070 1061 1059 1044 1036 1069 979 1104 1112 1068 1053 1033 1051 1040 1031 1035 1005 989 1118 1024 993 1084 1092 1030 1091 1079 993 1064 1050 1050 1044 1012 1055 1041 1001 1033 1048 1089 1001 978 1003 1049 1058 1002 1046 1029 1026 1042 1044 957 1046 1062 989 1022 998 1050 1053 1100 1050 991 1076 985 1036 1042 1011 1011 975 1038 1041 1015 1009 1053 989 1090 1032 1084 1018 1037 1061 1048 1049 998 978 1058 1072 985 1046 1059 1045 1003 1046 1001 1029 1005 1015 990 1035 1005 1001 1015 1036 1045 1105 977 1038 1018 1031 1027 993 1018 1041 1033 1005 1015 1075 1020 1030 980 1082 1011 1081 1051 1018 1107 1034 1070 1088 1045 1005 1046 1056 1002 1007 973 1117 1058 982 1034 1013 1035 1079 1050 1064 1037 1044 991 1067 987 1021 989 982 1052 1065 1034 1049 1056 1031 1091 1026 1040 1070 1010 1025 1129 1072 1041 1107 1066 1004 1097 988 1042 1138 1020 1101 1040 962 1079 1091 1037 1083 1152 1093 1102 1093 1093 1084 1090 1064 1097 1120 1101 1120 1097 1119 1124 1115 1082 1035 1117 1162 1088 1095 1054 1077 1050 1098 1132 1076 1092 1148 1173 1091 1039 1068 1136 1083 1101 1104 1118 1046 1034 1157 1092 1075 1080 1159 1148 1084 1097 1098 1095 1130 1053 1180 1055 1094 1082 1123 1096 1008 1049 1207 1122 1065 1145 1051 1128 1059 1084 1084 1112 1073 1105 1107 1068 1154 1077 1187 1079 1119 1079 1094 1086 1069 1123 1130 1134 1089 1207 1124 1115 1067 1051 1168 1047 1129 1106 1093 1185 1075 1033 1163 1153 1079 1166 1110 1146 1093 1069 1160 1110 1112 1075 1145 1056 1093 1112 1145 1090 1041 1103 1122 1060 1095 1051 1087 1056 1058 1056 1079 1101 1038 1090 1117 1070 1089 1075 1129 1078 1081 1086 1130 1035 1026 1104 1100 1162 1112 1084 1167 1080 1049 1058 1125 1069 963 1076 1054 1072 1063 1131 1078 1070 1070 1067 1020 1082 1021 1101 1058 1053 1040 1131 1040 1090 992 1005 982 1004 1059 1012 1040 1060 1001 1051 1015 1077 1054 1054 1061 1089 1059 1006 1089 1011 1068 1079 1088 1004 1063 1036 1087 1102 1053 1074 1012 1009 1037 1016 1039 1082 1044 1110 1046 1004 1065 1076 1031 1063 1090 1049 1034 1029 991 1026 1035 1013 1055 1088 992 1045 1116 1078 1078 1084 1106 1034 1074 1055 1031 1032 1015 1094 1053 1075 1051 1011 1109 1052 1062 1089 1068 999 1055 1004 1038 1089 1112 1034 1040 1025 1023 1032 1046 1121 1027 1075 1035 1117 1055 1034 1035 1070 1087 1023 1079 1077 1047 1053 1098 1125 1035 1055 1078 1061 1073 1060 1093 1053 1039 992 1091 1050 1047 1124 1079 1019 1082 1037 1121 1075 1060 1142 1091 1076 1036 1005 1087 1065 1042 1117 1032 1058 1031 1077 1063 1092 1080 1064 1033 1006 1025 1005 1093 1051 1041 1070 1031 1027 1039 1005 1030 1063 1037 1047 1067 1064 1051 1114 1025 1091 1075 1073 1088 1040 1081 1061 1076 1052 1040 1052 1080 1063 1035 1087 1035 1061 1044 1112 985 1011 1038 980 1064 1056 1041 1040 1095 1096 1048 1076 1081 1074 983 1074 1066 1065 1069 977 1055 1040 1075 1052 1056 1110 1096 1080 1075 1084 1064 1027 1032 1029 1081 994 1158 1062 1066 1051 1116 1048 1110 1030 1044 1051 1086 1041 1012 1088 998 1067 1089 1058 1065 1009 1081 1020 1083 1118 1084 1007 1053 1064 1007 1032 1006 1056 1076 1112 1091 1105 1038 1066 1008 1029 1039 1041 1086 1056 1076 1036 1081 1023 1035 1101 1063 1035 1089 1018 1056 1034 1096 1067 1068 1020 1074 1031 1017 1089 1086 1054 1100 1021 1105 1118 1092 1045 1122 1074 1073 1103 1070 1109 1042 1092 1107 1066 1092 1077 1088 1061 1074 1110 1136 1065 1081 1076 1083 1072 1059 1054 1082 1101 1086 1089 1088 1015 1100 1074 1058 1080 1019 1065 1121 1100 1134 1109 1062 1031 1148 1114 1078 1072 1104 1084 1041 1025 1094 1161 1151 1123 1120 1064 1083 1076 1104 1078 1096 1112 1090 1062 1082 1126 1111 1092 1038 1125 1069 1140 1077 1129 1082 1072 1143 1097 1147 1022 1100 1047 1041 1124 1160 1133 1128 1077 1074 1143 1171 1110 1086 1048 1075 1143 1157 1088 1151 1172 1164 1103 1091 1220 1072 1112 1065 1082 1140 1177 1157 1137 1166 1118 1135 1137 1143 1202 1186 1164 1103 1135 1187 1196 1193 1180 1133 1189 1068 1230 1191 1131 1248 1187 1231 1191 1182 1205 1205 1202 1248 1191 1202 1187 1251 1191 1218 1218 1291 1241 1209 1205 1227 1299 1205 1256 1267 1197 1165 1230 1257 1257 1181 1200 1217 1263 1250 1238 1289 1231 1253 1260 1298 1235 1192 1276 1316 1288 1237 1236 1322 1233 1210 1253 1284 1260 1290 1218 1372 1218 1258 1359 1283 1267 1263 1406 1275 1332 1343 1308 1403 1371 1375 1362 1382 1302 1403 1418 1393 1391 1446 1515 1445 1581 1579 1476 1545 1710 1738 1685 1898 2154 1891 1978 2715 2658 2125 2308 3093 2490 2177 2362 2892 1936 1883 2233 2035 1734 1709 1763 1717 1579 1621 1779 1607 1544 1788 1770 1607 1640 1865 1839 1672 1880 2235 1797 1879 2271 2105 1739 1706 1910 1690 1537 1587 1696 1464 1468 1547 1469 1357 1411 1505 1385 1290 1329 1404 1405 1307 1318 1416 1270 1273 1304 1299 1299 1344 1303 1315 1185 1352 1223 1221 1238 1283 1246 1225 1215 1275 1292 1210 1292 1245 1244 1204 1245 1217 1211 1194 1255 1257 1203 1275 1217 1156 1247 1203 1162 1149 1175 1181 1161 1173 1130 1202 1158 1215 1143 1201 1164 1096 1132 1232 1121 1216 1161 1200 1100 1187 1177 1131 1165 1148 1185 1084 1163 1117 1108 1160 1163 1170 1194 1164 1086 1116 1131 1192 1107 1152 1103 1194 1081 1111 1178 1143 1114 1147 1156 1157 1070 1131 1104 1164 1147 1191 1055 1123 1115 1107 1073 1081 1101 1093 1153 1139 1070 1111 1018 1105 1142 1067 1123 1064 1080 1130 1063 1031 1053 1184 1076 1079 1091 1191 1069 1061 1098 1121 1107 1129 1139 1104 1088 1106 1065 1116 1040 1092 1112 1107 1095 1133 1072 1077 1090 1093 1041 1087 1124 1098 1086 1101 1140 1049 1103 1131 1065 1098 1029 1177 1056 1064 1110 1154 1118 1063 1060 1103 1104 1137 1123 1081 1048 1110 1026 1063 1166 1042 1080 1076 1058 1041 1065 1078 1131 1055 1073 1110 1080 1118 1090 1093 1065 1116 1108 1079 1056 1067 1054 1101 1126 1140 1106 1083 1130 1133 1061 1136 1073 1079 1054 1079 999 1088 1024 1048 1018 1061 1102 1035 1095 1038 1077 992 1041 1133 1051 1077 1096 1080 1135 1082 1058 1105 1055 1124 1093 1120 1041 1118 1106 1032 1054 1111 1114 1084 1078 1059 1050 1092 1068 1065 1110 1055 1069 1022 1120 1086 1089 1100 1125 1041 1087 1061 1073 1064 1039 1086 1122 1003 1067 1051 1105 1092 1134 1066 1025 1046 1062 1080 1081 1076 1066 1100 1032 1066 1078 1094 1087 1130 1052 1034 1051 984 1020 1111 1115 1108 1114 1115 1128 1131 1045 1077 1106 1144 1069 1115 1100 1084 1101 1076 1059 1076 1105 1156 1065 1074 1048 1154 1104 1110 1039 1109 1048 1047 1086 1067 1049 1123 1084 1080 1134 1100 1112 1102 1091 1112 1090 1060 1089 1078 1112 1091 1063 1058 1054 1048 1110 1058 1097 1058 1092 1118 1075 1058 1084 1066 1097 1097 1067 1049 1031 1093 1118 1068 1031 1094 1082 1075 1074 1079 1069 1055 1052 1109 1086 1122 1103 1160 1103 1078 1003 1097 1084 1070 1111 1041 1102 1118 1078 1038 1064 1072 1069 1105 1075 1067 1093 1080 1116 998 1053 1148 1050 1062 1042 1045 1094 1030 1072 1075 1054 1066 1082 1050 1042 1019 1073 1052 1079 1097 1103 1077 1126 1079 1041 1098 1098 1062 1023 1106 1119 1110 1063 1038 1055 1064 1114 1143 1020 1083 1128 1087 1097 1056 1059 1038 1102 1045 1097 1101 1130 1121 1109 1101 1078 1101 1098 1064 1110 1120 1048 1078 1083 1040 1133 1098 1093 1119 1067 1138 1050 1024 1088 1088 1140 1054 1112 1091 1049 1118 1140 1096 1154 1133 1081 1050 1100 1106 1132 1019 1152 1049 1188 1094 1086 1080 1089 1070 1104 1068 1117 1154 1096 1117 1090 1120 1102 1125 1060 1056 1104 1178 1100 1060 1209 1069 1116 1130 1133 1019 1149 1088 1147 1051 1131 1130 1157 1062 1117 1081 1165 1110 1150 1160 1132 1087 1128 1093 1171 1119 1177 1148 1149 1166 1146 1081 1131 1166 1149 1121 1153 1145 1128 1179 1210 1177 1185 1165 1197 1180 1313 1137 1295 1235 1327 1276 1407 1255 1432 1340 1408 1366 1385 1244 1257 1262 1176 1255 1200 1184 1235 1178 1210 1182 1248 1189 1204 1163 1150 1135 1186 1246 1160 1177 1233 1185 1213 1207 1298 1230 1239 1258 1299 1256 1220 1237 1300 1255 1241 1201 1239 1181 1242 1175 1252 1138 1222 1223 1174 1245 1171 1078 1255 1142 1241 1086 1163 1135 1149 1159 1218 1172 1123 1133 1130 1132 1108 1173 1223 1142 1159 1166 1249 1151 1082 1164 1201 1140 1100 1145 1233 1156 1148 1149 1114 1158 1148 1143 1224 1160 1109 1205 1194 1190 1046 1129 1192 1165 1184 1097 1184 1105 1110 1144 1139 1190 1200 1152 1149 1105 1137 1125 1178 1148 1138 1172 1190 1205 1104 1214 1220 1264 1167 1109 1211 1253 1180 1161 1200 1200 1180 1105 1170 1203 1222 1135 1241 1249 1174 1142 1161 1215 1170 1140 1185 1265 1137 1139 1153 1199 1262 1142 1203 1211 1137 1132 1200 1260 1162 1149 1174 1126 1200 1167 1182 1202 1227 1167 1221 1214 1200 1175 1235 1205 1204 1067 1165 1189 1214 1115 1204 1231 1192 1157 1128 1204 1154 1149 1242 1216 1194 1174 1194 1213 1182 1119 1175 1210 1213 1186 1220 1232 1200 1152 1227 1184 1143 1101 1173 1234 1172 1180 1162 1201 1142 1187 1196 1219 1194 1152 1252 1178 1170 1148 1232 1264 1197 1174 1157 1277 1237 1213 1227 1208 1207 1149 1132 1189 1144 1069 1193 1207 1185 1122 1156 1239 1116 1126 1120 1161 1108 1090 1084 1182 1121 1087 1131 1201 1194 1118 1102 1104 1105 1123 1053 1144 1118 1056 1098 1133 1082 1045 1120 1106 1133 1115 1143 1130 1150 1063 1095 1147 1108 1080 1125 1061 1131 1128 1068 1072 1119 1088 1078 1082 1021 1072 1069 1093 1061 1128 1020 1092 1107 1111 1056 1066 1035 1036 1096 1074 1017 1005 1098 1047 1053 1061 1021 1105 1083 1047 1044 1109 1010 1082 1023 1094 1065 1077 1064 1018 1082 1036 1075 1022 1024 1056 1079 1104 1052 1072 1065 1100 1076 1106 1070 1045 1017 1046 1119 1086 1002 994 1020 1059 1082 1009 1048 1039 1058 1058 1066 1093 1051 1134 1149 1050 1062 1045 1078 1078 1112 1055 1030 1103 1073 1065 1130 1056 1025 1088 1109 1139 1066 1060 1023 1005 1083 1020 1042 1021 1076 1067 992 989 970 1047 1011 1045 1024 1055 1027 1003 1069 1056 1064 1049 1044 1051 1039 1048 1020 996 1062 1084 966 1032 1029 1004 1054 1088 1132 1074 1037 1052 1006 1080 1005 1032 1069 1003 1031 999 1103 1048 1045 1069 1023 1002 978 1065 1052 997 1051 1015 1102 995 1084 1062 1017 1084 996 1045 1003 1029 1050 974 988 1076 1003 1064 1012 1024 1045 985 1034 1059 1079 1039 1027 1084 992 1033 1032 1072 1083 1068 1018 1010 1067 1045 1087 1053 1002 1026 1065 1030 1044 1008 1048 1050 1031 1051 1063 1066 1052 1048 1008 1052 1039 1056 1126 1010 1106 1023 993 1126 1001 1053 1025 1072 1067 1066 1037 1073 1029 1031 1081 1045 998 1026 1005 1038 1086 1031 1005 1083 981 1026 1013 1037 1035 1061 1051 1086 1030 1053 1058 1051 1009 1049 1030 1007 1054 1053 1036 969 1052 1075 996 1050 977 1074 1106 1052 1017 999 1029 955 1109 1015 991 901 1034 1053 1060 995 1046 1060 1058 1006 1034 1038 1048 1018 1109 1061 1058 1022 1060 1072 1050 1039 1024 1063 1024 1115 1092 1026 1049 1049 1034 1066 1038 1041 1035 1100 1086 1016 1065 1066 1034 1032 959 1044 1006 1004 1088 1069 1003 1076 1032 1133 1077 1110 1059 1035 965 1017 1040 1069 1064 1038 1093 954 1030 1073 1061 1041 1017 1041 999 1003 1030 1114 1026 1055 1056 1059 1041 1003 1078 1079 1039 1016 993 995 1076 990 1067 1003 1060 1086 1031 1076 1048 1025 1040 1046 1015 1030 1101 1077 1026 1053 1055 1031 1035 1083 1006 1082 1052 1026 1036 1053 1045 1072 1047 1083 1039 1012 1033 1068 1063 1061 1048 1056 1042 1070 995 1072 1036 1041 1093 1027 994 1037 1060 1078 1007 985 961 1062 1064 1078 1082 1034 1064 1041 1074 1053 1072 1003 1042 1020 957 1032 992 1072 1083 1072 1078 1065 1070 1074 1046 969 1035 1001 1044 1078 1017 1046 1042 1097 1087 1077 1045 1064 1008 1042 1004 1060 1049 1063 1044 1058 1020 1037 1005 1110 1054 1059 1031 1069 1095 1104 1180 1027 1009 1051 1123 1045 1124 1046 1123 1037 1051 1109 1106 1035 1148 1124 1080 1135 1128 1083 1107 1073 1199 1158 1120 1109 1136 1213 1108 1145 1178 1075 1140 1050 1162 1164 1131 1083 1142 1106 1060 1095 1072 1101 1077 1098 1151 1134 1086 1123 1172 1117 1123 1123 1147 1139 1126 1078 1158 1156 1098 1072 1144 1112 1121 1104 1144 1116 1086 1097 1150 1104 1105 1108 1131 1179 1095 1122 1126 1134 1149 1078 1174 1111 1096 1059 1118 1042 1093 1121 1163 1147 1123 1062 1150 1149 1115 1107 1176 1224 1088 1034 1106 1132 1125 1121 1138 1129 1104 1079 1166 1109 1083 1140 1161 1119 1112 1143 1146 1091 1145 1054 1163 1132 1108 1148 1166 1145 1097 1129 1129 1065 1119 1110</intensities>
			</dataPoints>
		</scan>
	</xrdMeasurement>
</xrdMeasurements>