File: Data availability/00_STD_IN718_HT2X.xrdml
<?xml version="1.0" encoding="UTF-8"?>
<xrdMeasurements xmlns="http://www.xrdml.com/XRDMeasurement/1.6" xmlns:xsi="http://www.w3.org/2001/XMLSchema-instance" xsi:schemaLocation="http://www.xrdml.com/XRDMeasurement/1.6 http://www.xrdml.com/XRDMeasurement/1.6/XRDMeasurement.xsd" status="Completed">
	<comment>
		<entry>Configuration=reflection - transmission spinner, Owner=User-1, Creation date=10/26/2007 2:30:26 PM</entry>
		<entry>Goniometer=PW3050/60 (Theta/Theta); Minimum step size 2Theta:0.001; Minimum step size Omega:0.001</entry>
		<entry>Sample stage=Reflection-Transmission Spinner PW3064/60; Minimum step size Phi:0.1</entry>
		<entry>Diffractometer system=XPERT-PRO</entry>
		<entry>Measurement program=C:\PANalytical\Data Collector\Programs\00_STD_IN718.xrdmp, Identifier={28380439-0F33-476B-A426-78B1F912C0F4}</entry>
		<entry>Batch program=C:\PANalytical\Data Collector\Programs\00_patch_IN718.xrdmp, Identifier={A2BED34D-926D-4141-95EA-CABD315EAC4D}</entry>
	</comment>
	<sample type="To be analyzed">
		<id></id>
		<name></name>
		<preparedBy></preparedBy>
	</sample>
	<xrdMeasurement measurementType="Scan" status="Completed" sampleMode="Reflection">
		<comment>
			<entry>20-130 angle .004 step 30s </entry>
			<entry>PHD Lower Level = 5.34 (keV), PHD Upper Level = 11.09 (keV)</entry>
		</comment>
		<usedWavelength intended="K-Alpha 1">
			<kAlpha1 unit="Angstrom">1.7890100</kAlpha1>
			<kAlpha2 unit="Angstrom">1.7929000</kAlpha2>
			<kBeta unit="Angstrom">1.6208300</kBeta>
			<ratioKAlpha2KAlpha1>0.5000</ratioKAlpha2KAlpha1>
		</usedWavelength>
		<incidentBeamPath>
			<radius unit="mm">240.00</radius>
			<xRayTube id="1010042" name="Empyrean Co LFF (9430 033 7600x) DK417097">
				<tension unit="kV">40.0</tension>
				<current unit="mA">45.0</current>
				<anodeMaterial>Co</anodeMaterial>
				<focus type="Line">
					<length unit="mm">12.0</length>
					<width unit="mm">0.4</width>
					<takeOffAngle unit="deg">6.0</takeOffAngle>
				</focus>
			</xRayTube>
			<filter id="20010003" name="Beta-filter Iron">
				<material>Fe</material>
				<thickness unit="mm">0.016</thickness>
			</filter>
			<sollerSlit id="21010002" name="Soller slits 0.04 rad.">
				<opening unit="rad">0.0400</opening>
			</sollerSlit>
			<mask id="22080002" name="Fixed incident beam mask 10 mm">
				<width unit="mm">6.60</width>
			</mask>
			<antiScatterSlit id="22010003" name="Fixed slit 1°" xsi:type="fixedAntiScatterSlitType">
				<height unit="mm">1.52</height>
			</antiScatterSlit>
			<divergenceSlit id="22010004" name="Fixed slit 1/2°" xsi:type="fixedDivergenceSlitType">
				<distanceToSample unit="mm">140.00</distanceToSample>
				<height unit="mm">0.76</height>
			</divergenceSlit>
		</incidentBeamPath>
		<sampleMovement xsi:type="spinningSampleMovementType">
			<spinnerRevolutionTime unit="seconds">4.0</spinnerRevolutionTime>
		</sampleMovement>
		<diffractedBeamPath>
			<radius unit="mm">240.00</radius>
			<antiScatterSlit id="22090004" name="AS slit 5.5 mm (X'Celerator)" xsi:type="fixedAntiScatterSlitType">
				<height unit="mm">5.50</height>
			</antiScatterSlit>
			<sollerSlit id="21010002" name="Soller slits 0.04 rad.">
				<opening unit="rad">0.0400</opening>
			</sollerSlit>
			<detector id="7010013" name="X'Celerator detector" xsi:type="rtmsDetectorType">
				<phd>
					<lowerLevel unit="%">38.5</lowerLevel>
					<upperLevel unit="%">80.0</upperLevel>
				</phd>
				<mode>Scanning</mode>
				<activeLength unit="deg">2.022</activeLength>
			</detector>
		</diffractedBeamPath>
		<scan appendNumber="0" mode="Continuous" scanAxis="Gonio" status="Completed">
			<header>
				<startTimeStamp>2020-02-20T20:04:46-08:00</startTimeStamp>
				<endTimeStamp>2020-02-20T21:56:33-08:00</endTimeStamp>
				<author>
					<name>User</name>
				</author>
				<source>
					<applicationSoftware version="5.4">Data Collector</applicationSoftware>
					<instrumentControlSoftware version="2.2D 20160920">XPERT-PRO</instrumentControlSoftware>
					<instrumentID>0000000011030022</instrumentID>
				</source>
			</header>
			<dataPoints>
				<positions axis="2Theta" unit="deg">
					<startPosition>20.00008891</startPosition>
					<endPosition>129.99783913</endPosition>
				</positions>
				<positions axis="Omega" unit="deg">
					<startPosition>10.00004445</startPosition>
					<endPosition>64.99891957</endPosition>
				</positions>
				<positions axis="Phi" unit="deg">
					<commonPosition>168.6</commonPosition>
				</positions>
				<commonCountingTime unit="seconds">30.250</commonCountingTime>
				<intensities 1181 1213 1221 1251 1191 1244 1199 1266 1236 1180 1222 1258 1156 1258 1206 1340 1189 1225 1206 1255 1208 1250 1206 1263 1242 1252 1252 1162 1207 1223 1246 1173 1173 1291 1220 1196 1253 1236 1210 1165 1223 1225 1176 1189 1186 1165 1173 1250 1189 1158 1208 1205 1197 1241 1264 1194 1213 1219 1150 1211 1215 1159 1175 1262 1177 1180 1174 1209 1196 1162 1176 1174 1146 1159 1201 1176 1139 1245 1255 1190 1224 1218 1203 1199 1221 1201 1211 1225 1145 1265 1231 1191 1199 1294 1258 1246 1135 1164 1214 1181 1221 1187 1178 1209 1157 1221 1271 1248 1193 1252 1300 1217 1249 1159 1297 1193 1266 1163 1214 1158 1234 1192 1306 1158 1222 1236 1321 1208 1208 1208 1271 1203 1239 1232 1399 1261 1228 1219 1248 1173 1202 1196 1255 1209 1208 1196 1242 1187 1105 1174 1221 1201 1218 1172 1224 1196 1158 1189 1230 1276 1228 1195 1264 1153 1237 1274 1211 1219 1246 1191 1289 1148 1202 1233 1209 1213 1272 1223 1318 1133 1230 1237 1294 1178 1275 1204 1251 1150 1206 1209 1210 1187 1180 1269 1233 1182 1199 1185 1178 1145 1170 1167 1228 1164 1258 1162 1194 1193 1217 1275 1279 1189 1162 1207 1220 1232 1220 1119 1222 1154 1125 1171 1247 1211 1162 1193 1263 1128 1197 1209 1251 1078 1170 1207 1209 1261 1215 1272 1237 1186 1187 1170 1173 1100 1106 1164 1162 1209 1174 1221 1205 1121 1158 1108 1235 1146 1194 1187 1261 1162 1094 1079 1244 1190 1137 1194 1185 1074 1120 1125 1194 1118 1232 1089 1154 1170 1111 1218 1129 1201 1166 1211 1186 1195 1109 1182 1109 1211 1095 1171 1082 1177 1116 1170 1154 1122 1162 1162 1114 1192 1077 1150 1109 1154 1087 1160 1138 1176 1194 1204 1111 1130 1166 1106 1151 1152 1143 1184 1118 1177 1197 1143 1138 1195 1163 1170 1128 1194 1116 1148 1095 1089 1151 1102 1106 1136 1090 1126 1081 1180 1094 1133 1119 1253 1135 1142 1089 1069 1080 1132 1111 1139 1163 1096 1064 1219 1160 1050 1134 1091 1119 1092 1131 1150 1205 1109 1173 1137 1122 1106 1143 1061 1142 1142 1180 1168 1126 1089 1145 1134 1172 1165 1147 1176 1228 1104 1173 1116 1156 1097 1125 1180 1096 1166 1135 1180 1156 1108 1178 1200 1138 1097 1188 1144 1100 1191 1148 1211 1161 1204 1117 1178 1076 1174 1148 1164 1166 1153 1166 1210 1166 1200 1115 1174 1181 1126 1193 1137 1135 1219 1213 1138 1191 1154 1121 1110 1171 1219 1164 1132 1139 1144 1182 1184 1122 1119 1191 1176 1128 1185 1233 1139 1139 1121 1115 1142 1131 1140 1174 1137 1128 1182 1180 1123 1171 1160 1173 1110 1086 1157 1190 1147 1161 1168 1211 1145 1144 1181 1146 1148 1101 1185 1187 1129 1069 1168 1128 1138 1144 1116 1262 1122 1108 1124 1209 1170 1128 1162 1206 1121 1092 1177 1220 1182 1174 1191 1177 1084 1104 1144 1228 1215 1200 1204 1243 1126 1101 1232 1176 1173 1109 1164 1248 1208 1139 1187 1148 1166 1184 1230 1227 1225 1186 1123 1259 1188 1128 1177 1193 1206 1241 1257 1231 1258 1120 1200 1173 1201 1089 1253 1160 1159 1108 1151 1213 1138 1084 1309 1186 1199 1214 1238 1197 1152 1179 1223 1176 1149 1117 1208 1245 1202 1182 1157 1215 1138 1162 1130 1131 1145 1118 1119 1207 1128 1193 1164 1224 1152 1111 1193 1228 1118 1131 1142 1210 1147 1135 1122 1079 1147 1140 1106 1164 1101 1104 1154 1138 1197 1159 1131 1202 1123 1081 1096 1154 1079 1101 1196 1115 1165 1165 1193 1171 1082 1131 1160 1156 1117 1150 1159 1174 1199 1134 1151 1164 1135 1101 1157 1121 1137 1144 1179 1174 1175 1160 1138 1148 1151 1137 1128 1202 1199 1112 1186 1150 1142 1118 1133 1145 1172 1081 1189 1100 1143 1137 1185 1148 1194 1089 1135 1122 1241 1111 1094 1142 1204 1145 1157 1170 1128 1039 1168 1153 1147 1111 1130 1107 1179 1157 1080 1180 1194 1064 1055 1158 1123 1050 1121 1060 1118 1091 1064 1061 1128 1078 1082 1116 1118 1049 1107 1097 1061 1111 1119 1165 1124 1131 1048 1145 1072 1134 1098 1112 1082 1126 1063 1064 1088 1174 1049 1152 1140 1146 1107 1171 1076 1148 1092 1109 1069 1105 1063 1054 1092 1148 1041 1062 1146 1132 1138 1131 1123 1131 1083 1097 1120 1066 1100 1118 1092 1104 1134 1112 1106 1096 1114 1154 1118 1072 1104 1063 1041 1131 1102 1100 1081 1150 1088 1135 1125 1062 1131 1157 1114 1135 1097 1111 1092 1146 1112 1130 1100 1065 1083 1062 1162 1138 1067 1038 1125 1144 1095 1060 1064 1102 1064 1061 1077 1052 1045 1143 1116 1094 1037 1077 1158 1091 1088 1068 1046 1073 1048 1078 1147 1063 1058 1039 1084 1048 1108 1107 1139 1052 1060 1092 1045 1128 1086 1065 1098 1079 1003 1058 1089 1148 1046 1144 1040 1086 1012 1037 1108 1039 1080 1022 1045 1117 1030 1064 1131 1122 1026 1102 1097 1130 1094 1142 1023 1129 1036 1037 1129 1166 1080 1095 1047 1063 1049 1082 1006 1125 1123 1066 1078 1105 1107 1094 1036 1063 1081 1089 1100 1042 1053 1006 1086 1082 1087 1104 1092 1086 1147 1045 1116 1041 1070 1115 988 1042 1109 1025 1032 1032 1063 1090 1124 1066 1026 1094 1064 998 1068 1096 1025 1103 1012 1087 1084 1022 1106 1094 1107 1081 1084 1056 1094 1110 1101 1126 1050 1074 1033 1068 1065 1125 1031 1130 1018 1120 1031 1006 1068 1072 1092 1053 1123 1064 1107 1088 1058 1107 1082 1109 1024 1172 1041 1056 1060 1108 1079 1026 1084 1075 1067 1126 1061 1056 1012 1102 1082 1069 1046 1030 1034 1123 1031 1070 1050 1125 1082 1069 1124 1120 1038 1098 1091 1097 1095 1134 1016 1118 1091 1089 1069 1147 1075 1107 1091 1115 1015 1087 1108 1079 1067 1084 1089 1160 1109 1095 1089 1094 1016 1107 1100 1133 1062 1100 1074 1120 1069 1079 1067 1168 1020 1094 1052 1133 1088 1062 1063 1100 1051 1119 1121 1092 1024 1081 1088 1130 1079 1098 1092 1097 1075 1107 1082 1184 1002 1053 1021 1089 1111 1077 1136 1171 1032 1084 1059 1111 1036 1097 1093 1128 1066 1023 1058 1101 1035 1073 1125 1158 1089 1129 1095 1103 1040 1078 1110 1182 1025 1023 1059 1114 1032 1060 1130 1096 1032 1075 1103 1146 1007 1045 1052 1094 1011 1069 1096 1118 1083 1102 1065 1120 974 1134 1062 1103 1030 1218 1049 1069 1081 1108 1053 1075 1064 1124 1125 1055 1029 1098 1136 1121 1054 1156 1069 1121 978 1098 1134 1094 1024 1058 1068 1139 1152 1170 1188 1180 1118 1097 1145 1079 1093 1125 1150 1088 1013 1133 1092 1146 1083 1062 1152 1109 1016 1100 1092 1104 1094 1089 1126 1106 1056 1100 1080 1104 1044 1090 1074 1076 1034 1115 1079 1046 1034 1067 1067 994 1046 1091 1063 1053 1078 1084 1130 1062 1034 1126 1075 1062 1027 1035 1102 1094 1042 1143 1087 1045 1038 1093 1121 1074 1058 1087 1095 1077 1019 1062 1040 1081 1037 1109 1108 1072 1034 1082 1107 1068 1007 1136 1098 1105 1055 1061 1077 1056 981 1126 1021 1084 1098 1068 1056 1058 1025 1079 1062 1097 1062 1054 1146 1048 1007 1111 1067 1042 1054 1136 1084 1044 1018 1121 1136 1097 1026 1093 1038 1006 992 1051 1146 1049 1051 1062 1055 1048 988 1083 1060 1024 1008 1052 979 1103 988 1053 1016 1051 1060 1121 1044 1048 979 1102 1082 1042 1007 1078 1032 1072 1004 1083 1022 987 1041 1050 1037 989 1034 1033 1076 1033 984 1098 1016 1013 974 1026 1067 988 1019 1117 1026 994 952 1007 975 1010 978 1006 973 1063 963 1068 990 1026 1013 1017 1032 1051 997 1060 976 993 987 1035 1005 1017 1030 1074 989 1029 1041 1017 1015 1037 982 1070 1040 1038 1050 1073 1024 1123 981 1087 1005 966 999 1045 1016 1103 960 1075 1055 969 936 1021 1005 1039 1026 1010 1035 1006 964 1015 1029 1063 1006 1054 1092 987 1056 989 1041 1084 973 990 1024 1042 1045 1095 1011 1090 1034 1053 1003 974 975 1016 1037 1047 1041 1035 1059 1032 980 1024 1012 1019 1042 1024 1091 1020 1045 1045 1091 971 1072 1037 1007 1003 967 1020 1010 982 1020 1054 1024 978 999 1023 1039 1008 1011 1040 1066 1054 1020 1044 1006 1050 1074 1031 984 964 935 1023 1058 1009 971 1064 995 983 1072 993 1041 1020 975 992 1068 1117 1108 1038 1003 1016 996 1067 1026 1055 1022 1069 982 1005 1025 1022 1111 1032 1035 995 1030 971 1018 998 1011 992 1096 1024 1004 1001 1056 990 1066 1009 1022 987 1082 1018 1024 1053 1022 1021 995 1052 1012 1031 1032 1098 1062 1060 1061 1011 1027 1012 1034 1042 1033 1103 1063 1059 1011 1037 1051 950 1018 998 1010 1061 1030 1066 1048 1072 1010 1095 1032 1115 1049 1069 1052 1063 1051 1033 1054 1056 982 1042 1050 1112 1054 1039 1090 1093 1088 1045 1103 1089 1058 1023 1140 1003 994 1017 1076 1094 1060 1018 1008 1078 1016 1084 1084 1083 1002 1095 1064 1079 981 1029 1086 1072 1020 1044 1059 1015 1037 1098 1070 1076 980 1048 1056 1080 1049 1094 1110 1039 1070 1098 1053 1098 964 993 1148 1081 1002 1045 1050 1112 1062 1042 1114 1110 1060 1025 1077 1093 1007 1046 1078 1049 1065 1053 1090 1121 926 1002 1134 1049 1056 1018 1086 1112 1055 1046 1063 1079 1027 1062 1039 1068 1045 1032 1048 1088 978 1078 1092 1105 1018 1060 1042 1062 1009 968 1075 1058 998 1030 1077 1018 1091 1008 1083 1109 1034 999 1029 1101 1058 1025 1102 1070 1062 1046 1086 1121 1042 1020 1112 1103 989 1009 1090 1035 1067 1052 1133 1009 1021 1026 1080 1102 985 979 1133 1022 1008 985 1059 1052 1022 969 1042 1002 989 1025 1104 1022 1033 1041 1086 1078 1002 969 1082 956 982 1022 984 1026 1022 1019 1009 1053 1062 1080 1039 1007 1010 1047 1065 1055 1023 1102 1058 983 1037 1004 1051 974 988 1031 1034 1025 1051 990 1015 1012 1060 1073 1041 1032 1094 1048 1027 1002 1029 1082 1010 1055 1039 1114 1007 1038 1038 1052 1015 1022 1095 1065 1006 989 1097 1029 1070 1025 1095 1025 1026 968 1042 1013 1064 960 961 998 1004 1040 995 1024 978 992 1033 1033 998 1038 1023 1024 984 1041 1036 1050 901 1001 1070 1100 1045 1046 1075 1015 1022 1053 1056 1063 1016 1031 1097 1010 982 1075 1013 1025 1006 1036 1104 1090 1033 1026 1068 993 1006 1023 981 978 1002 1019 1038 1036 1067 992 1084 1045 1040 988 1094 1046 984 1063 1098 1064 969 1050 1139 969 957 1004 1047 1020 967 966 1106 973 994 969 1064 1026 1013 976 1101 1072 1045 1055 999 984 980 1017 1073 959 995 978 1027 1044 941 1003 1088 1060 1106 1032 994 974 991 1008 1023 1039 988 953 1050 1059 935 1005 1023 984 1033 1052 1080 1018 1046 1045 1032 1051 977 1061 1015 994 1037 997 1013 949 1019 1030 1047 963 1008 1012 1022 984 984 963 1038 994 1008 977 1029 993 974 992 998 976 990 985 1003 1026 967 1007 1031 1004 1029 1001 1018 999 1020 998 1012 1054 965 999 1074 968 1049 1006 991 993 954 946 1030 1029 1024 1050 1029 1035 948 994 988 1047 969 955 960 995 987 956 1016 998 925 1016 1023 1045 966 994 956 1010 1030 1001 1017 1012 1004 991 996 1050 998 1004 993 1017 1045 1008 1025 1006 935 998 1023 1078 1033 950 982 1015 992 1058 953 981 971 989 960 976 1032 1034 981 946 952 984 980 1010 1024 987 950 977 981 1027 973 1034 996 968 970 1031 1049 1022 948 1006 974 1029 1052 982 983 1006 1036 948 995 950 968 1033 973 1053 1001 973 1039 1026 1022 1035 1018 994 954 1032 1009 1046 1004 1017 1016 984 967 1007 995 996 1044 1024 955 1017 1003 992 998 998 1052 961 975 1001 976 996 998 1009 1088 1018 966 1018 1064 970 974 971 959 1039 1023 978 1046 1007 1006 985 980 1042 997 1023 969 1026 918 950 1029 1013 948 980 931 987 1034 981 974 1019 991 995 1003 1042 941 989 1041 984 973 1049 977 996 943 957 970 914 985 1023 1029 1008 963 984 1003 995 952 973 926 1016 1032 1007 1013 1011 943 1002 997 1013 921 963 1035 938 953 1048 1018 1007 955 964 1003 1018 969 998 1006 974 965 1006 964 1017 976 946 941 957 973 970 1011 1040 1012 976 1004 1002 1015 984 1055 993 971 1006 1052 1074 998 1002 1020 991 1024 993 964 1005 1033 1006 995 988 1019 1002 1002 992 962 1009 1025 1015 1064 1008 1018 985 989 1053 1015 955 1030 1007 966 1047 1020 1021 982 1029 1021 928 978 998 959 1020 967 962 1018 1063 1023 1011 962 1018 1010 998 974 946 931 1005 968 948 946 1031 996 929 995 1035 1003 992 1030 954 1023 1025 981 979 996 974 1017 1026 1008 962 952 951 1035 1036 979 999 1001 1045 1047 1029 1046 1017 946 991 1045 971 955 1059 1032 1009 925 1054 1033 978 1008 1025 1066 1006 990 1029 1046 1030 978 993 1058 1013 1062 956 984 1009 1007 999 1004 1040 979 1008 1031 1013 973 1086 1084 980 981 1030 1023 1023 1001 984 1041 954 1039 962 1011 964 975 971 979 1039 1031 1034 1016 984 1039 1063 1052 1045 1020 1005 1031 1020 940 1103 1064 1107 1017 1038 1017 1041 1030 1054 1038 1090 1024 1062 1020 1074 1016 1035 1005 1046 1064 1083 1060 1017 1006 1047 1123 1081 1053 1030 985 1069 999 1016 1065 1013 1060 1023 1049 976 1039 1060 1056 1017 1094 1034 1036 1106 1053 1117 1103 1097 1092 1066 1072 1052 1050 1061 1103 1066 1110 1072 1160 1102 1080 1112 1012 1051 1066 1186 1104 1077 1061 1196 1148 1097 1131 1047 1171 1097 1126 1142 1177 1280 1211 1176 1189 1295 1298 1285 1307 1364 1393 1445 1572 1731 1834 1912 2499 2687 2712 2927 4993 5565 5179 6499 8441 4316 2634 3336 3111 2568 2673 4909 4760 2954 2906 2835 1826 1535 1548 1458 1378 1288 1329 1279 1223 1247 1200 1164 1194 1165 1184 1097 1158 1084 1066 1117 1109 1147 1149 1130 1108 1154 1046 1154 1083 1050 1102 1114 1104 1004 1059 1117 1041 1053 1061 1119 1081 1011 1072 1077 1076 1063 1062 1093 1039 1053 1040 1034 1013 1058 1025 1037 1095 1041 1020 1037 1063 1039 1015 1015 999 1050 1038 1004 979 1082 968 1011 1026 1021 1070 1022 1035 957 947 1064 1020 983 1024 996 983 970 1035 1016 1059 993 1004 1015 991 985 1027 1064 989 971 938 1051 947 961 1018 1002 1008 1016 1018 983 963 981 914 987 1068 1019 982 1029 1052 998 995 1032 937 982 1021 1054 969 988 949 995 964 1026 946 1054 966 1011 967 962 974 941 895 973 1011 1009 1030 987 963 941 978 963 967 914 1004 1006 982 945 1012 994 1029 1021 967 1033 956 950 1007 1025 997 947 961 1031 936 1006 946 957 1011 965 990 1039 981 966 974 960 1022 937 1003 968 1040 988 967 1031 1079 979 1002 980 975 1037 987 987 962 951 983 967 932 951 960 957 960 1030 1001 1009 947 942 1010 976 987 975 960 985 1002 1003 962 1003 962 956 999 1044 998 1002 993 962 964 935 982 1034 1011 999 1008 1030 974 947 1019 1010 935 1004 919 971 1032 960 1027 988 1032 967 977 971 1017 961 977 1009 963 956 984 961 960 970 983 1034 974 934 1025 996 969 978 984 937 1016 913 1008 957 983 925 1033 976 951 929 1036 1003 973 989 992 960 973 964 1005 1009 960 931 985 1025 928 935 989 963 1009 1002 1011 934 976 956 955 996 1017 966 1001 984 1003 1053 999 1023 1008 978 968 1001 998 954 953 943 949 954 960 1022 969 923 1019 980 932 1013 1008 993 985 979 995 953 980 923 982 987 992 968 990 963 976 1044 1025 1030 950 965 1009 959 988 969 1006 998 976 992 1035 968 987 991 935 1009 973 1022 1007 982 966 1045 950 1019 919 963 1013 954 984 891 979 1037 968 932 1007 1017 987 967 957 957 1008 948 991 992 997 939 999 942 1006 1008 919 1021 1006 974 957 1018 955 913 1031 955 1003 1027 990 973 962 993 952 893 980 1010 1026 991 983 969 1002 925 1004 934 971 963 1015 968 953 967 1002 947 961 982 1092 976 906 1004 992 984 933 989 946 981 997 991 988 1055 966 957 974 954 1084 1004 960 964 894 960 990 1030 1060 928 998 1013 918 985 1019 993 967 1006 1010 1005 1008 1001 975 1060 984 980 967 1032 971 1001 1008 909 1025 965 932 967 981 967 979 984 938 982 988 999 1033 998 1001 984 950 939 934 983 1045 969 1051 981 978 977 960 1076 1032 969 1006 976 934 959 1003 1007 1018 1001 951 996 1017 1002 999 1009 977 950 1004 1042 1018 1026 1010 999 999 1016 1004 1046 950 1023 1021 985 989 999 1035 1040 1013 978 1038 1029 1044 1004 1004 1086 1022 1047 1003 1020 1003 980 1079 1047 1047 1054 1066 1081 985 1023 1018 1054 1066 1084 1078 1090 1021 1094 1076 1080 1021 1098 1082 1073 1146 1097 1149 1100 1021 1119 1089 1036 1063 1116 1095 1062 1172 1131 1080 1107 1109 1108 1072 1132 1087 1094 1102 1118 1116 1111 1174 1062 1125 1118 1103 1070 1142 1021 1167 1100 1111 1122 1145 1145 1128 1137 1153 1154 1109 1230 1137 1158 1184 1182 1158 1227 1135 1190 1256 1178 1334 1213 1338 1365 1307 1267 1298 1412 1421 1473 1357 1558 1699 1712 1766 2023 2277 2521 2863 3350 3931 3998 4631 5076 5895 5456 6700 5715 4745 4217 4090 3831 3274 3474 3560 3522 3454 3846 3517 2891 2474 2248 1954 1637 1657 1495 1417 1329 1311 1315 1185 1203 1230 1245 1188 1187 1204 1184 1149 1111 1214 1092 1112 1192 1189 1096 1145 1180 1231 1151 1088 1109 1201 1104 1161 1110 1138 1128 1125 1107 1162 1166 1084 1151 1123 1136 1139 1161 1137 1105 1126 1161 1131 1135 1158 1016 1106 1094 1086 1061 1067 1126 1147 1077 1038 1067 1056 1095 1008 1105 1061 1088 1053 1070 1069 1023 1060 1019 1058 994 1068 987 970 1005 1055 1094 1006 966 1042 1069 963 981 1015 1087 978 926 950 1049 961 988 1067 982 992 1051 963 991 999 1031 980 960 997 1003 1033 995 990 1022 985 987 1046 1019 974 983 927 940 971 1013 961 949 964 962 965 962 933 963 947 1004 949 956 955 974 961 960 992 978 999 945 988 952 981 910 941 988 931 969 999 967 929 964 997 993 1030 940 990 1007 978 955 1006 1027 1083 939 1003 925 1033 1017 1032 995 1032 961 942 980 952 946 1007 974 1004 896 1001 966 1060 954 1002 994 987 947 974 949 1047 984 1011 925 970 965 990 1021 1048 960 1002 979 998 993 965 1012 996 1012 1023 898 948 948 978 978 1048 995 1022 942 999 965 991 947 985 992 984 997 1031 1003 966 951 1074 990 1003 984 1065 970 1047 960 1016 1011 1010 1038 1018 956 979 1078 1052 1001 1033 1033 1105 1034 1016 1038 1104 1047 963 1027 1029 1005 987 1096 1008 1006 934 1033 1054 1008 1017 1116 1087 1015 987 1082 1047 1068 966 1086 1040 1040 1021 1056 1075 1026 919 1026 1072 1020 995 1066 1058 1008 950 1055 1052 1046 967 1096 1058 975 1018 989 1061 998 1050 1054 1036 1068 998 1003 1009 1096 1036 1039 1053 1055 973 1027 1027 1013 969 988 1039 1090 1063 1070 1012 1010 954 1065 1033 1079 1013 1048 997 1065 1024 1088 1074 1050 1002 1005 1069 1079 1093 1093 1040 1059 1031 1087 997 970 1051 1064 1042 1010 987 1103 1098 1089 1066 1102 1034 1087 1055 1074 1016 1104 1101 1110 996 1007 1066 1054 980 1053 1027 1060 1012 1039 1054 1060 1002 1041 1107 1046 954 1044 1008 1059 976 1059 991 1078 1021 1047 1023 1102 1004 1030 995 1030 1005 949 996 1020 953 979 979 975 950 964 1008 948 957 1022 1050 963 928 1029 997 963 956 965 1013 1026 989 1041 1030 1041 969 1030 1067 1008 977 1013 1049 964 935 1018 1084 998 1013 962 1037 1012 960 979 1044 950 968 1017 1126 1017 973 1024 1021 948 1021 969 1030 1017 922 1027 1054 1037 983 967 982 981 991 1039 976 977 964 959 991 1010 990 997 1069 920 993 983 1088 1004 999 1062 1059 976 974 973 1039 974 987 1012 1036 1025 980 1048 1016 1061 985 988 1072 1052 988 1060 1103 996 1015 1020 1047 1042 991 1053 975 1051 1038 1002 1111 1076 1024 1074 1034 1076 1078 1062 1134 1073 1029 1021 1111 1059 1084 1067 1069 1148 1042 1114 1103 1044 1011 1122 1045 1047 1004 1062 1081 1091 1089 1068 1097 1083 953 1063 1110 1060 1042 1054 1045 1044 1052 1019 1059 1011 1010 1111 1080 1061 1054 1027 1092 1095 988 1076 1050 1051 980 1040 1008 1008 1010 1041 1078 978 1026 1086 1011 1096 1036 1118 1070 1105 1031 1031 1031 1072 1055 1080 1087 1091 1050 1062 1073 1041 993 1054 1054 1021 1062 1047 1056 1072 1054 1082 1083 1061 1078 1053 1037 1116 1024 1178 1156 1052 1030 1031 1104 1136 1065 1140 1046 1075 1037 1098 1048 1144 1076 1047 1012 1107 1049 1145 1063 1090 1094 1077 1019 1056 1052 1019 1068 1083 1048 1052 1007 1129 1102 1067 1027 1033 1013 1049 998 1034 1087 1034 1050 1022 1058 1091 1025 1061 963 1070 997 1063 1045 1046 1073 1095 954 990 1016 1046 999 1012 993 1056 974 993 1019 1029 1016 1033 1093 1041 977 1021 984 1038 962 975 1002 1045 1062 960 1032 1015 990 1062 1055 1031 998 993 1045 1087 996 1015 1010 1030 983 1022 1007 1042 999 989 1007 1069 1035 937 993 1017 1027 1018 1023 1073 952 1021 1017 1024 1012 1047 1074 1061 1007 1052 1047 1044 934 1032 1011 1019 971 1001 973 1132 976 1030 1011 1050 1012 991 1003 1040 971 1048 1022 1030 1025 1032 1053 1063 981 1052 1031 989 967 987 1034 1040 1041 1017 982 1053 995 1084 1017 1020 968 1015 1081 1050 941 1007 978 1019 995 1015 950 998 915 956 994 1026 1033 967 1037 1013 953 947 962 977 939 1023 1013 1041 970 983 1012 982 1010 1024 1034 968 980 992 1002 987 983 963 983 974 997 898 1021 1049 995 959 1037 980 961 1005 992 1041 939 931 970 1040 966 988 963 925 988 974 1037 1036 1013 956 952 985 907 901 1042 997 935 988 999 960 960 909 983 976 950 979 984 973 968 967 993 938 948 999 1033 1002 1022 981 973 954 966 913 994 976 1006 998 1011 999 893 993 964 1010 979 962 990 998 950 967 957 1027 966 929 1018 993 940 965 1021 1011 977 977 1009 996 1008 979 989 966 936 1048 1040 1029 1045 960 963 955 1012 939 980 947 981 1004 995 968 993 1018 985 1016 990 1018 933 949 949 1047 980 1006 987 993 934 1041 1018 971 979 1011 1002 989 1002 997 959 1072 1002 966 974 1018 1042 1021 1022 1018 1019 980 1035 1006 952 1027 1053 961 1004 994 991 1031 967 1004 989 1013 974 962 979 992 934 965 1018 987 1011 1025 950 1002 962 959 942 998 1032 1058 992 1020 976 1040 977 966 956 946 971 998 1020 1010 976 1006 940 963 1034 996 1019 980 1002 977 994 948 991 943 978 979 1036 1046 904 1001 993 1011 994 1010 1034 957 977 1008 1004 1011 971 1020 979 938 941 1006 1013 1005 1060 957 1002 967 1040 929 966 1030 1005 971 1002 995 1018 1008 987 1016 932 963 962 979 953 945 1023 949 978 1015 992 989 940 938 968 1021 935 974 991 964 961 951 999 946 981 1010 1024 990 966 981 1006 973 997 996 951 980 1029 983 1020 918 898 966 953 971 923 965 962 1016 921 1018 1022 907 981 940 1044 919 1026 987 997 1030 954 991 993 991 937 960 989 936 1018 967 990 967 1046 1003 1022 961 966 949 1030 990 1012 1011 984 1011 1036 1001 1020 949 1050 999 1050 1007 980 992 1015 1072 1008 977 965 933 1007 996 1040 1009 1064 1002 1020 957 1063 987 992 947 1031 1001 1013 1030 1091 948 950 982 955 1006 998 1026 1020 975 940 961 1007 975 984 1003 1030 976 1023 998 1073 985 1017 980 1059 1025 1064 963 1010 1044 982 1011 1123 968 1026 921 1010 993 1078 969 1075 996 1023 921 995 970 1009 1015 1016 994 1012 955 1089 941 967 1035 991 974 945 968 1058 1030 1042 1006 1054 995 1051 965 1011 1021 1067 1002 1096 1009 989 1020 1012 1008 1001 957 1011 989 1037 956 1035 996 967 1016 1061 1081 1079 1030 1073 1015 1024 993 984 1053 963 1005 1106 1093 1023 948 998 982 1002 988 1086 1027 1018 1021 1003 976 1006 934 1083 1005 945 973 1002 992 954 1046 1034 976 1034 967 1029 1005 1067 968 1041 951 998 980 1121 980 997 1015 1075 995 1130 974 1074 959 1053 1041 1008 997 982 973 1022 1034 1009 1053 1037 991 1004 1006 1007 1008 1044 927 934 940 980 977 936 966 1003 894 979 984 1031 988 949 979 995 962 961 963 1020 1007 997 951 955 948 962 985 1093 1032 973 952 1003 949 997 1007 1032 975 923 980 1013 926 1002 950 1010 1007 931 982 1007 933 943 1044 1013 968 965 941 1033 934 1011 976 997 982 998 1004 1027 973 1005 1024 915 1005 938 966 1002 953 1025 911 1002 975 964 996 1029 1037 1038 867 988 992 974 942 1027 969 1023 1006 1025 959 965 1005 933 953 1029 1025 1035 1016 957 1013 1009 1012 995 942 950 991 996 1039 967 971 1005 993 974 985 979 952 992 996 1002 1003 923 976 1008 983 962 1024 952 965 1013 981 967 983 1018 1006 1015 1020 994 1008 964 975 985 964 989 1013 973 991 996 992 949 932 979 999 966 1004 978 1011 1024 939 988 952 1010 951 964 960 884 1032 926 962 998 970 984 991 938 942 992 969 979 920 1020 996 995 985 981 978 980 973 1041 955 970 992 980 942 978 977 905 979 1040 983 994 954 996 1018 1003 934 988 948 964 925 1036 1034 996 1008 963 974 967 931 1045 1055 965 962 943 939 966 998 985 970 1015 937 938 945 953 911 990 929 936 969 974 962 993 971 950 949 1007 1062 987 968 977 939 981 993 1007 945 977 1006 994 948 1021 900 934 1005 984 974 1033 956 946 1010 991 949 992 1037 1013 966 1032 896 991 1008 967 977 1001 928 985 998 959 927 984 941 1045 969 979 993 956 969 997 1016 962 959 939 1001 1002 991 943 894 926 934 934 1008 928 997 999 981 984 948 939 968 961 994 945 976 963 1001 1038 987 991 952 1034 985 983 922 923 939 956 963 932 991 983 953 964 928 1021 924 911 1013 977 976 924 968 947 959 1009 950 990 948 1019 995 1011 924 1015 968 978 957 981 989 996 1016 982 928 946 1030 975 1004 911 995 955 1017 943 1016 938 967 984 964 926 1015 993 924 899 1032 970 969 925 960 990 955 931 987 973 984 937 927 978 980 1002 952 1008 1030 966 985 967 1041 1021 1022 987 931 981 954 984 1007 975 947 959 942 991 977 926 968 959 925 1001 982 995 952 920 1024 963 940 964 980 950 925 961 943 1036 955 963 942 957 966 953 979 941 951 960 999 998 935 1050 960 933 1010 911 979 965 919 964 951 1005 953 1012 998 899 968 1035 956 935 942 977 983 924 976 960 981 994 994 980 967 949 941 947 962 960 953 999 933 945 932 1019 1006 987 978 1001 907 952 897 913 973 994 929 977 956 963 953 950 1016 997 956 937 973 921 1011 978 995 933 987 959 951 1004 956 1031 925 971 1009 960 955 965 987 1007 1005 985 943 938 1016 926 1002 962 971 940 1018 1003 937 979 981 912 924 957 938 1007 940 985 945 991 914 946 952 946 952 894 955 992 917 1047 979 1004 957 973 946 999 932 926 967 1010 999 946 923 987 969 993 964 1064 981 996 987 983 995 921 980 988 1001 939 951 1040 994 979 998 949 971 935 990 971 968 955 971 962 949 1006 952 961 1006 991 953 942 1021 920 1007 921 977 927 1008 1007 922 936 1016 897 960 976 1011 942 936 955 1046 973 980 920 988 995 999 920 1025 933 1007 1007 1029 939 933 937 970 1002 931 915 996 945 1023 1008 908 964 918 940 978 956 1005 984 967 967 932 962 996 1026 1045 955 950 908 965 932 979 951 976 951 921 990 929 948 959 977 934 933 966 985 1023 1006 974 960 1045 1058 924 1033 988 970 924 1008 975 1013 956 992 945 1027 971 1044 977 966 1011 1025 1001 989 1044 989 994 993 977 970 1016 1012 990 952 995 1012 956 1062 991 980 975 964 1005 990 977 1104 1021 1045 987 1030 1001 1047 1041 956 1008 1003 1037 1005 1058 1027 1039 1007 1026 1047 1048 1046 1062 1012 1026 1008 1062 1044 1009 1016 1004 1093 1058 959 1033 1063 1035 1044 1108 1042 1045 1027 1080 1026 1025 988 1037 1026 1021 1095 1046 1011 987 1013 1066 1021 1030 1112 1021 1011 1080 1121 1092 1031 977 1092 1140 1114 1044 1051 1068 1059 993 1096 1011 1023 1048 1083 998 1044 1011 1126 1108 1084 976 1051 1041 1037 1059 1107 1140 1109 1049 1086 1139 1032 1051 1095 1070 1065 1034 1103 1056 1096 1039 1034 1046 1098 1092 1079 1118 992 964 1061 1068 1104 957 1016 1110 1078 1066 1104 1073 983 1025 1006 1115 988 1032 1070 1110 1093 1016 1129 1054 1070 1024 1040 1163 1025 1062 1063 1045 1050 1052 1105 1134 1012 1072 1050 1046 1068 1017 1025 1102 1056 1003 1086 1062 1038 1060 1056 1103 1049 1083 1023 1114 1050 1016 1073 1138 1031 1022 1078 1027 1007 1061 1073 1084 1098 959 1016 1114 1081 1030 1051 1008 1063 1048 1021 1010 1064 1046 1054 1073 1010 999 1072 1100 1007 1053 1062 1129 1034 952 1075 1073 1066 994 1047 1121 1017 997 1045 1058 1072 1046 1072 1026 1077 1100 1031 1083 1010 1027 1015 1052 1046 1061 1065 1095 1051 1098 1041 1052 1062 1068 1072 1077 1114 1070 1091 1145 1170 1206 1146 1304 1142 1184 1206 1202 1227 1263 1107 1125 1102 1137 1154 1129 1092 1121 1076 1111 1096 1131 1192 1192 1115 1119 1105 1137 1122 1093 1086 1058 1094 1070 1011 1114 1045 1091 1065 1083 1027 1077 1029 1103 1087 1090 1097 1075 993 1062 1013 1045 1126 1047 1063 1066 1030 982 1033 1015 1075 1048 1046 999 1048 998 1055 1098 1047 1103 1051 1002 1090 1012 964 1098 1058 1007 1031 1069 1062 1076 1036 1025 1065 1078 1002 1031 1020 1037 1001 1060 1115 1093 984 1001 1025 1069 999 1074 1067 1019 977 1070 1003 1013 984 1068 1042 1072 988 1013 988 977 980 1054 990 1064 1068 1086 1074 1060 999 1069 1003 1022 987 1048 1037 1004 1022 1058 1046 1081 998 1104 1009 1050 1018 1058 1059 947 1048 1049 1005 1030 1064 1082 1024 1016 1039 1094 1012 1090 1058 1062 1045 993 1081 1091 979 1021 1061 1107 1041 1018 1070 1108 1060 1104 1102 1090 1008 1098 1004 1032 1086 1060 1110 1090 1062 1080 1088 1089 1065 1086 1192 1146 1093 1089 1173 1102 1090 1126 1165 1159 1062 1072 1166 1053 1070 1058 1133 1137 1070 1084 1143 1117 1035 1118 1249 1115 1051 1130 1067 1089 1105 1081 1066 1081 1120 1075 1093 1179 1018 1096 1062 1136 1006 1029 1104 1015 974 1038 1101 1074 1093 1110 1122 1048 1108 1079 1108 1145 988 1095 1084 979 1020 1034 1081 1092 1016 963 1115 1069 1006 1059 1091 1004 1073 1004 1112 1038 1042 1031 1095 964 1075 1109 1058 1040 1061 1087 1102 1056 1039 1083 1148 1098 1025 1101 1146 1049 1049 1061 1123 1123 1067 1074 1108 1055 1034 1075 1081 1016 1061 1058 1172 1039 969 1068 1128 1026 995 1060 1100 984 984 1118 1116 987 1011 1072 1068 1002 1039 1046 1081 985 1009 1013 1078 1026 992 1051 1016 961 1098 981 1056 1041 1002 1033 1066 980 1024 1047 1001 1027 1019 1039 1033 994 1003 992 974 940 1006 1016 990 981 911 990 955 987 975 1072 935 1018 988 991 925 996 940 1084 903 967 967 978 933 979 959 935 968 987 928 1055 1058 971 1004 987 938 1029 903 1016 951 967 953 984 975 980 911 1022 964 954 1025 934 950 960 895 1016 953 974 988 985 941 996 970 1053 953 914 992 980 997 942 994 975 962 953 984 993 938 942 1021 1039 987 959 957 1001 1013 1030 934 997 985 1016 954 985 1009 976 1005 990 946 987 951 1015 945 1039 992 1006 952 969 993 979 978 1001 1015 973 970 967 966 946 979 1031 1023 1070 954 1023 1026 1009 1008 994 1036 908 967 976 955 974 1031 1019 1080 959 998 1005 975 980 1048 1021 981 992 1023 1021 992 950 1023 1006 1018 1001 1038 1051 977 955 945 1020 965 982 987 1023 1038 995 962 1001 948 997 953 984 1016 965 982 997 971 1015 961 992 1026 941 963 1003 1029 1023 1017 1054 966 1004 1012 998 1005 991 990 999 1017 954 996 1011 1048 963 997 1042 999 1006 976 1017 996 922 978 999 1010 975 1022 954 1044 997 997 1015 1065 995 938 1048 970 1035 983 1011 1029 1026 1005 1031 1078 1037 1003 1035 1024 977 1045 1054 988 1007 1009 1051 1052 975 1001 1030 987 974 1026 1039 1049 1010 1002 1064 1030 989 952 1019 1016 998 999 1039 984 997 956 1025 991 922 977 1054 1038 1021 1001 1063 998 968 1012 1036 974 1021 1001 964 985 992 1050 1054 979 998 977 1053 1020 1038 955 975 1004 953 1026 1033 1059 1007 1019 1016 974 1049 1022 1035 1033 1029 926 1069 1046 955 941 983 1035 1017 925 996 1015 1058 1016 997 936 1004 1002 1055 1061 1010 1002 1019 1083 1007 1010 1026 1063 959 973 1024 1021 1074 1005 1052 1029 975 1010 991 1005 996 966 1066 1030 1042 1018 1051 973 955 975 1006 1045 1053 974 985 1052 975 1038 1060 1046 1016 1007 1064 1048 1031 956 1025 1027 1001 1050 1045 1070 983 1058 1102 1089 1084 1110 1023 993 965 999 1049 1009 1004 1001 1036 1068 984 981 1053 966 965 970 998 1005 1006 989 1029 1001 1022 1042 1069 1021 977 1048 1021 1044 1021 1001 1052 1041 985 1032 1060 1037 1016 1032 1031 1056 1010 990 1027 1031 1027 1039 1080 1035 941 1010 1005 1095 1053 1019 1007 1051 1029 1017 1062 1031 1026 997 1023 1004 943 966 1019 1062 1059 996 1059 1011 1018 995 979 1033 989 991 1053 1047 1049 1024 1002 983 1025 995 1001 1006 994 1050 996 1033 965 1114 969 1109 979 1016 1008 918 1048 1050 970 1006 992 1009 997 979 1006 1002 991 1046 1036 1059 1042 1024 980 1016 971 1045 1061 966 990 1031 1001 1052 998 1007 1016 1092 1005 1038 1049 998 1046 1039 962 1064 1035 1017 951 1098 1024 993 892 1027 1020 1031 969 991 950 1037 979 993 957 1035 1027 959 1023 962 953 967 969 987 931 991 961 943 1004 975 1039 1008 955 953 920 968 967 954 922 1003 968 994 960 987 1016 988 1027 974 929 976 977 954 965 1008 942 1008 994 978 998 1020 994 1001 973 881 965 982 926 943 975 960 985 982 915 1008 977 936 964 1020 919 1016 952 1070 965 922 961 933 988 961 965 950 894 906 978 954 982 956 967 1026 961 931 974 1011 967 929 982 955 920 926 957 966 963 960 962 956 951 999 934 969 974 996 964 984 1022 1016 967 968 965 923 927 976 976 938 928 945 976 1017 977 969 928 1012 953 961 931 976 982 896 965 999 935 993 932 1018 940 996 925 894 1005 975 949 985 927 956 934 1017 966 981 973 999 908 1031 982 1021 947 1001 954 938 994 971 990 1040 929 1015 971 984 967 992 982 1003 948 1049 931 987 954 980 948 974 877 996 965 970 962 961 1010 1004 905 1032 934 945 957 1030 1036 1029 908 978 977 1012 928 1033 969 974 926 937 891 985 915 946 1016 1052 956 992 971 1002 901 947 963 937 942 987 980 1008 929 956 931 1034 923 1004 961 970 959 991 922 1022 919 897 918 943 894 977 935 1056 965 941 950 997 888 994 1021 1045 913 999 974 969 921 932 1011 963 874 1007 961 1084 926 964 964 1023 946 961 965 1048 980 992 981 964 947 982 1013 978 935 998 992 979 937 1059 1004 1019 990 994 990 912 987 964 949 919 966 973 998 987 943 965 962 966 923 1026 945 948 984 931 1003 896 991 1026 929 965 933 971 935 960 1003 977 994 969 1001 1087 956 994 984 950 1002 1005 951 978 970 1003 957 917 954 891 978 931 1015 910 1007 927 1013 980 961 937 1007 948 988 1023 1015 934 1003 993 970 984 941 991 975 966 985 960 982 935 938 1009 1013 950 937 956 965 907 963 989 924 996 941 996 945 912 946 1013 929 952 952 909 937 926 979 971 970 976 1006 976 960 934 971 947 926 973 939 1013 926 1001 926 1038 978 939 982 1020 1010 940 938 1002 984 934 971 979 968 943 945 987 988 904 963 973 999 954 938 913 928 995 953 984 922 921 981 1054 1001 1013 917 939 937 954 962 967 964 937 961 917 962 969 982 975 908 943 947 947 964 1025 973 947 968 959 962 987 1005 951 994 967 932 945 980 995 886 963 978 974 1030 1017 936 976 954 943 973 971 914 921 968 989 968 940 943 921 954 962 948 963 981 937 961 954 1018 911 954 931 1010 964 999 983 984 976 968 950 948 922 957 950 988 935 982 943 964 1030 942 936 991 913 989 978 935 927 945 949 999 979 913 1001 971 984 1015 952 998 1031 948 1013 957 974 927 927 965 1040 979 977 979 968 996 981 995 928 962 971 942 939 949 990 989 1039 1001 984 1012 927 965 967 949 984 989 917 979 927 985 966 968 970 976 1027 1032 1002 983 1001 907 1007 950 959 970 970 992 1001 1011 1010 998 920 948 907 991 994 1003 920 1046 969 956 945 973 905 1015 964 981 989 1010 1002 993 977 942 1023 984 947 995 942 1008 913 971 945 989 984 940 1024 975 928 1003 960 1005 990 966 1068 1010 1010 1069 1007 974 957 973 970 995 950 1068 951 1027 996 933 989 1031 919 961 952 1017 999 978 995 1012 1038 952 1055 1030 1001 1032 1027 1022 969 1040 959 1031 967 968 1013 1082 965 989 954 1032 964 964 974 1013 984 993 994 998 953 953 1030 1023 1009 993 1011 1019 1007 1005 999 1008 1031 1005 1017 1042 1020 966 1056 985 1072 1003 1051 1045 1059 1006 1038 1005 1040 1030 1012 1079 1004 1029 1036 1013 1019 1035 964 1066 994 1016 1080 1039 1056 998 1068 1063 980 1029 996 1049 991 1015 1022 1017 1011 1003 1015 1105 1104 1054 992 1008 993 952 1076 1006 1059 968 1069 1018 994 1035 1094 1013 1007 983 1053 1040 1074 1046 979 1044 1037 1035 1062 1005 1095 1012 1070 1063 1082 1056 1082 1015 1097 1069 1013 1079 1129 1045 1064 1015 1069 1081 1140 1112 1088 1041 1112 1090 1153 1073 1097 1128 1175 1051 1157 1138 1108 1069 1187 1142 1146 1214 1279 1217 1245 1300 1373 1274 1389 1487 1556 1460 1621 1920 1711 1732 2024 2328 1986 2010 2512 2153 1856 1896 2107 1660 1608 1746 1686 1393 1421 1481 1404 1328 1407 1466 1450 1301 1445 1434 1365 1388 1500 1572 1415 1492 1862 1555 1504 1686 1840 1448 1458 1604 1486 1301 1333 1294 1224 1194 1243 1219 1121 1118 1175 1184 1046 1129 1082 1080 1065 1091 1086 1124 1060 1115 1029 1001 1049 1067 1146 1053 1065 1105 1124 1093 1035 1070 1016 1063 1076 1079 1073 1087 1112 1051 1044 1018 1072 1023 1092 1021 1031 1029 1125 1064 1026 1017 1011 1030 1077 1070 1042 1049 1046 1051 1045 1139 1020 1023 1082 1080 959 1035 1096 1034 1058 1062 1117 1025 988 1061 1004 981 1013 1006 1025 984 979 1015 1053 1007 1029 1013 1015 1088 1003 990 970 998 956 1017 1030 956 1007 976 1004 929 1045 926 1001 917 989 997 995 1001 961 973 996 981 993 1030 974 1024 954 977 983 980 989 962 1039 989 970 948 979 971 956 956 1037 979 980 1009 952 1026 932 966 925 975 963 1005 966 915 998 936 942 925 953 911 974 961 1004 1023 1005 925 974 952 1012 974 1041 979 965 1038 977 975 964 979 1034 963 992 1024 953 941 978 951 950 961 945 1007 907 955 1008 943 946 998 945 977 997 966 970 967 933 1027 943 976 925 976 924 965 990 943 961 954 911 952 942 934 970 965 948 1002 910 945 903 1015 969 1001 953 999 978 883 995 1036 1008 973 995 943 965 969 1042 968 1011 959 994 962 974 922 971 939 1007 940 993 989 971 956 924 1035 988 960 966 937 978 962 1002 924 1027 979 946 997 971 967 982 1002 991 962 978 933 980 965 947 966 950 984 977 978 999 964 921 917 954 991 948 926 949 967 994 894 992 966 971 934 934 976 1050 941 1038 973 967 978 961 915 1019 960 927 978 974 982 983 941 950 954 988 954 954 911 989 922 981 1009 953 947 964 1032 988 1037 889 945 993 942 1001 922 915 982 917 914 968 945 928 957 924 977 946 952 984 952 998 933 956 977 1004 971 945 952 914 1009 949 989 968 975 948 964 978 973 920 1006 910 920 897 1010 886 914 1022 976 1030 990 990 989 970 957 1010 967 880 943 1018 942 1008 990 999 946 975 965 939 971 965 1009 927 938 982 990 957 970 955 947 957 952 1034 982 1003 951 953 953 939 1026 971 960 979 1020 961 983 959 991 995 968 976 1030 937 974 937 967 956 969 945 966 965 988 1016 984 1004 945 1015 1044 975 932 959 950 968 936 982 975 959 960 1048 994 1024 945 953 1003 955 1010 960 913 924 1098 975 1004 946 1049 1002 965 949 1037 1005 985 1030 1033 1008 988 1050 1058 994 1029 997 1056 942 1026 1019 1036 1040 955 1038 955 998 1011 1010 1045 1058 962 1038 1069 1011 1022 1006 1078 1039 1025 997 1070 1011 989 1053 1019 1033 996 1030 1068 1003 1046 974 1095 1069 1037 988 1038 1039 1042 1007 1067 1017 1026 1080 1048 1027 947 1031 1031 999 1010 1038 1062 1016 1009 994 1080 1002 987 1066 1106 1035 1049 1083 1101 1156 1056 1059 1073 1059 1090 1077 1086 1048 993 1064 1137 1106 1034 1052 1041 1106 1094 1117 1109 1213 1166 1174 1190 1376 1219 1154 1580 1815 1291 1277 1915 1553 1231 1424 1570 1304 1117 1315 1362 1101 1162 1253 1166 1102 1104 1154 1096 1117 1128 1200 1088 1123 1144 1119 1171 1172 1233 1214 1204 1354 1315 1274 1245 1480 1260 1101 1372 1386 1174 1130 1325 1176 1051 1147 1196 1132 1109 1115 1139 1144 1024 1061 1093 1018 1067 1073 1145 1069 1040 1064 1108 1124 1065 1070 1064 1023 1106 1075 1074 1066 1025 1039 1024 1120 1064 1118 1104 1041 1027 1020 1102 1089 1021 1076 1068 1064 1022 1058 1001 1098 1050 990 1049 1017 1068 983 1042 1031 992 983 977 1122 1032 983 997 1110 989 934 1052 1083 1054 1094 1024 1111 1031 970 1037 1048 1013 1024 1017 1076 992 956 1032 1011 932 997 1052 1078 988 1029 1056 1036 998 1006 1004 1003 1012 968 1015 1046 973 965 1037 1008 993 988 981 1069 1011 1046 1015 1077 1024 960 1005 1086 1021 1005 1040 1090 988 1003 1055 1075 1018 1025 965 1064 995 1023 1045 1145 1059 1049 1065 1077 1019 997 998 1053 1019 1053 1015 996 1003 1032 1031 1044 975 1031 1013 1035 974 993 1023 992 1045 978 1108 1095 984 968 1032 1041 1054 970 1007 1040 979 1031 1003 1044 974 959 1013 1108 994 993 1009 987 962 953 1073 1013 1015 980 1036 1056 996 1044 1013 1030 978 943 1050 1049 993 985 955 969 969 941 1031 965 980 957 1052 1035 952 992 1046 994 1023 966 1013 1064 975 1001 971 985 965 987 955 979 960 1060 1006 989 942 1010 999 1016 978 983 977 974 937 1053 949 1001 951 1026 1020 1018 988 1023 966 982 1005 1037 996 1009 950 985 996 1008 970 1036 996 978 966 1006 941 997 963 1037 1039 1046 1010 908 1002 1015 991 977 949 970 1011 987 964 1006 940 970 933 1042 935 998 922 914 919 1002 1033 985 889 980 946 952 1009 1020 929 945 933 963 982 965 961 971 1027 1003 938 1018 981 997 937 965 987 969 979 872 1064 1019 947 1039 942 1010 1027 1038 1017 960 959 960 1004 952 927 1031 1030 1001 965 1021 1035 957 981 982 978 1009 961 960 931 909 1023 993 1023 1007 966 960 1016 950 915 993 940 947 954 980 967 936 937 1012 1002 929 1004 1011 1004 985 1018 995 993 989 983 950 985 912 951 935 998 932 1004 999 982 913 965 989 985 971 933 1076 1002 974 995 991 1002 978 987 1024 948 981 1022 1038 959 991 956 973 992 962 904 981 969 981 971 979 945 984 1006 1001 976 970 974 1008 977 908 991 1002 1036 980 964 1016 925 979 974 899 957 949 994 975 1019 997 1025 1058 1010 897 996 1011 990 950 1010 936 1051 956 941 1017 962 973 964 962 996 913 990 975 1024 934 960 1006 1025 940 954 1003 907 965 949 994 988 1008 959 1022 937 999 969 1018 1027 1003 1023 977 977 1047 964 947 974 1058 984 954 971 954 969 1030 985 934 1007 1026 993 926 1029 991 961 969 962 1001 961 989 953 1036 1011 932 988 1036 954 1033 955 1039 984 984 941 1056 1023 1010 953 992 1046 925 941 1030 977 985 969 950 1013 1029 975 990 985 937 961 950 1013 950 1034 1026 975 1025 969 982 1040 982 924 957 971 955 1029 978 1008 994 977 1017 1025 959 923 941 973 990 984 1022 987 991 1047 999 1012 1016 990 1045 954 1024 1022 983 964 973 997 1004 1026 989 1087 1026 1012 1001 970 1051 1004 1037 984 1009 963 1049 1010 1052 1031 1016 981 1074 1033 1091 1068 989 996 1007 1040 983 1033 1025 1012 952 1063 1041 999 1011 1059 991 999 970 992 1023 1012 997 1068 1080 1004 1007 988 990 1015 1022 1026 995 1054 998 996 1083 1045 1031 1038 1047 1092 1010 1033 1077 1005 1082 1019 1027 1060 990 1024 1023 1026 957 1009 997 1027 1008 962 981 1042 1019 1025 991 1037 1049 953 1040 1027 1010 1016 1062 974 977 901 1020 1040 983 975 1092 1039 1020 968 1005 1013 927 947 1015 1052 978 1021 1069 1005 1042 954 1050 1032 981 960 1041 1063 999 928 1002 994 990 973 974 1022 955 971 1076 1026 1045 994 973 963 1046 995 955 973 990 990 993 985 956 955 1017 1008 1032 1059 1020 1092 1056 1039 1041 1045 1037 948 999 1021 1026 1039 1012 1008 1067 941 1031 994 1036 947 1008 1025 1015 1023 985 1008 1061 980 974 1007 1006 1002 1022 975 970 994 960 1001 1065 1034 996 1017 1025 981 991 1060 1050 940 1073 999 927 1021 996 992 1078 1003 934 984 1072 961 1022 1038 980 989 964 1050 1038 992 999 1003 1022 1009 943 950 1100 984 1010 999 1009 998 970 991 947 980 945 945 1032 925 1019 1076 993 914 939 976 1008 1040 968 956 1006 980 975 928 1019 1008 1020 1042</intensities>
			</dataPoints>
		</scan>
	</xrdMeasurement>
</xrdMeasurements>