File: Data availability/00_STD_IN718_HT3X.xrdml
<?xml version="1.0" encoding="UTF-8"?>
<xrdMeasurements xmlns="http://www.xrdml.com/XRDMeasurement/1.6" xmlns:xsi="http://www.w3.org/2001/XMLSchema-instance" xsi:schemaLocation="http://www.xrdml.com/XRDMeasurement/1.6 http://www.xrdml.com/XRDMeasurement/1.6/XRDMeasurement.xsd" status="Completed">
	<comment>
		<entry>Configuration=reflection - transmission spinner, Owner=User-1, Creation date=10/26/2007 2:30:26 PM</entry>
		<entry>Goniometer=PW3050/60 (Theta/Theta); Minimum step size 2Theta:0.001; Minimum step size Omega:0.001</entry>
		<entry>Sample stage=Reflection-Transmission Spinner PW3064/60; Minimum step size Phi:0.1</entry>
		<entry>Diffractometer system=XPERT-PRO</entry>
		<entry>Measurement program=C:\PANalytical\Data Collector\Programs\00_STD_IN718.xrdmp, Identifier={28380439-0F33-476B-A426-78B1F912C0F4}</entry>
		<entry>Batch program=C:\PANalytical\Data Collector\Programs\00_patch_IN718.xrdmp, Identifier={40C978E3-ABC2-4E6C-9A3B-A5D759AE5D9D}</entry>
	</comment>
	<sample type="To be analyzed">
		<id></id>
		<name></name>
		<preparedBy></preparedBy>
	</sample>
	<xrdMeasurement measurementType="Scan" status="Completed" sampleMode="Reflection">
		<comment>
			<entry>20-130 angle .004 step 30s </entry>
			<entry>PHD Lower Level = 5.34 (keV), PHD Upper Level = 11.09 (keV)</entry>
		</comment>
		<usedWavelength intended="K-Alpha 1">
			<kAlpha1 unit="Angstrom">1.7890100</kAlpha1>
			<kAlpha2 unit="Angstrom">1.7929000</kAlpha2>
			<kBeta unit="Angstrom">1.6208300</kBeta>
			<ratioKAlpha2KAlpha1>0.5000</ratioKAlpha2KAlpha1>
		</usedWavelength>
		<incidentBeamPath>
			<radius unit="mm">240.00</radius>
			<xRayTube id="1010042" name="Empyrean Co LFF (9430 033 7600x) DK417097">
				<tension unit="kV">40.0</tension>
				<current unit="mA">45.0</current>
				<anodeMaterial>Co</anodeMaterial>
				<focus type="Line">
					<length unit="mm">12.0</length>
					<width unit="mm">0.4</width>
					<takeOffAngle unit="deg">6.0</takeOffAngle>
				</focus>
			</xRayTube>
			<filter id="20010003" name="Beta-filter Iron">
				<material>Fe</material>
				<thickness unit="mm">0.016</thickness>
			</filter>
			<sollerSlit id="21010002" name="Soller slits 0.04 rad.">
				<opening unit="rad">0.0400</opening>
			</sollerSlit>
			<mask id="22080002" name="Fixed incident beam mask 10 mm">
				<width unit="mm">6.60</width>
			</mask>
			<antiScatterSlit id="22010002" name="Fixed slit 2°" xsi:type="fixedAntiScatterSlitType">
				<height unit="mm">3.03</height>
			</antiScatterSlit>
			<divergenceSlit id="22010001" name="Fixed slit 4°" xsi:type="fixedDivergenceSlitType">
				<distanceToSample unit="mm">140.00</distanceToSample>
				<height unit="mm">5.88</height>
			</divergenceSlit>
		</incidentBeamPath>
		<sampleMovement xsi:type="spinningSampleMovementType">
			<spinnerRevolutionTime unit="seconds">4.0</spinnerRevolutionTime>
		</sampleMovement>
		<diffractedBeamPath>
			<radius unit="mm">240.00</radius>
			<antiScatterSlit id="22090005" name="AS slit 6.6 mm (X'Celerator)" xsi:type="fixedAntiScatterSlitType">
				<height unit="mm">6.60</height>
			</antiScatterSlit>
			<sollerSlit id="21010002" name="Soller slits 0.04 rad.">
				<opening unit="rad">0.0400</opening>
			</sollerSlit>
			<detector id="7010013" name="X'Celerator detector" xsi:type="rtmsDetectorType">
				<phd>
					<lowerLevel unit="%">38.5</lowerLevel>
					<upperLevel unit="%">80.0</upperLevel>
				</phd>
				<mode>Scanning</mode>
				<activeLength unit="deg">2.022</activeLength>
			</detector>
		</diffractedBeamPath>
		<scan appendNumber="0" mode="Continuous" scanAxis="Gonio" status="Completed">
			<header>
				<startTimeStamp>2020-03-10T03:23:13-07:00</startTimeStamp>
				<endTimeStamp>2020-03-10T05:15:02-07:00</endTimeStamp>
				<author>
					<name>User</name>
				</author>
				<source>
					<applicationSoftware version="5.4">Data Collector</applicationSoftware>
					<instrumentControlSoftware version="2.2D 20160920">XPERT-PRO</instrumentControlSoftware>
					<instrumentID>0000000011030022</instrumentID>
				</source>
			</header>
			<dataPoints>
				<positions axis="2Theta" unit="deg">
					<startPosition>20.00008891</startPosition>
					<endPosition>129.99783913</endPosition>
				</positions>
				<positions axis="Omega" unit="deg">
					<startPosition>10.00004445</startPosition>
					<endPosition>64.99891957</endPosition>
				</positions>
				<positions axis="Phi" unit="deg">
					<commonPosition>150.6</commonPosition>
				</positions>
				<commonCountingTime unit="seconds">30.250</commonCountingTime>
				<intensities 1278 1262 1285 1289 1348 1276 1290 1255 1359 1356 1259 1288 1312 1321 1319 1308 1315 1269 1280 1297 1299 1311 1232 1312 1263 1322 1319 1338 1257 1312 1274 1299 1318 1308 1275 1277 1313 1289 1331 1283 1305 1291 1257 1270 1288 1329 1327 1273 1371 1309 1312 1286 1392 1321 1328 1273 1286 1272 1214 1332 1265 1305 1269 1230 1262 1270 1271 1287 1312 1206 1294 1300 1283 1233 1351 1260 1274 1287 1229 1267 1248 1322 1241 1264 1255 1217 1250 1305 1280 1267 1299 1232 1309 1243 1263 1246 1281 1333 1232 1225 1306 1290 1260 1278 1306 1211 1263 1286 1251 1291 1294 1235 1311 1258 1313 1302 1287 1210 1277 1204 1311 1245 1259 1276 1281 1243 1290 1274 1223 1233 1208 1262 1250 1267 1196 1280 1287 1281 1302 1322 1345 1251 1278 1281 1295 1285 1208 1263 1214 1165 1259 1255 1236 1317 1246 1210 1293 1243 1261 1269 1234 1189 1248 1245 1252 1206 1238 1251 1242 1201 1244 1223 1211 1208 1211 1265 1292 1239 1235 1272 1188 1236 1192 1270 1208 1299 1260 1213 1242 1215 1227 1199 1290 1216 1227 1261 1219 1262 1245 1280 1265 1319 1241 1177 1165 1215 1248 1269 1206 1156 1218 1206 1181 1224 1238 1293 1269 1244 1191 1206 1201 1243 1173 1252 1246 1241 1249 1217 1232 1234 1255 1196 1175 1180 1204 1216 1205 1261 1239 1259 1192 1214 1219 1261 1241 1181 1242 1237 1232 1182 1145 1260 1164 1176 1247 1264 1191 1274 1217 1228 1228 1168 1144 1201 1165 1239 1164 1237 1117 1205 1208 1178 1199 1265 1200 1205 1200 1184 1130 1217 1270 1200 1149 1243 1208 1228 1280 1223 1208 1216 1220 1250 1158 1184 1202 1308 1176 1220 1210 1199 1203 1253 1253 1204 1142 1175 1182 1133 1238 1206 1221 1189 1181 1101 1147 1167 1242 1153 1218 1244 1207 1168 1130 1237 1228 1191 1132 1211 1149 1196 1164 1208 1177 1147 1195 1151 1170 1199 1230 1207 1163 1211 1202 1202 1206 1206 1177 1236 1176 1202 1176 1199 1205 1199 1193 1120 1196 1179 1151 1150 1192 1154 1230 1256 1133 1202 1189 1166 1128 1244 1232 1185 1229 1239 1233 1134 1193 1255 1189 1241 1237 1232 1245 1244 1239 1163 1228 1160 1173 1173 1229 1152 1188 1218 1251 1199 1252 1302 1199 1218 1253 1287 1262 1158 1243 1180 1204 1192 1168 1225 1214 1159 1245 1228 1157 1252 1230 1196 1163 1239 1195 1216 1161 1237 1152 1193 1260 1131 1117 1191 1192 1239 1245 1208 1309 1253 1202 1253 1214 1277 1177 1239 1166 1229 1272 1250 1195 1277 1221 1247 1219 1234 1217 1275 1207 1277 1206 1224 1224 1228 1184 1215 1235 1249 1235 1273 1253 1230 1211 1278 1250 1220 1223 1317 1233 1278 1272 1230 1206 1291 1145 1249 1245 1301 1241 1253 1238 1311 1278 1253 1253 1250 1278 1229 1326 1233 1190 1200 1251 1204 1207 1263 1232 1255 1213 1287 1298 1302 1216 1222 1260 1295 1251 1289 1298 1285 1190 1243 1263 1195 1275 1227 1253 1328 1298 1331 1291 1327 1218 1187 1308 1222 1248 1219 1328 1239 1237 1222 1264 1257 1227 1201 1209 1304 1262 1267 1262 1248 1263 1215 1250 1246 1236 1253 1293 1385 1302 1245 1265 1290 1241 1245 1223 1288 1238 1220 1340 1396 1263 1224 1270 1291 1181 1273 1343 1357 1223 1255 1235 1264 1259 1237 1262 1317 1287 1253 1197 1284 1291 1266 1274 1312 1266 1206 1338 1300 1235 1237 1263 1264 1290 1263 1286 1242 1211 1219 1251 1248 1229 1302 1209 1243 1257 1206 1250 1278 1252 1220 1251 1230 1342 1230 1190 1250 1248 1217 1271 1271 1200 1197 1244 1265 1256 1193 1258 1273 1309 1274 1229 1341 1241 1245 1237 1223 1205 1188 1316 1293 1289 1278 1286 1307 1307 1187 1245 1302 1241 1232 1245 1330 1220 1241 1247 1348 1246 1222 1288 1293 1244 1227 1228 1241 1217 1211 1216 1287 1284 1185 1207 1325 1285 1269 1307 1285 1291 1194 1269 1290 1262 1209 1305 1311 1349 1222 1252 1359 1264 1195 1215 1345 1202 1242 1221 1251 1210 1180 1228 1164 1211 1228 1182 1246 1211 1203 1195 1210 1197 1238 1209 1277 1168 1288 1187 1284 1199 1191 1195 1228 1188 1220 1164 1200 1301 1209 1140 1199 1271 1107 1111 1188 1216 1252 1201 1256 1190 1218 1129 1207 1166 1157 1232 1200 1237 1154 1222 1234 1158 1178 1215 1197 1143 1115 1188 1175 1164 1164 1182 1217 1137 1103 1156 1203 1116 1156 1199 1219 1188 1133 1189 1192 1129 1179 1203 1217 1168 1166 1182 1220 1182 1144 1173 1165 1166 1171 1172 1163 1225 1180 1231 1152 1197 1095 1182 1143 1149 1145 1129 1149 1120 1174 1181 1118 1156 1076 1217 1135 1075 1193 1103 1174 1167 1162 1182 1175 1196 1180 1114 1110 1156 1164 1145 1154 1140 1152 1128 1070 1150 1178 1152 1108 1224 1092 1146 1156 1190 1149 1096 1130 1191 1159 1092 1194 1087 1114 1133 1120 1153 1158 1122 1105 1172 1146 1161 1202 1103 1120 1206 1102 1164 1147 1130 1139 1227 1123 1159 1175 1163 1148 1138 1136 1221 1130 1114 1152 1138 1180 1160 1165 1131 1167 1147 1130 1142 1131 1205 1089 1112 1088 1179 1147 1178 1136 1144 1187 1241 1153 1144 1140 1124 1152 1132 1172 1139 1137 1107 1179 1178 1179 1178 1138 1123 1220 1144 1218 1174 1239 1184 1154 1223 1180 1259 1168 1218 1173 1180 1195 1241 1176 1173 1291 1206 1204 1231 1286 1222 1273 1383 1250 1247 1290 1292 1216 1270 1265 1356 1281 1261 1262 1327 1213 1250 1293 1346 1259 1286 1250 1322 1232 1273 1327 1272 1295 1285 1348 1325 1263 1289 1389 1365 1243 1275 1341 1387 1250 1325 1379 1379 1345 1348 1314 1319 1302 1292 1349 1340 1301 1380 1375 1336 1227 1371 1392 1342 1317 1389 1422 1404 1309 1403 1375 1411 1278 1342 1372 1497 1370 1314 1401 1475 1374 1369 1498 1443 1461 1331 1477 1396 1485 1449 1388 1426 1516 1456 1511 1461 1469 1454 1577 1477 1563 1435 1516 1488 1389 1383 1562 1541 1515 1414 1636 1570 1549 1417 1650 1551 1410 1496 1573 1571 1459 1457 1584 1510 1542 1525 1596 1594 1567 1480 1561 1572 1484 1466 1712 1607 1571 1429 1577 1556 1500 1462 1607 1531 1534 1427 1577 1466 1473 1462 1619 1450 1490 1467 1625 1531 1462 1415 1544 1521 1493 1433 1575 1467 1442 1355 1577 1422 1486 1400 1535 1460 1422 1347 1476 1426 1518 1431 1443 1333 1404 1303 1483 1417 1489 1355 1475 1371 1416 1349 1434 1385 1416 1280 1418 1377 1411 1351 1459 1404 1469 1374 1356 1309 1384 1369 1407 1338 1499 1323 1397 1299 1400 1317 1403 1294 1350 1340 1413 1340 1350 1286 1361 1291 1429 1288 1349 1278 1386 1275 1371 1336 1340 1308 1403 1241 1345 1228 1357 1249 1351 1264 1276 1277 1365 1272 1289 1250 1264 1260 1245 1182 1191 1147 1316 1157 1184 1149 1227 1201 1178 1188 1239 1249 1247 1255 1272 1261 1246 1121 1202 1121 1180 1179 1184 1144 1213 1105 1137 1168 1161 1166 1196 1201 1205 1138 1216 1137 1130 1070 1134 1078 1130 1174 1188 1145 1078 1087 1214 1122 1109 1146 1178 1144 1110 1124 1165 1231 1156 1058 1158 1163 1178 1134 1176 1184 1251 1227 1257 1193 1261 1206 1260 1157 1152 1166 1147 1195 1230 1242 1194 1201 1213 1244 1202 1281 1277 1255 1231 1182 1223 1294 1206 1290 1263 1262 1217 1187 1302 1275 1161 1295 1331 1260 1182 1259 1277 1317 1232 1264 1284 1220 1230 1189 1276 1241 1267 1259 1267 1236 1191 1286 1260 1262 1274 1248 1293 1211 1177 1200 1269 1252 1237 1209 1283 1229 1283 1288 1245 1217 1229 1279 1266 1189 1333 1249 1323 1223 1274 1217 1297 1344 1291 1208 1271 1262 1235 1289 1319 1295 1306 1246 1314 1301 1334 1311 1330 1328 1286 1270 1357 1358 1303 1312 1398 1322 1312 1228 1365 1357 1286 1292 1358 1314 1345 1311 1402 1327 1232 1278 1390 1382 1244 1290 1387 1357 1295 1244 1422 1394 1276 1318 1433 1389 1374 1309 1411 1407 1299 1352 1425 1391 1312 1371 1419 1397 1325 1267 1475 1387 1245 1207 1422 1319 1321 1348 1362 1328 1216 1307 1356 1275 1196 1208 1363 1297 1225 1189 1371 1270 1239 1251 1373 1235 1193 1179 1237 1316 1164 1203 1330 1311 1225 1239 1308 1257 1227 1165 1256 1241 1298 1180 1358 1227 1232 1196 1248 1267 1161 1149 1358 1267 1280 1250 1300 1263 1205 1249 1288 1241 1297 1211 1275 1303 1193 1194 1271 1269 1257 1130 1290 1269 1255 1171 1302 1264 1235 1209 1299 1269 1215 1195 1293 1220 1258 1241 1284 1237 1238 1136 1330 1258 1225 1231 1274 1181 1217 1154 1217 1229 1180 1202 1266 1305 1181 1227 1249 1222 1239 1190 1235 1270 1181 1187 1218 1301 1147 1133 1194 1173 1236 1140 1170 1247 1178 1215 1218 1213 1172 1181 1186 1204 1130 1199 1177 1197 1222 1206 1217 1248 1165 1220 1110 1161 1206 1129 1191 1159 1151 1174 1158 1158 1145 1179 1178 1148 1258 1125 1135 1117 1197 1128 1171 1197 1160 1157 1223 1190 1129 1171 1101 1128 1206 1144 1136 1186 1187 1180 1176 1161 1128 1090 1186 1180 1095 1162 1104 1193 1146 1150 1134 1156 1111 1140 1172 1215 1154 1144 1231 1126 1224 1168 1178 1122 1076 1121 1120 1091 1122 1154 1086 1140 1182 1102 1078 1109 1143 1147 1114 1172 1193 1102 1179 1125 1182 1165 1121 1162 1163 1122 1069 1161 1116 1151 1124 1108 1116 1182 1108 1188 1142 1095 1087 1110 1171 1080 1122 1115 1052 1125 1129 1121 1088 1140 1111 1089 1138 1070 1163 1151 1094 1075 1153 1176 1083 1132 1112 1129 1131 1109 1179 1156 1111 1125 1176 1184 1153 1151 1191 1186 1109 1110 1116 1153 1100 1143 1182 1139 1111 1065 1118 1093 1058 1053 1111 1075 1039 1050 1061 1064 1049 1084 1081 1045 1132 1079 1086 1046 1083 1076 1089 1049 1073 1056 1094 1149 1097 1156 1050 1090 1050 1045 1112 1119 1083 1121 1049 1126 1093 1077 1108 1052 1154 1106 1109 1065 1045 1047 1089 1159 1087 1044 1109 1126 1064 1070 1131 1105 1075 1033 1122 1056 1094 1015 1096 1093 1088 1048 1066 1018 1066 1097 1129 1110 1067 1056 1050 1069 1131 1041 1052 1059 1140 1059 1066 1105 1132 1065 1144 1140 1068 1108 1106 1096 1045 1054 1125 1050 1062 1078 1089 1070 1081 1111 1039 1079 1082 1095 1092 1031 1060 1075 1135 1054 1003 1031 1098 1038 1132 1120 1052 1185 1117 998 1106 1060 1108 1090 1109 1061 1090 1072 1087 988 1035 1069 1126 1110 1077 1061 1095 1107 1083 999 1054 1058 1079 1013 1098 1061 1122 1048 1076 1048 1052 1097 1077 1098 1019 1123 1114 1051 1150 1056 1072 1074 1024 1068 1032 1054 1069 1023 1131 1094 1074 1104 1019 1087 1046 1078 1110 1088 1102 1050 1087 1026 1055 1080 1079 1074 1082 1097 1087 1070 1064 1065 1087 1013 1050 1096 1051 1118 1086 1089 1110 1073 1094 1165 1131 1088 1125 1072 1179 1146 1083 1026 1138 1096 1101 1079 1129 1105 1046 1111 1087 1081 1108 1030 1110 1056 1084 1115 1050 1041 1032 1087 1142 1128 1050 1029 1068 1090 1078 1055 1034 1082 1042 1047 1055 1104 1086 1129 1124 1094 1090 1072 1034 1063 1126 1095 1048 1067 1047 1090 1097 1031 1096 1048 1104 1084 1025 1076 1053 1040 1078 1081 1045 1126 1117 1116 1047 1128 1066 1062 1115 1063 1144 1067 1049 1063 1118 1124 1082 1066 1094 1114 1083 1114 1112 1161 1110 1129 1076 1111 1159 1104 1084 1144 1089 1074 1082 1087 1077 1048 1093 1074 1081 1075 1134 1089 1084 1075 1087 1153 1095 1154 1047 1125 1107 1138 1077 1122 1103 1065 1120 1162 1163 1106 1138 1159 1084 1021 1122 1124 1077 1025 1096 1139 1121 1106 1097 1083 1079 1055 1094 1174 1035 1106 1068 1072 1125 1081 1080 1086 1121 1074 1082 1157 1121 1124 1167 1170 1117 1111 1040 1184 1077 1090 1097 1196 1108 1125 1091 1165 1029 1161 1031 1137 1046 1062 1101 1116 1049 1073 1090 1070 1092 1112 1076 1056 1078 1044 1067 1098 1095 1094 1063 1055 1060 1105 1130 1070 1096 1053 1089 1165 1053 1097 1066 1079 1139 1084 1046 1124 1051 1045 1111 1082 1119 1082 1076 1050 1017 1117 1090 1089 1048 1070 1036 1118 1034 1060 1065 1079 1074 1067 1052 1077 1076 1052 1105 1064 1074 1054 1010 1072 1069 1086 1072 1047 1098 1062 1018 1007 1068 1075 1094 1009 1100 1032 1101 1105 1056 1096 1021 995 1087 1038 1029 1092 1104 1072 1118 1073 1091 1020 1005 1045 1095 1004 1044 1049 985 1132 1112 1101 1045 1064 1105 1114 1115 1069 1105 1125 1106 1044 1096 1110 1134 1097 1070 1091 1119 1154 1149 1145 1128 1114 1093 1070 1134 1158 1107 1121 1115 1131 1128 1121 1184 1105 1088 1108 1093 1176 1082 1131 1197 1173 1162 1133 1191 1114 1098 1150 1068 1126 1055 1093 1151 1060 1049 1116 1083 1130 1056 1090 1070 1097 1086 1156 1162 1066 1139 1135 1125 1058 1080 1118 1110 1102 1078 1109 1039 1041 1136 1081 1088 1060 1083 1080 1041 1116 1076 1086 1132 1090 1093 1041 1073 1054 1076 1116 1139 1126 1103 1181 1121 1069 1091 1136 1077 1081 1066 1105 1115 1144 1136 1072 1153 1145 1029 1120 1067 1104 1117 1138 1128 1157 1096 1115 1125 1129 1109 1130 1089 1111 1135 1181 1095 1100 1138 1171 1107 1134 1145 1203 1132 1136 1112 1134 1151 1142 1186 1091 1176 1146 1124 1114 1137 1083 1173 1166 1137 1078 1168 1130 1187 1090 1206 1088 1116 1092 1131 1143 1170 1180 1164 1140 1174 1116 1087 1120 1173 1109 1182 1175 1088 1172 1168 1164 1172 1187 1143 1219 1224 1149 1193 1214 1194 1112 1153 1185 1146 1165 1221 1185 1170 1203 1194 1213 1165 1203 1249 1247 1194 1271 1257 1238 1189 1131 1124 1247 1162 1176 1208 1265 1206 1150 1192 1190 1197 1136 1207 1247 1259 1172 1158 1248 1249 1101 1184 1187 1167 1191 1239 1216 1199 1163 1280 1219 1205 1236 1238 1211 1200 1237 1201 1244 1239 1277 1232 1255 1302 1253 1219 1312 1270 1288 1378 1360 1364 1311 1328 1359 1402 1311 1438 1511 1573 1590 1608 1741 1898 2080 2309 2526 2829 3054 3560 4184 4479 4861 5805 5914 4814 4940 4891 3821 3305 3529 3577 3232 3346 3591 3294 2491 2329 2192 1797 1521 1565 1555 1411 1415 1470 1400 1325 1384 1428 1344 1273 1356 1355 1300 1278 1322 1329 1278 1250 1261 1293 1246 1229 1197 1205 1244 1144 1228 1251 1171 1158 1122 1203 1202 1140 1196 1194 1167 1182 1248 1219 1180 1164 1116 1135 1178 1189 1147 1158 1105 1177 1224 1179 1148 1161 1194 1123 1136 1133 1233 1260 1126 1143 1166 1138 1138 1200 1125 1162 1156 1121 1129 1144 1112 1112 1149 1123 1066 1090 1107 1167 1122 1121 1138 1058 1122 1089 1170 1108 1125 1132 1194 1138 1089 1175 1172 1097 1138 1145 1062 1152 1156 1041 1209 1132 1134 1131 1170 1079 1165 1090 1193 1074 1181 1082 1138 1117 1110 1120 1122 1123 1164 1190 1202 1144 1075 1197 1109 1177 1174 1134 1160 1149 1132 1107 1213 1186 1146 1204 1217 1218 1167 1193 1221 1177 1241 1197 1172 1126 1186 1166 1133 1172 1123 1197 1152 1142 1205 1152 1176 1209 1206 1175 1261 1166 1186 1208 1202 1189 1211 1230 1195 1216 1255 1219 1222 1189 1203 1250 1189 1228 1275 1225 1224 1204 1228 1274 1257 1221 1167 1273 1207 1221 1211 1283 1246 1224 1245 1239 1257 1142 1153 1242 1185 1214 1221 1214 1228 1210 1204 1301 1143 1264 1258 1242 1196 1142 1214 1246 1216 1224 1261 1291 1230 1270 1301 1277 1217 1297 1239 1340 1222 1241 1337 1352 1225 1214 1261 1263 1247 1247 1252 1290 1209 1208 1248 1216 1266 1197 1205 1285 1156 1193 1213 1195 1196 1164 1166 1174 1117 1253 1123 1225 1237 1186 1189 1220 1205 1184 1090 1211 1138 1159 1126 1209 1131 1131 1150 1154 1178 1182 1173 1105 1133 1151 1131 1191 1182 1168 1098 1148 1150 1148 1167 1263 1108 1150 1115 1206 1124 1239 1147 1175 1156 1193 1144 1236 1087 1162 1177 1108 1144 1111 1129 1147 1128 1061 1137 1140 1112 1108 1104 1157 1130 1093 1094 1102 1098 1098 1034 1189 1046 1088 1153 1131 1068 1107 1132 1173 1102 1133 1090 1143 1088 1081 1138 1124 1069 1095 1115 1118 1140 1091 1068 1061 1129 1093 1069 1065 1067 1102 1195 1152 1076 1156 1083 1117 1142 1064 1041 1153 1089 1053 1007 1083 1061 1074 1100 1098 1069 1151 1095 1101 1077 1059 1151 1083 1068 1174 1083 1095 1116 1108 1058 1061 1140 1081 1133 1097 1103 1136 1142 1128 1109 1104 1165 1073 1139 1203 1173 1132 1148 1106 1149 1144 1079 1182 1157 1114 1081 1069 1131 1095 1045 1101 1126 1097 1117 1067 1112 1186 1192 1053 1134 1164 1083 1088 1082 1139 1066 1153 1076 1192 1115 1104 1104 1104 1103 1072 1150 1052 1206 1158 1144 1121 1109 1156 1163 1082 1118 1144 1098 1168 1096 1154 1108 1144 1133 1124 1210 1130 1144 1163 1164 1167 1112 1161 1078 1170 1160 1140 1185 1146 1126 1148 1172 1151 1145 1095 1152 1158 1129 1168 1158 1095 1146 1157 1195 1090 1101 1112 1160 1161 1094 1086 1195 1108 1102 1160 1137 1091 1111 1153 1182 1159 1144 1199 1180 1130 1091 1176 1197 1165 1135 1125 1111 1161 1134 1100 1074 1173 1110 1086 1181 1145 1124 1219 1110 1158 1201 1207 1176 1163 1162 1150 1186 1164 1096 1160 1128 1139 1178 1157 1115 1094 1190 1182 1156 1093 1239 1191 1144 1142 1191 1156 1142 1245 1186 1176 1218 1176 1165 1186 1125 1245 1269 1206 1279 1152 1249 1236 1205 1217 1245 1249 1229 1209 1200 1300 1215 1192 1256 1337 1278 1215 1276 1316 1279 1221 1348 1360 1257 1313 1290 1392 1322 1382 1355 1340 1325 1329 1337 1330 1368 1384 1361 1390 1301 1388 1448 1371 1373 1398 1368 1410 1388 1387 1431 1408 1393 1419 1379 1415 1434 1474 1434 1439 1476 1517 1482 1478 1532 1481 1616 1729 1639 1624 1808 1770 1814 1909 1983 2087 2218 2434 2564 2672 2737 3046 3265 3484 3967 4093 4445 4771 5458 6044 6008 6710 7443 7726 7418 7955 7982 7044 6367 6106 5523 4808 4562 4781 4656 4413 4465 4366 3917 3544 3210 2610 2208 2159 2010 1842 1720 1726 1686 1626 1621 1573 1517 1583 1631 1585 1498 1558 1532 1619 1446 1478 1491 1556 1456 1485 1568 1427 1431 1485 1491 1404 1469 1435 1432 1374 1422 1420 1407 1376 1380 1397 1309 1364 1336 1281 1322 1265 1341 1302 1278 1318 1225 1288 1267 1262 1257 1174 1181 1257 1117 1236 1111 1165 1171 1178 1176 1132 1217 1195 1185 1137 1097 1207 1088 1087 1140 1173 1101 1098 1109 1147 1100 1083 1142 1140 1053 1082 1050 1109 1089 1123 1080 1094 1149 1121 1122 1129 1088 1091 1096 1052 1063 1120 1088 1052 1092 1077 1102 1110 1053 1092 1069 1151 1100 1106 1134 1069 1081 1131 1118 1139 1064 1055 1003 1091 1080 1087 1112 1120 1010 1066 1117 1079 1077 1097 1094 1115 1090 1047 1112 1066 1101 1072 1090 1109 1084 1065 1087 1080 1102 1036 1077 1042 1015 1106 1072 1074 1090 1192 1031 1065 1079 1026 1075 1047 1144 1146 1075 1145 1094 1125 1120 1107 1117 1134 1174 1102 1184 1150 1105 1140 1164 1111 1112 1154 1182 1261 1120 1211 1292 1323 1140 1215 1245 1317 1117 1228 1224 1377 1160 1210 1251 1314 1172 1246 1275 1297 1150 1181 1275 1288 1078 1162 1313 1262 1090 1170 1208 1234 1138 1208 1315 1295 1172 1242 1255 1352 1102 1237 1286 1362 1144 1193 1344 1304 1156 1195 1311 1285 1148 1250 1277 1345 1142 1259 1300 1266 1117 1206 1219 1361 1184 1217 1272 1290 1149 1229 1192 1261 1162 1231 1214 1252 1192 1176 1279 1303 1180 1259 1297 1264 1110 1234 1273 1277 1137 1163 1236 1289 1131 1250 1267 1316 1165 1199 1243 1233 1145 1171 1291 1313 1126 1217 1257 1288 1182 1190 1229 1360 1125 1261 1209 1322 1124 1213 1311 1322 1106 1209 1191 1207 1132 1130 1291 1264 1038 1184 1151 1228 1126 1125 1188 1320 1162 1187 1196 1232 1089 1186 1272 1229 1058 1116 1168 1259 1084 1150 1182 1196 1135 1122 1203 1243 1083 1066 1270 1101 1067 1058 1061 1083 1123 1119 991 1123 1012 1111 1082 1021 1073 1100 1019 1004 1013 1091 1053 1038 1041 991 1046 994 1027 1019 1050 963 1050 959 1091 1024 1026 1055 1039 1061 1031 1030 1027 1041 1018 1088 1025 987 1011 963 1031 977 1003 1055 1062 1076 1044 1031 1046 964 993 1004 1008 1080 1026 1019 1001 1026 1024 1062 1060 1038 1044 1090 1030 1037 1022 1026 995 976 1045 999 989 1015 946 1032 1041 1033 1017 1032 978 1011 1036 1045 1051 1035 1128 1038 980 1006 1042 997 1004 1027 1030 1018 1026 997 1049 1022 1076 1017 1056 1017 998 1054 976 1030 1020 1002 1013 1013 1091 1064 1045 1001 987 1015 1010 1078 1001 1015 996 987 1046 1061 1029 999 988 992 1040 1025 965 1011 1053 1025 1025 1081 1018 1041 981 1046 1070 1059 1054 1013 1024 1049 1080 1012 1031 995 983 1037 1031 1060 1058 1015 1064 1022 1037 1018 1022 1056 1060 1034 1032 1016 1041 1020 1030 1025 1015 1030 981 970 1038 1005 1097 1017 1023 981 1005 1073 1025 1008 1041 1026 980 981 1012 985 1049 1066 1020 998 1061 1008 1038 1080 1009 1051 1010 1040 987 1029 1075 1018 1055 1010 1069 1041 960 1041 996 1056 1019 1086 1061 998 1079 1106 999 1096 992 1032 993 1089 1045 1056 1031 1044 1019 1034 1039 1018 1042 1038 1058 1052 1081 1026 1034 1029 1029 1041 1008 1027 990 1030 1044 1070 1066 1053 1035 1073 1060 1083 1020 1076 1052 1027 961 1026 1017 1063 1045 1017 995 1075 1008 1074 1050 1049 1064 987 1080 1026 1054 1042 990 1063 1055 973 1087 1063 1072 1023 1069 1022 1033 1084 1068 1019 1091 1045 1027 1082 1052 1036 1047 1062 1035 1054 1097 999 1101 1097 1146 1061 1083 1093 1089 1066 1045 1075 1101 1063 1049 1036 1069 1090 1070 1053 1038 1074 1041 1107 1065 1044 1050 1069 1080 1104 1054 1080 1060 1047 1118 1103 1068 1148 1077 1047 1092 1088 1139 1123 1138 1096 1119 1097 1061 1107 1135 1044 1097 1080 1131 1081 1151 1089 1088 1084 1123 1093 1146 1094 1002 1129 1145 1044 1065 1034 1149 1089 1095 1117 1123 1101 1120 1060 1166 1083 1097 1063 1138 1024 1200 1092 1167 1143 1133 1132 1126 1030 1179 1093 1147 1086 1108 1115 1115 1137 1125 1131 1166 1084 1139 1156 1140 1154 1088 1120 1119 1120 1173 1107 1076 1214 1161 1132 1133 1136 1149 1075 1137 1149 1158 1163 1214 1156 1209 1162 1156 1204 1172 1151 1104 1149 1201 1136 1161 1129 1203 1092 1151 1150 1094 1167 1242 1148 1106 1167 1168 1177 1209 1059 1120 1142 1149 1104 1121 1109 1250 1157 1117 1147 1129 1126 1164 1120 1063 1178 1164 1135 1134 1153 1163 1166 1135 1213 1260 1179 1151 1129 1179 1073 1210 1134 1125 1135 1140 1180 1171 1087 1139 1124 1232 1134 1204 1124 1108 1146 1084 1153 1146 1190 1136 1115 1144 1100 1117 1186 1131 1104 1161 1166 1102 1129 1088 1123 1134 1211 1118 1145 1133 1142 1093 1133 1108 1095 1120 1142 1072 1082 1168 1147 1114 1201 1109 1093 1117 1145 1109 1105 1112 1080 1132 1114 1125 1062 1116 1115 1053 1107 1146 1117 1063 1121 1114 1084 1181 1119 1067 1040 1121 1138 1140 1153 1151 1165 1262 1157 1197 1123 1178 1179 1262 1126 1170 1132 1251 1202 1167 1105 1165 1102 1197 1191 1125 1135 1156 1208 1182 1124 1126 1125 1104 1111 1196 1133 1086 1116 1161 1187 1165 1188 1135 1150 1114 1074 1164 1093 1166 1156 1150 1112 1082 1133 1132 1051 1137 1070 1130 1066 1109 1105 1205 1146 1134 1070 1114 1055 1100 1117 1151 1065 1040 1131 1142 1102 1146 1100 1119 1129 1132 1087 1137 1115 1133 1086 1146 1134 1070 1114 1161 1126 1091 1061 1128 1078 1107 1117 1194 1105 1120 1142 1176 1105 1097 1067 1146 1168 1134 1109 1190 1065 1143 1144 1151 1120 1147 1157 1164 1157 1158 1184 1120 1152 1122 1107 1171 1122 1097 1065 1078 1093 1121 1094 1078 1080 1031 1123 1126 1048 1142 1135 1101 1129 1120 1080 1098 1103 1104 1151 1147 1005 1131 1086 1157 1050 1076 1064 1143 1135 1120 1039 1088 1035 1105 1026 1049 1064 956 1007 1078 1032 1074 1039 1084 1068 1020 994 1020 1069 1001 1106 1013 1045 1015 976 997 1024 983 1032 1054 1048 1062 1015 1008 1077 1021 1063 1051 1048 1065 1031 1031 976 994 987 1022 1006 1024 1013 1019 988 1048 1034 1058 1073 1018 981 957 961 1052 1016 997 1035 989 1074 1019 946 1021 1002 1010 984 967 1036 987 1059 1074 1013 960 1011 1004 1033 997 1016 1047 978 1032 1114 983 1019 1024 1011 1032 1017 1048 1030 1026 1027 982 1053 995 948 983 1026 1039 1036 1011 1050 1002 1027 1061 1066 1039 998 1017 1032 1018 1046 1007 1022 975 1019 1005 1055 1027 994 1016 1003 1026 1042 1023 1007 1063 990 993 1046 998 995 1052 1041 974 980 1023 1024 1009 1012 997 991 1008 1090 991 1073 1030 1048 990 1003 935 981 999 1020 1040 1053 1030 988 985 1032 1009 1026 1017 961 1040 1058 1097 1061 1049 989 1009 1098 1022 1008 1077 1001 1015 1013 1029 1011 1094 1024 1046 976 947 1106 1019 1006 1001 1023 982 1082 1055 992 1058 1086 992 959 981 1054 1008 1055 997 997 1006 1005 1038 1010 909 1067 1035 994 996 954 989 1026 1015 1064 1072 1002 969 1052 1075 949 1033 987 981 1009 1023 1024 1044 977 979 999 977 1008 970 1004 1001 1026 956 1024 1015 1022 1025 984 987 967 1012 1030 1036 948 1035 1041 1026 993 935 1035 976 1007 982 1026 1017 982 1030 1008 1008 1053 995 997 970 1064 1027 1032 1046 1024 1030 1020 1051 966 1080 971 1002 1039 992 1054 1007 1037 995 1074 974 1020 1074 1008 1063 963 1096 1026 1018 952 1030 1012 957 1017 982 1033 1049 1015 1010 1054 996 960 1046 1012 979 1067 1032 1034 1009 1045 1030 1012 964 980 1066 1054 968 1018 1030 1061 1041 1035 1048 1025 968 1077 1089 998 1056 1029 984 959 1003 1026 993 1052 975 1029 1031 962 1051 1038 1019 1011 1030 1032 974 1033 1012 913 1047 988 1009 991 1022 1020 1056 1069 989 1056 1039 1040 977 988 1001 1048 1047 996 1004 975 1051 1094 1004 1032 1015 1019 1045 1101 1039 1046 1018 1077 1024 1056 1058 990 1092 968 994 1027 1008 1020 1027 1039 1001 1034 1052 1029 988 1052 1015 980 1010 970 1050 1021 1035 1038 1069 1016 1056 990 976 1083 1053 1061 973 1048 987 1029 1035 1039 1024 1087 1108 1059 1030 1111 1037 1039 1059 1064 1083 1012 962 1058 1038 1013 1029 995 1105 1036 983 1047 1050 1053 1101 1095 1102 999 1067 1076 1074 1062 1021 1024 1046 1017 1069 1038 984 992 1091 1037 1007 1007 1030 1068 1015 1024 993 1015 1042 1052 1024 1035 982 1039 1064 1041 1033 1051 1058 1044 1059 976 1027 1083 1044 1035 1005 1011 1142 997 1039 997 984 1029 1069 1052 1053 978 1046 1152 1100 1031 1089 1041 1091 1098 1083 1024 1049 1076 1087 1098 1041 1052 1012 1041 1051 967 1024 1030 1066 1069 1033 1013 1081 985 1013 1091 1027 1050 995 1122 1054 1022 1056 1015 1101 1066 948 1070 1044 1055 1023 1042 1053 983 1044 1051 1066 1012 1008 1018 1048 1046 1063 1010 1025 997 1034 1044 1032 1063 1013 1056 1037 1092 1036 1064 965 1045 1067 990 1038 1018 1026 1048 1073 984 1017 1073 969 1019 1052 1045 1013 997 975 1039 1056 987 1009 1024 1059 1050 1124 1083 1091 1058 960 1079 970 1018 1010 1073 999 1033 984 1049 1049 1025 1007 1032 984 1115 1045 1062 1007 1012 994 1083 1082 1032 1050 965 1052 1056 1007 1009 1041 1018 995 985 1064 1036 1089 1034 1078 1063 1010 1064 1013 1060 1054 1026 1010 1055 984 1002 1022 1019 1022 1058 1024 1068 1009 1007 1036 988 1102 991 1012 1027 1035 963 1013 946 1041 1034 949 1054 1072 1050 988 1066 1011 1003 999 991 1039 1016 1068 991 1048 974 1048 1105 1074 981 1053 992 1011 956 1012 1016 1095 985 969 984 1009 1036 1056 1039 1007 996 1026 1092 1053 1025 1024 1060 1050 965 1016 1007 992 1024 1039 990 1016 1049 974 1070 1022 1042 1049 1067 985 1053 971 999 1001 1006 983 1036 995 1037 988 1074 1001 988 1008 1042 999 1066 1089 1063 1024 1018 987 968 1041 1041 1026 969 1042 1009 1079 1001 1034 1051 1021 1063 1062 1175 1029 1056 1074 1140 1037 1106 1074 1148 1068 1054 1111 1098 1080 1089 1096 1089 1118 1122 1157 1128 1050 1128 1105 1190 1130 1076 1114 1103 1116 1023 1128 1067 1117 1064 1136 1090 1138 1098 1134 1120 1083 1089 1060 1093 1103 1080 1119 1083 1039 1082 1068 1156 1089 1081 1092 1083 1109 1109 1138 1150 980 1073 1112 1050 1114 1091 1149 1052 1006 1081 1082 1024 1080 1098 1149 1096 1116 1039 1088 1089 1073 1078 1119 1074 1029 1023 1029 1087 1079 1069 1039 1088 1080 1053 1054 1041 1101 1058 1092 1079 1031 1001 1100 1093 1107 1162 1092 1160 985 1046 1092 1115 1066 1080 1088 1016 1048 1062 1138 1048 1066 1134 1192 1110 1120 1129 1144 1175 1118 1187 1166 1101 1056 1132 1185 1096 1082 1101 1110 1121 1081 1154 1100 1065 1112 1148 1123 1083 1090 1112 1135 1103 1092 1145 1098 1133 1126 1147 1154 1144 1137 1128 1092 1008 1065 1062 1084 1015 1032 1110 1088 1056 1106 1053 1088 1027 1066 1086 1077 1066 1090 1074 1092 1046 1122 1094 1063 1080 1036 1086 1075 1070 1016 1066 1105 1058 997 1103 1117 1049 1038 1084 1093 1094 1022 1111 1047 1033 1096 1116 1078 1056 1156 1117 1061 1035 1068 1115 1109 1053 1050 1079 1158 1089 1067 1125 1090 1077 1097 1079 1084 1080 1030 1143 1067 1058 1088 1112 1130 1026 1128 1100 1106 1077 1117 1102 1116 1030 1063 1097 1125 1070 1094 1065 1114 1041 1068 1097 1045 1132 1033 1146 1148 1130 1160 1090 1100 1015 1023 1166 1109 1042 1106 1098 1139 1065 1106 1072 1147 1088 1052 1101 1152 1074 1114 997 974 1051 1035 1023 1069 1038 1052 1064 1005 1080 1029 983 1089 1030 1053 1035 1056 1006 1039 1032 1055 1061 1066 1022 1029 1136 1047 1070 974 1023 1035 1037 995 1105 1024 1065 1038 1087 1081 1082 1074 1060 1010 1064 1074 1098 1006 1100 1061 998 1042 1047 1042 1117 1084 1060 1110 1055 1018 1051 1064 1065 1041 1054 1035 1029 1109 1079 1116 1065 1080 1104 1086 1116 1017 1129 1126 1151 1105 1093 1147 1074 1130 1137 1138 1140 1063 1132 1119 1092 1124 1063 1068 1089 1145 1008 1106 1148 1143 1126 1126 1102 1045 1087 1163 1091 1126 1065 1084 1048 1101 1092 1058 1054 1145 1148 1134 1137 1091 1149 1107 1134 1105 1052 1138 1106 1128 1153 1108 1143 1112 1120 1139 1178 1179 1195 1167 1158 1173 1143 1218 1211 1184 1070 1200 1163 1214 1239 1145 1151 1258 1172 1210 1179 1139 1200 1261 1214 1257 1264 1161 1220 1204 1206 1187 1232 1201 1218 1214 1270 1238 1305 1301 1172 1292 1236 1411 1288 1313 1314 1370 1349 1368 1390 1421 1422 1461 1478 1446 1613 1683 1718 1805 1868 1950 2049 2048 2342 2391 2464 2750 2738 2774 3120 3138 2982 3021 3337 3014 2894 3066 2915 2779 2578 2732 2493 2337 2192 2336 2292 2236 2257 2474 2308 2191 2268 2318 2125 2185 2265 2069 2092 2010 1900 1710 1644 1624 1534 1574 1569 1456 1476 1503 1476 1411 1356 1470 1329 1445 1342 1299 1355 1357 1313 1261 1365 1287 1281 1288 1305 1236 1230 1210 1210 1245 1197 1244 1160 1222 1248 1249 1196 1248 1209 1186 1178 1159 1191 1191 1133 1084 1136 1173 1165 1177 1144 1137 1110 1078 1125 1181 1114 1139 1058 1108 1081 1064 1066 1039 1105 1108 1045 1076 1086 1081 1101 1047 1081 1053 1024 1069 1060 1074 1124 1075 1088 1059 1049 1051 1006 1034 1098 1035 1094 1055 1047 1064 1106 1013 1005 1094 1025 1050 1067 1047 1072 1040 1029 1115 1048 1012 1115 1001 1018 1049 1038 1044 991 1047 1031 1047 968 1080 1052 1053 1078 1001 1018 1040 1005 1061 1041 1069 1084 990 1103 1013 1081 1078 1065 1024 1016 1066 1075 1048 1051 1016 1041 1087 991 1025 1054 1032 1032 1078 996 1073 1022 1038 1066 1009 1078 1146 1104 1055 996 1018 1049 1045 1019 1015 1073 1022 990 1039 1135 1086 1030 1074 1063 1073 1040 1061 1052 1065 1045 1104 1076 1017 1087 1034 1091 1160 1137 1084 1070 1134 1060 1069 1093 1119 1107 1136 1061 1047 1120 1080 1081 1070 1111 1116 1122 1165 1148 1097 1087 1106 1174 1161 1075 1136 1165 1052 1147 1154 1185 1143 1140 1165 1103 1091 1148 1137 1103 1139 1111 1216 1097 1195 1138 1167 1145 1149 1103 1154 1134 1154 1134 1131 1133 1114 1104 1179 1136 1148 1111 1079 1182 1114 1146 1159 1204 1117 1200 1163 1136 1124 1163 1150 1193 1214 1081 1177 1186 1181 1159 1201 1188 1188 1120 1148 1150 1264 1187 1245 1259 1185 1196 1163 1177 1186 1130 1125 1201 1283 1181 1234 1142 1196 1201 1215 1203 1243 1136 1216 1221 1227 1148 1199 1176 1231 1221 1161 1219 1259 1168 1200 1182 1264 1230 1248 1227 1227 1225 1222 1180 1258 1279 1251 1191 1235 1220 1248 1171 1270 1114 1180 1250 1295 1185 1181 1294 1222 1239 1175 1279 1261 1179 1158 1167 1194 1304 1190 1164 1244 1279 1187 1149 1194 1236 1224 1176 1213 1276 1187 1203 1288 1301 1266 1143 1189 1269 1185 1162 1275 1192 1217 1189 1235 1187 1107 1140 1176 1182 1171 1140 1289 1182 1215 1154 1195 1196 1149 1178 1223 1259 1163 1203 1165 1228 1152 1174 1277 1230 1214 1124 1231 1271 1151 1149 1246 1171 1168 1140 1217 1206 1209 1230 1323 1205 1167 1172 1234 1196 1171 1089 1236 1171 1229 1161 1265 1171 1158 1248 1246 1197 1225 1177 1188 1146 1211 1191 1220 1232 1229 1176 1162 1120 1202 1229 1185 1187 1173 1173 1243 1176 1185 1211 1293 1229 1223 1185 1182 1186 1213 1140 1184 1184 1188 1163 1281 1186 1162 1237 1265 1217 1204 1235 1323 1154 1166 1260 1293 1236 1187 1266 1312 1243 1228 1317 1257 1249 1251 1266 1255 1218 1228 1288 1283 1274 1177 1252 1309 1266 1223 1302 1277 1211 1229 1279 1332 1315 1242 1288 1247 1272 1253 1215 1280 1157 1194 1251 1279 1290 1194 1260 1213 1227 1270 1244 1294 1204 1223 1271 1266 1228 1223 1248 1300 1293 1218 1231 1252 1225 1185 1261 1285 1234 1156 1269 1356 1283 1192 1361 1362 1219 1255 1211 1302 1210 1284 1247 1279 1256 1204 1288 1260 1190 1219 1252 1304 1269 1230 1258 1297 1241 1147 1318 1288 1209 1158 1227 1250 1272 1259 1302 1237 1216 1267 1184 1319 1259 1204 1196 1262 1249 1245 1266 1250 1262 1213 1187 1302 1238 1207 1219 1294 1251 1130 1222 1273 1235 1305 1246 1231 1261 1215 1203 1294 1213 1185 1156 1274 1250 1224 1218 1250 1193 1206 1168 1222 1216 1209 1244 1190 1259 1161 1184 1163 1182 1203 1160 1185 1228 1149 1151 1188 1222 1220 1168 1157 1130 1157 1153 1124 1153 1144 1095 1124 1174 1100 1136 1149 1157 1164 1106 1133 1181 1185 1138 1102 1153 1176 1097 1067 1111 1147 1137 1130 1133 1172 1115 1216 1143 1147 1133 1166 1187 1081 1178 1120 1139 1163 1130 1147 1208 1176 1123 1130 1197 1120 1182 1154 1165 1192 1156 1121 1133 1158 1157 1188 1166 1165 1168 1128 1213 1148 1120 1148 1179 1131 1096 1133 1173 1151 1135 1158 1067 1116 1124 1148 1150 1194 1128 1172 1160 1156 1182 1117 1109 1159 1176 1180 1098 1166 1161 1118 1076 1119 1087 1150 1122 1131 1190 1119 1084 1091 1109 1104 1139 1101 1151 1097 1103 1091 1150 1140 1130 1079 1104 1066 1092 1069 1131 1102 1102 1051 1098 1189 1032 1084 1100 1162 1095 1200 1159 1105 1070 1078 1159 1108 1060 1103 1070 1118 1098 1084 1159 1106 1108 1165 1128 1088 1112 1138 1153 1121 1171 1091 1098 1077 1089 1114 1147 1180 1073 1152 1150 1096 1123 1090 1193 1106 1117 1147 1087 1162 1056 1166 1111 1078 1149 1110 1110 1133 1093 1112 1132 1118 1118 1088 1160 1152 1160 1078 1136 1120 1076 1125 1182 1164 1069 1117 1223 1149 1079 1157 1153 1076 1135 1082 1232 1258 1133 1121 1184 1130 1119 1135 1120 1181 1073 1110 1196 1122 1083 1174 1064 1156 1125 1161 1120 1135 1108 1176 1101 1161 1126 1117 1149 1179 1093 1157 1148 1213 1136 1115 1110 1201 1055 1150 1190 1171 1129 1104 1147 1146 1045 1133 1151 1133 1133 1053 1103 1145 1089 1072 1097 1101 1105 1123 1171 1172 1050 1135 1088 1090 1091 1106 1104 1136 1151 1106 1136 1206 1072 1032 1105 1110 1162 1101 1150 1121 1106 1080 1110 1093 1092 1080 1088 1174 1084 1094 1087 1051 1047 1159 1129 1132 996 1052 1042 1110 1068 1114 1117 1078 1079 1041 1143 1128 1025 1086 1087 1101 1089 1112 1073 1092 1130 1046 1116 1065 1060 1024 1098 1073 1049 1018 1083 1064 1090 1094 1124 1076 1083 982 1035 1076 1027 1090 1059 1018 1056 1044 1066 1004 1069 1033 1061 1049 1046 1052 1087 1017 988 1004 1061 1038 993 1067 994 1103 990 1073 982 998 1008 1047 1037 1012 1051 1072 943 1055 1015 1002 978 1016 967 999 1002 1070 1049 978 1041 1030 1021 1032 996 1004 1049 1051 1009 1075 1023 1044 1030 1084 1045 1024 1044 1011 988 1066 989 1004 1004 1078 1090 1025 1016 991 1032 1023 1036 973 1027 990 1001 1009 1051 1048 968 1045 1018 1082 988 1037 1026 1017 1015 1010 995 1011 963 1073 1018 1063 1045 1105 1027 1031 1063 1122 1052 1070 1027 1038 935 984 1017 1032 1010 1003 983 1010 1035 1058 1050 1034 1097 1061 978 982 1007 1019 1037 1086 1001 999 1053 1018 1021 998 1024 990 988 1077 1018 1002 995 1011 999 1006 1022 1008 1042 1010 1047 1024 1017 1064 985 1068 1069 1054 1026 1016 1012 1037 1065 969 975 989 1081 1036 1055 1032 1035 1032 1088 1069 1055 1104 1066 1024 1048 1067 1011 1083 1045 1034 1024 1040 1015 950 1041 1004 996 1086 1063 1102 1054 1016 1025 993 1046 995 1019 1094 1002 1024 946 1016 1024 1042 1039 1032 1033 1059 991 1073 1055 1006 1075 1026 1047 987 1050 1021 1039 968 1046 1072 1017 1010 1034 1038 1029 1035 1037 1029 1018 1055 987 1038 1037 1070 1051 1009 1091 1033 1070 975 1010 1024 987 997 1078 978 976 1022 1046 1061 1059 1128 1045 975 1063 984 1047 1029 1076 992 1025 1102 1041 1068 1042 1107 1034 1048 1072 1055 1062 1079 1063 1041 1074 1062 1083 976 1048 1047 1076 1035 1040 1017 1042 1063 1052 1066 991 1068 1056 1004 1003 1027 1082 1003 967 1026 1136 1080 1042 1081 1058 1087 1029 1042 1064 1049 1017 1164 1040 999 998 1038 1026 1132 1134 995 1060 990 1055 1064 1056 1033 1007 1083 1042 1066 1032 1094 1062 1045 955 1126 1064 1005 1025 1036 1087 1013 1032 1024 1081 1082 1122 1067 1010 1045 1095 1072 1044 1035 1064 1108 1039 1054 1044 1115 1005 1103 1024 1070 998 1036 1150 1061 993 1082 1022 1125 1065 1070 1060 1023 1049 1060 1009 1029 1089 1107 1070 1075 1054 976 1061 1046 1020 1097 1037 1115 1126 1105 1041 1060 1063 1052 1026 1073 1033 1108 1035 1059 1037 1139 1069 999 1039 1065 1018 1015 1045 1053 1089 1061 1056 1044 1104 1063 1114 1038 1070 1018 1066 1027 1073 1128 1082 1044 1100 1095 1050 1050 1096 1033 1092 1082 1031 1076 1128 975 1058 1011 1067 1086 1056 1066 1090 1075 1101 1095 1049 1042 1095 1073 1084 1065 988 1050 1094 1012 1066 1063 1075 1075 1111 1049 1068 1070 1074 1074 1117 1109 1006 1133 1128 1079 1146 1140 1049 1108 1069 1086 1105 1115 1123 1026 1056 1092 1066 1065 1044 1125 1087 1098 1101 1116 1083 1074 1040 1110 1066 1068 1046 1139 1051 1133 1094 1040 1056 1114 1059 1051 1063 1102 1065 1056 1124 1080 1034 1065 1094 1091 1045 1170 1158 1073 1077 1153 1082 1031 1128 1052 1072 1008 1106 1102 1090 1116 1088 1122 1064 1129 1097 1080 1073 1159 1094 1107 1137 1152 1093 1107 1166 1130 1062 1114 1101 1112 1111 1074 1116 1066 1109 1161 1112 1120 1122 1154 1058 1117 1174 1150 1140 1133 1185 1112 1186 1131 1142 1123 1115 1199 1217 1170 1146 1167 1145 1209 1160 1168 1146 1129 1171 1170 1089 1161 1189 1146 1197 1144 1161 1179 1181 1208 1199 1159 1149 1201 1172 1255 1211 1201 1204 1242 1234 1233 1224 1218 1188 1256 1206 1219 1261 1225 1196 1204 1192 1236 1244 1229 1312 1193 1265 1245 1292 1235 1272 1229 1256 1223 1287 1247 1259 1300 1315 1321 1338 1305 1280 1341 1258 1314 1287 1293 1358 1300 1360 1347 1401 1319 1358 1304 1292 1312 1358 1406 1447 1383 1435 1492 1403 1454 1464 1546 1462 1573 1593 1589 1631 1650 1779 1739 1729 1797 1952 1847 1862 2012 2171 2055 2182 2381 2393 2320 2563 2765 2754 2830 3145 3080 2850 2887 3296 3088 2882 2939 2957 2669 2656 2932 2714 2515 2449 2506 2286 2155 2206 2280 2039 2063 2240 2159 2058 2097 2300 2163 2188 2252 2436 2207 2175 2282 2271 2104 2232 2144 2011 1919 2053 1997 1806 1859 1898 1813 1627 1534 1681 1525 1431 1577 1545 1457 1436 1418 1480 1418 1425 1392 1368 1400 1443 1362 1399 1392 1467 1433 1447 1406 1354 1259 1314 1298 1289 1345 1343 1307 1345 1262 1332 1301 1311 1283 1294 1281 1274 1267 1260 1260 1220 1208 1276 1286 1257 1277 1190 1214 1237 1214 1262 1223 1308 1189 1196 1191 1192 1149 1177 1203 1180 1162 1196 1197 1121 1144 1231 1184 1129 1166 1144 1125 1157 1069 1251 1107 1144 1144 1131 1139 1134 1131 1103 1143 1186 1062 1104 1107 1147 1156 1091 1115 1132 1122 1056 1158 1088 1132 1069 1096 1042 1091 1088 1098 1058 1096 1042 1084 1072 1094 1050 1077 1084 1079 1116 1115 1111 1078 1090 1086 1156 1116 1110 1082 1137 1081 1073 1010 1090 1083 1166 1084 1100 1065 1117 1058 1056 1086 1075 1051 1026 1081 1061 1063 1051 1018 1077 1090 1125 1038 1109 1041 1039 1122 1069 1048 1068 1018 1075 998 1050 1063 1029 1050 1076 1031 1034 1048 1027 1024 1035 1091 1087 1020 1073 1049 1090 1048 1018 1048 1056 1010 1077 1026 1087 1053 1077 980 1090 1090 1051 1010 1087 1115 1077 1065 1100 1080 1050 1021 1034 929 1016 1052 948 1013 1036 1067 1037 1079 1050 1034 1035 1018 1002 1073 997 987 1036 1009 1087 1052 1048 1034 1052 1032 1011 1048 1050 1089 1017 1013 1110 1040 1023 1037 1048 1008 1119 1053 1021 1038 1122 1049 1003 995 1078 1076 1012 995 1048 1083 1050 999 1021 1004 1046 1090 989 1042 1049 1040 1015 1048 1029 1059 1064 1031 1063 1079 1073 1020 1036 1026 1006 1040 1058 1064 1025 1062 1054 1041 1124 1044 1035 1018 1034 1001 1104 1038 1073 969 1060 1055 1018 1070 1079 1004 1037 1060 1074 1080 1027 1013 991 1036 1029 1037 1044 1069 1042 1065 1068 1091 939 1027 1037 1030 997 1048 1002 1072 1090 1029 1026 1038 1033 1027 1019 1024 1089 1106 1001 1079 973 1023 1088 1111 1037 1098 1030 1081 973 975 1065 1039 1024 1108 1051 1053 1016 1033 990 1035 1074 1037 1064 1089 1011 1044 1004 1060 1037 1037 1030 1019 1060 1129 1041 1158 1080 1031 1009 1019 1004 1086 1045 1032 1063 1041 1040 1044 1038 1122 1039 1056 1065 1060 1005 1075 1035 1076 1066 1042 1022 1025 1006 1030 1030 1070 1017 1033 1027 1068 1046 1029 1002 1020 1079 1050 1051 1047 1001 1050 1078 1031 1055 1039 1062 1036 1020 1077 1036 1033 1051 1003 1079 1021 1016 1032 1078 1055 1030 1021 1066 1027 1075 1023 1090 1046 1128 989 1019 1013 1093 1058 1077 1021 1086 1047 1011 1120 1023 1020 1004 1056 1013 1019 1044 1010 1035 1066 1086 1049 1050 1056 1041 1041 1102 1037 1026 1108 1087 1077 1052 992 1075 1021 1051 1036 1041 1093 1084 1143 1053 981 1093 1034 1062 1066 1070 993 1062 1066 1074 1036 1047 1115 1037 1029 1079 1116 1050 1063 1055 1032 1045 1042 1135 1017 1063 1102 995 1019 997 1089 1110 1009 1033 1072 1016 1103 1094 1055 1027 1061 1093 1044 1035 1040 1034 1060 1025 1004 1047 1044 1093 1108 1067 1093 1044 1068 1128 1100 1106 1066 1111 1066 1045 1108 1016 1110 1066 1075 1140 1100 1114 1158 1111 1098 1087 1087 1115 1135 1140 1080 1103 1157 1137 1042 1167 1139 1130 1153 1223 1168 1108 1128 1210 1161 1093 1227 1233 1078 1119 1214 1203 1228 1121 1098 1110 1110 1106 1134 1098 1054 1108 1105 1070 1066 1162 1097 1046 1140 1174 1100 1084 1163 1104 1142 1075 1154 1210 1119 1076 1132 1122 1105 1152 1106 1122 1077 1151 1027 1097 1070 1115 1069 1052 1168 1088 1101 1059 1062 1107 1056 1100 1082 1017 1106 1065 1012 1062 1097 1088 1078 1068 1161 1116 1081 1041 1012 1034 979 1046 1147 1056 1074 1037 1046 1041 1020 1088 1031 1050 1060 1042 1090 1047 1088 1050 1062 1054 1056 1049 1004 1052 1008 1044 1056 1031 1044 1073 1087 1037 1030 1013 1033 1040 1092 1066 954 1065 1111 1015 1073 1002 1058 1016 1034 1038 1046 1069 1003 1004 1053 1048 1096 1041 1019 1042 1036 1008 1030 1048 1031 984 1084 1097 1022 1032 1049 990 1041 1033 1039 1033 1004 1078 1021 1022 1075 1027 1038 1036 1023 1025 1091 1025 1016 956 1045 1033 1070 1039 979 1097 1067 1131 1066 1106 1001 1023 1032 1008 1039 1053 1033 1020 996 1051 1004 1024 1013 1023 1036 1008 989 1107 1038 1021 1030 1021 1011 1042 1088 1037 1003 1046 1037 1072 1060 985 969 1034 1053 1041 1022 1051 1044 1089 1009 1022 996 1072 1010 1037 1004 1077 987 1084 1020 1015 980 1048 1039 1082 1110 1016 980 1036 1092 1009 1037 1064 1019 1044 968 1017 1018 1064 984 1027 1073 1088 1007 1017 1041 1044 974 1058 1037 1022 995 1068 1004 1023 1087 1058 1033 1064 1060 1031 1109 1040 1025 1035 1029 1065 1060 975 1062 1022 1052 1016 1016 1042 1013 1005 1003 1032 1040 1081 1098 1053 1032 1067 985 1015 971 1029 1062 1055 1074 1023 997 1010 1006 1047 1081 1040 1039 1019 1063 1063 994 1067 1011 1025 1037 1013 1033 1061 967 965 1021 1018 982 1086 1031 1017 1010 1008 1002 1080 1051 1031 999 1050 1060 1050 1026 1053 1048 1024 1052 1017 974 1035 1003 1056 1048 1022 1055 1069 1074 1021 1018 1039 1054 1022 1064 1064 1022 1004 1053 1076 962 1035 1137 1041 1044 1060 1058 1075 1016 1068 1029 1021 1041 1025 1020 1051 1077 1075 1087 1048 1033 971 1025 1111 991 1009 1091 924 1038 1070 1011 1038 1050 977 1029 1053 1016 1012 1036 984 981 1018 994 1035 984 1047 1053 1091 1018 1041 1036 1059 1044 1067 1059 1053 1081 1040 997 1049 1063 1051 1064 1081 1078 1070 1033 1073 1012 1023 1034 1061 1070 1033 1068 1008 1058 1068 1011 1035 1055 1027 1024 1023 1089 996 1037 1005 960 1095 1006 996 1039 1022 1006 1051 988 1105 1048 988 1006 1036 1042 1038 1023 1031 1023 1105 1010 1025 1105 987 1073 985 1069 1074 997 1019 1042 1091 1021 1041 1042 1031 1031 1049 1032 984 1052 1054 1025 985 1059 1056 1046 1029 1044 1069 1049 991 1027 1037 1024 1062 1034 1061 1044 1010 1029 1001 1076 1042 1055 1032 973 1029 1063 1031 1012 1033 1010 1029 1041 1019 964 1094 1035 1004 1069 1076 1050 1081 1004 1020 1106 1005 1024 1062 1044 1088 1029 1036 1031 1051 1044 1040 946 1045 1009 1079 1016 998 1034 1055 1016 1004 1029 1023 1016 990 1025 984 1075 1010 1058 1060 1006 1019 1002 1005 1037 1027 1005 994 1029 1045 1038 1010 1027 1003 994 1076 1070 1035 1058 1047 1142 985 1103 1017 1040 977 990 1025 1020 999 1084 1056 1060 1053 1074 1061 1081 1046 976 1076 995 1079 1060 1045 1114 981 1037 1035 1056 1089 1044 1074 1009 1024 1015 1039 1082 1016 1046 974 1050 1027 1038 1053 1067 1053 999 1037 1040 1039 1047 1122 1062 1009 1070 1023 1081 1024 1006 1026 1084 1016 995 1009 1060 1013 1046 990 1066 1040 1094 1002 1049 1048 1010 1026 1020 1066 1036 1048 1016 1037 1007 1102 1077 979 1041 1068 1025 1006 1041 1003 1066 1068 1073 1059 1036 999 983 1022 1070 1092 1048 1026 1019 1020 1046 1096 1053 1097 1081 1006 957 1042 1048 1056 995 1063 1055 993 1042 1039 984 1074 1012 1061 1054 1088 1054 1023 1027 1026 1070 1037 969 1025 1016 1166 1094 1006 1018 962 1047 1044 1018 996 1077 1007 1069 1044 1002 1001 954 1060 1115 1029 1051 1069 1116 1032 1051 1064 978 1103 1029 964 1073 1089 1019 967 1019 1037 997 960 1011 1001 1059 1027 1042 1081 1010 978 1015 937 1032 1008 1030 998 1001 1041 1048 1046 1036 989 1058 1035 1076 1115 990 1060 1041 1092 1040 1011 1050 1036 928 1037 1016 1077 1003 1020 1053 1046 1032 1022 1011 1039 1005 1054 1051 1089 968 1016 1004 1036 1068 1059 1050 999 1009 1038 1084 1017 990 1045 1025 1084 1066 1075 1082 1045 1020 1042 1048 999 1063 1015 1095 999 1092 1064 1026 1005 1070 996 1004 1054 999 1064 1065 993 1077 1023 1006 1007 1015 1091 1041 976 1018 1063 1075 1070 1081 1025 1053 1030 1050 1065 987 994 1054 1015 1123 1078 1040 1013 997 981 1026 1037 1034 1078 1112</intensities>
			</dataPoints>
		</scan>
	</xrdMeasurement>
</xrdMeasurements>