File: Data availability/00_STD_IN718_HT0X.xrdml
<?xml version="1.0" encoding="UTF-8"?>
<xrdMeasurements xmlns="http://www.xrdml.com/XRDMeasurement/1.6" xmlns:xsi="http://www.w3.org/2001/XMLSchema-instance" xsi:schemaLocation="http://www.xrdml.com/XRDMeasurement/1.6 http://www.xrdml.com/XRDMeasurement/1.6/XRDMeasurement.xsd" status="Completed">
	<comment>
		<entry>Configuration=reflection - transmission spinner, Owner=User-1, Creation date=10/26/2007 2:30:26 PM</entry>
		<entry>Goniometer=PW3050/60 (Theta/Theta); Minimum step size 2Theta:0.001; Minimum step size Omega:0.001</entry>
		<entry>Sample stage=Reflection-Transmission Spinner PW3064/60; Minimum step size Phi:0.1</entry>
		<entry>Diffractometer system=XPERT-PRO</entry>
		<entry>Measurement program=C:\PANalytical\Data Collector\Programs\00_STD_IN718.xrdmp, Identifier={28380439-0F33-476B-A426-78B1F912C0F4}</entry>
		<entry>Batch program=C:\PANalytical\Data Collector\Programs\00_patch_IN718.xrdmp, Identifier={C1934502-B9F7-4F6E-A8BC-61E6EA24040D}</entry>
	</comment>
	<sample type="To be analyzed">
		<id></id>
		<name></name>
		<preparedBy></preparedBy>
	</sample>
	<xrdMeasurement measurementType="Scan" status="Completed" sampleMode="Reflection">
		<comment>
			<entry>20-130 angle .004 step 30s </entry>
			<entry>PHD Lower Level = 5.34 (keV), PHD Upper Level = 11.09 (keV)</entry>
		</comment>
		<usedWavelength intended="K-Alpha 1">
			<kAlpha1 unit="Angstrom">1.7890100</kAlpha1>
			<kAlpha2 unit="Angstrom">1.7929000</kAlpha2>
			<kBeta unit="Angstrom">1.6208300</kBeta>
			<ratioKAlpha2KAlpha1>0.5000</ratioKAlpha2KAlpha1>
		</usedWavelength>
		<incidentBeamPath>
			<radius unit="mm">240.00</radius>
			<xRayTube id="1010042" name="Empyrean Co LFF (9430 033 7600x) DK417097">
				<tension unit="kV">40.0</tension>
				<current unit="mA">45.0</current>
				<anodeMaterial>Co</anodeMaterial>
				<focus type="Line">
					<length unit="mm">12.0</length>
					<width unit="mm">0.4</width>
					<takeOffAngle unit="deg">6.0</takeOffAngle>
				</focus>
			</xRayTube>
			<filter id="20010003" name="Beta-filter Iron">
				<material>Fe</material>
				<thickness unit="mm">0.016</thickness>
			</filter>
			<sollerSlit id="21010002" name="Soller slits 0.04 rad.">
				<opening unit="rad">0.0400</opening>
			</sollerSlit>
			<mask id="22080002" name="Fixed incident beam mask 10 mm">
				<width unit="mm">6.60</width>
			</mask>
			<antiScatterSlit id="22010003" name="Fixed slit 1°" xsi:type="fixedAntiScatterSlitType">
				<height unit="mm">1.52</height>
			</antiScatterSlit>
			<divergenceSlit id="22010004" name="Fixed slit 1/2°" xsi:type="fixedDivergenceSlitType">
				<distanceToSample unit="mm">140.00</distanceToSample>
				<height unit="mm">0.76</height>
			</divergenceSlit>
		</incidentBeamPath>
		<sampleMovement xsi:type="spinningSampleMovementType">
			<spinnerRevolutionTime unit="seconds">4.0</spinnerRevolutionTime>
		</sampleMovement>
		<diffractedBeamPath>
			<radius unit="mm">240.00</radius>
			<antiScatterSlit id="22090004" name="AS slit 5.5 mm (X'Celerator)" xsi:type="fixedAntiScatterSlitType">
				<height unit="mm">5.50</height>
			</antiScatterSlit>
			<sollerSlit id="21010002" name="Soller slits 0.04 rad.">
				<opening unit="rad">0.0400</opening>
			</sollerSlit>
			<detector id="7010013" name="X'Celerator detector" xsi:type="rtmsDetectorType">
				<phd>
					<lowerLevel unit="%">38.5</lowerLevel>
					<upperLevel unit="%">80.0</upperLevel>
				</phd>
				<mode>Scanning</mode>
				<activeLength unit="deg">2.022</activeLength>
			</detector>
		</diffractedBeamPath>
		<scan appendNumber="0" mode="Continuous" scanAxis="Gonio" status="Completed">
			<header>
				<startTimeStamp>2020-02-20T14:39:14-08:00</startTimeStamp>
				<endTimeStamp>2020-02-20T16:31:04-08:00</endTimeStamp>
				<author>
					<name>User</name>
				</author>
				<source>
					<applicationSoftware version="5.4">Data Collector</applicationSoftware>
					<instrumentControlSoftware version="2.2D 20160920">XPERT-PRO</instrumentControlSoftware>
					<instrumentID>0000000011030022</instrumentID>
				</source>
			</header>
			<dataPoints>
				<positions axis="2Theta" unit="deg">
					<startPosition>20.00008891</startPosition>
					<endPosition>129.99783913</endPosition>
				</positions>
				<positions axis="Omega" unit="deg">
					<startPosition>10.00004445</startPosition>
					<endPosition>64.99891957</endPosition>
				</positions>
				<positions axis="Phi" unit="deg">
					<commonPosition>39.2</commonPosition>
				</positions>
				<commonCountingTime unit="seconds">30.250</commonCountingTime>
				<intensities 1081 1168 1213 1181 1119 1153 1156 1111 1180 1194 1077 1112 1171 1201 1104 1157 1122 1168 1147 1157 1106 1122 1163 1189 1131 1194 1104 1204 1138 1191 1154 1136 1146 1161 1152 1182 1115 1137 1157 1214 1217 1118 1118 1121 1105 1195 1106 1178 1132 1138 1196 1116 1177 1143 1154 1115 1137 1152 1203 1162 1079 1102 1151 1196 1093 1163 1120 1131 1125 1166 1106 1171 1149 1173 1083 1120 1158 1158 1134 1149 1142 1195 1170 1192 1131 1114 1101 1111 1133 1118 1133 1195 1159 1133 1181 1207 1119 1128 1131 1154 1098 1151 1142 1101 1129 1152 1129 1137 1152 1086 1098 1115 1148 1126 1184 1104 1147 1107 1089 1102 1185 1089 1156 1156 1135 1125 1159 1163 1082 1110 1118 1209 1100 1135 1036 1132 1162 1134 1130 1134 1187 1160 1157 1185 1106 1055 1133 1167 1176 1084 1061 1115 1136 1063 1151 1094 1050 1106 1129 1159 1117 1089 1137 1134 1095 1186 1097 1081 1191 1131 1132 1095 1119 1120 1103 1147 1125 1168 1123 1055 1079 1051 1144 1148 1084 1125 1091 1107 1172 1134 1106 1083 1125 1126 1120 1109 1094 1046 1136 1150 1118 1146 1173 1089 1187 1047 1134 1120 1172 1094 1082 1167 1145 1137 1055 1179 1120 1140 1126 1121 1070 1115 1137 1062 1121 1148 1109 1115 1077 1139 1170 1078 1117 1165 1095 1110 1108 1124 1158 1104 1069 1076 1042 1077 1153 1084 1070 1013 1062 1075 1005 1115 1088 1074 1073 1108 1153 1069 1088 1163 1108 1118 1072 1039 1124 1094 1091 1091 1076 1023 1104 1083 1134 1115 1063 1066 1103 1090 1052 1072 1129 1072 1052 1049 1093 1096 1084 1037 1143 1065 1047 1081 1160 1082 1090 1078 1072 1066 1101 1153 1066 1088 1058 1073 1086 1119 1022 1121 1076 1097 1084 1175 1147 1136 1051 1066 1080 1070 1070 1115 1066 1096 1083 1077 1082 1066 1102 1094 1096 1096 1081 1129 1059 1076 1091 1144 1103 1065 1111 1083 1029 1068 1059 1079 1081 1102 1077 1060 1029 1087 1087 1063 1132 1104 1134 1027 1091 1094 1027 1075 1138 1087 1097 1070 1012 1079 1070 1089 1104 1037 1050 1073 1047 1089 1063 1102 1102 1077 1096 1008 1018 1091 1084 1107 1053 1060 1072 1058 1078 1122 1101 1102 1067 1100 1053 1048 1081 1061 1153 1094 1063 1137 1081 1063 1083 1050 1035 1047 1083 1130 1035 1059 1134 1082 989 1075 1084 1038 1050 1146 1078 1032 1042 1123 1058 1041 1062 1044 1070 1054 1016 1147 1097 1086 1056 1035 1110 1133 1094 1048 1070 1108 1044 1039 1063 1090 1114 1105 1066 1059 1130 1106 1109 1079 1037 1025 1074 1053 1052 1049 1078 1060 1075 1025 1041 1047 1088 1037 1062 1103 1101 1062 1069 1102 1064 1084 1051 1092 1109 989 1065 1055 1084 1153 995 1091 1094 1049 1015 1075 1079 1034 1086 1047 1046 1036 1089 1060 1017 1078 1093 1097 1017 1165 1081 1140 1061 1095 1088 1072 1076 1035 1008 1058 1077 1112 1053 1069 1072 1039 1018 1111 1098 1135 1079 1029 1052 1108 984 1039 1035 1076 970 1019 1073 1108 1069 1056 1076 1076 1067 1048 1059 1050 1081 1086 1101 1075 1084 1090 1073 1011 1049 993 1089 1053 1061 1006 1026 1033 1058 1060 1110 1126 1096 1029 1111 1055 1086 1081 1054 1065 1052 1032 1051 1046 1054 1023 1055 1097 1034 1020 1069 1015 1041 1101 1005 1092 1034 1058 995 1051 1052 1011 1154 1064 1017 978 1092 1023 1021 1077 984 1063 1033 1035 1008 1041 1050 1037 1069 1047 1031 1064 1039 1013 1007 1037 1011 1066 1032 1025 1045 983 1125 994 1055 1091 985 1003 1139 1067 1089 989 1083 1006 1088 1031 1070 1018 990 1011 1030 1038 1058 1041 1051 992 976 1023 1117 1058 1042 1027 1090 1059 1066 987 1084 1017 1034 1006 1038 1064 1011 1039 995 1034 1031 1042 1065 1030 976 1026 1050 1039 991 1045 1007 996 1006 1065 1037 1038 1027 1008 991 1090 1031 1054 988 1082 1010 1029 1124 1039 1115 993 1082 1032 1069 1017 1004 1031 1060 1018 1044 1058 1042 1048 1026 993 1027 1001 1023 1042 1020 1002 1017 1019 987 1040 1009 1038 1039 1111 1009 1077 973 1003 1037 1056 990 1001 997 1068 1035 1036 1055 984 1024 1015 974 1008 993 957 1056 1104 1051 1064 1001 1046 1040 1090 1061 1078 970 999 1036 1086 996 1017 1015 1021 996 1039 1034 1015 1012 994 1051 1078 991 983 1037 993 993 1038 1032 977 1033 1033 1005 1004 973 1004 1010 985 996 980 1019 1027 1067 978 1019 1031 1047 1031 1025 1021 1107 1034 1026 1079 997 1022 1051 980 1005 967 1038 1001 1029 968 1077 982 1051 980 1064 1086 1051 1034 1026 1051 1033 1033 1044 1011 1050 1029 1022 966 1010 998 970 988 1033 1029 1019 983 1034 982 979 1002 994 975 1008 1034 1008 1046 1001 997 1073 1040 1081 1019 1078 1035 1022 1027 1024 1034 1019 1019 1010 1031 1006 934 1073 1046 993 964 1003 975 1075 1082 1001 1005 1108 967 1053 1055 1061 1020 1026 997 994 1002 1024 1041 1024 1013 1025 997 1008 1009 1029 1007 967 1054 1027 1006 1017 1024 1032 1020 1025 1067 984 1026 1045 959 1054 971 1031 1044 1019 1019 1050 976 969 1020 983 995 1032 974 975 1013 997 965 1027 966 1078 978 1023 1027 1027 1025 975 1059 984 950 1041 1021 962 1015 990 1050 1005 998 968 996 1001 1041 996 1037 999 987 1026 932 1030 1004 1026 963 966 1042 978 1008 973 999 1030 951 1062 1003 980 1026 985 1034 1074 1006 1044 1024 996 992 1034 1056 981 1050 1038 1087 1010 1074 991 1017 1005 1072 1068 1016 966 1029 1083 961 994 1032 1093 1038 1002 1027 1078 1023 1045 993 1021 1103 1027 953 1004 1051 1006 995 948 1010 1019 957 1020 996 984 1008 996 992 975 1004 1016 1096 1059 1024 1024 1044 981 1026 1045 1059 1012 1012 1030 1046 984 1037 1032 955 1020 1010 969 1007 985 956 981 1005 980 993 989 1062 1078 985 961 1029 1031 1041 1004 1024 940 1042 1009 1041 992 1022 991 963 1033 1020 973 1048 1002 1061 1004 989 967 1027 927 1022 989 1009 976 1041 992 996 1047 1056 1066 985 953 1033 959 1003 1029 1005 1058 1016 977 1008 1004 975 1034 997 974 1033 996 1023 1018 1031 1004 1040 985 994 983 993 1032 1032 1040 1010 989 996 1007 1037 970 1088 987 956 981 990 1059 1042 1013 1004 1034 1019 1044 970 1078 978 1001 1031 1042 983 1022 1034 967 973 956 997 973 997 976 998 1027 1013 1006 1011 1009 1050 1027 1003 1027 985 997 1041 954 963 957 951 960 1046 1021 1007 973 1009 973 1039 1045 963 1019 1010 1046 1021 1007 1004 1010 957 975 957 1009 985 1015 951 1015 951 965 963 1003 1015 1036 1024 984 931 982 965 1050 1002 1072 977 918 992 1016 975 957 982 981 971 954 963 1020 950 1051 1006 1058 947 1033 1031 995 1032 948 1007 922 978 1018 982 965 1073 1018 997 1027 965 995 1006 995 998 970 1037 1008 985 994 979 948 921 979 1029 1015 1022 969 1032 937 984 1024 1020 1016 1023 979 946 1026 995 990 997 1017 937 967 990 1002 1005 954 1034 989 963 1026 973 1024 1032 1029 973 964 1027 1049 981 939 996 993 983 1005 1002 1026 971 953 984 984 990 953 996 1023 1040 987 992 1021 976 966 963 1016 979 1032 973 941 1019 943 1004 945 963 1006 1001 1049 987 991 1016 969 977 954 976 1007 1033 1019 971 1022 1005 996 1025 1001 990 1010 963 948 1010 981 982 990 1004 917 988 985 1008 1027 948 1034 983 989 991 1006 1037 1006 989 1008 1017 975 1027 934 991 1008 1020 976 985 1004 1012 962 1004 991 1015 980 936 951 1011 989 939 990 998 1010 1007 1016 1088 1004 977 1006 1010 974 976 977 994 985 975 1037 1016 1002 952 994 961 956 981 970 992 955 1047 1017 1010 1021 988 1042 952 1002 990 992 1011 1047 929 932 936 991 973 1042 1003 991 993 1007 1015 962 1007 992 941 964 977 987 1006 969 1006 951 975 1025 966 1029 991 927 942 998 1023 960 1001 1016 917 952 987 1034 992 979 992 1125 1021 970 1048 995 963 993 998 982 934 1037 1046 1045 1035 1021 1017 987 1034 1012 959 1024 1013 997 988 912 973 1001 1021 970 956 945 973 997 1004 1046 978 937 1036 1004 963 992 993 980 911 1009 993 1001 997 913 1026 1001 1017 989 1026 1006 933 966 1037 1027 981 918 1058 925 951 988 1013 911 983 978 994 1063 985 967 980 976 976 1030 995 960 970 1032 1007 984 997 1019 933 998 980 962 994 993 987 954 954 1003 1020 995 896 1047 1008 1011 940 961 971 968 975 945 922 942 996 965 964 969 988 918 936 957 1049 929 966 1027 1031 937 1018 951 971 974 995 1033 975 970 1006 981 983 995 926 979 970 940 1023 945 1054 1013 997 1025 973 942 975 956 941 974 959 959 977 933 996 990 962 955 932 955 968 967 969 988 1003 963 964 938 942 974 998 983 1025 993 991 903 1039 961 1020 904 1003 969 956 1013 1020 990 955 954 998 980 942 966 987 950 949 988 1008 1021 1048 885 926 979 1017 1020 954 961 978 970 985 905 941 1003 999 964 949 1013 989 926 953 984 1003 995 996 948 978 925 926 1018 985 942 999 989 961 950 961 977 1009 956 975 946 932 1009 1005 973 992 950 998 1039 1030 960 1001 985 977 927 1001 1032 993 1023 995 1007 966 987 956 1002 984 919 961 963 947 969 978 1022 971 937 975 977 912 893 1021 949 950 936 1001 943 951 1021 973 925 957 933 956 992 963 977 997 1001 935 924 934 938 936 1007 919 949 996 965 920 1020 926 963 975 975 1003 951 915 935 928 984 995 947 955 985 939 991 961 989 932 1008 981 947 948 947 929 940 1009 974 987 957 921 988 895 977 968 971 973 1011 929 973 961 938 963 942 936 971 973 961 957 914 951 980 947 979 901 960 993 967 978 951 934 934 1021 978 974 988 927 937 907 1032 954 969 970 964 966 939 956 897 1003 980 1005 979 892 983 922 968 942 1003 1029 932 962 989 991 1002 965 933 953 982 988 970 1006 947 963 990 976 952 954 1023 982 954 959 996 983 954 952 970 949 952 915 970 947 961 936 957 961 949 987 988 931 956 976 1003 963 912 991 1060 889 995 996 926 988 943 915 1007 999 980 955 991 975 979 948 989 926 957 1004 1015 956 1012 1037 1013 961 1035 993 1003 960 979 975 964 948 1013 976 911 975 992 909 966 997 964 967 993 974 940 970 979 1008 1001 950 990 921 995 979 948 990 908 959 965 995 980 965 953 883 931 921 946 965 882 945 970 943 989 906 941 929 955 999 1003 934 876 953 994 964 978 927 951 999 904 952 962 922 1029 1004 941 1047 931 976 893 981 962 925 954 970 976 985 956 947 962 919 1047 945 929 993 949 1038 861 949 962 927 1010 939 966 953 993 1006 969 964 1006 961 1005 939 917 950 1011 960 1005 959 942 948 959 1003 975 945 987 1012 1068 960 1023 979 1031 982 1045 980 995 999 982 962 940 933 998 942 983 994 996 952 912 960 1006 942 999 980 910 945 981 1045 949 985 932 955 909 991 967 948 957 941 928 1019 904 973 864 979 1016 1012 909 1016 880 941 976 953 982 949 947 918 905 858 991 962 934 963 1001 977 961 917 981 937 1005 988 1011 995 937 1021 949 1002 943 952 985 1052 921 923 1041 941 983 952 969 970 981 918 964 999 965 955 998 979 915 955 935 935 925 983 970 982 940 982 992 948 980 990 976 990 905 946 991 942 899 984 937 991 946 927 1005 997 974 903 977 927 908 957 901 997 1009 1010 979 1033 975 964 954 991 925 997 940 976 890 951 955 981 965 976 997 951 938 962 951 967 953 1044 983 990 910 935 1015 1018 914 976 980 914 912 940 987 988 1012 990 967 982 973 942 990 975 945 1053 1002 1023 1030 984 994 1002 1022 1029 1037 1002 971 1030 987 963 953 999 970 947 982 970 994 979 904 1001 1032 984 1009 983 987 960 1003 995 1004 946 942 994 984 980 988 994 1025 984 1029 1011 929 960 1045 1001 959 905 997 966 967 945 963 1006 921 957 998 943 959 975 966 951 946 962 970 985 954 980 936 964 953 993 1007 949 966 970 937 940 938 919 936 975 984 1009 931 987 922 912 1001 963 989 960 985 1007 956 915 965 981 974 938 975 932 955 957 965 978 962 940 933 980 980 982 923 997 996 993 989 975 965 985 1072 966 1008 983 969 990 1001 975 963 946 1055 970 1018 984 964 1027 992 1024 999 997 978 978 928 994 1001 1053 938 912 1030 1005 980 940 1016 1053 966 1001 955 1009 936 1060 1037 971 1044 961 987 1102 1010 1082 952 1031 1059 1036 1069 1074 1087 1054 1036 1083 1119 1209 1103 1151 1160 1197 1247 1255 1211 1319 1326 1274 1302 1431 1467 1577 1585 1651 1711 1737 1838 1838 1859 1954 2104 2193 2172 2256 2316 2507 2463 2535 2612 2794 2887 3110 3269 3513 3866 4193 4532 5019 5425 5624 6320 6581 6551 6672 6392 6003 5712 5377 5163 4837 4674 4375 4019 3897 3529 3132 2825 2458 2189 2019 1877 1682 1464 1430 1311 1290 1253 1227 1171 1173 1213 1147 1086 1110 1111 1110 1059 992 1035 1124 1003 994 1073 1023 1023 1036 1030 1020 988 963 946 1019 955 1023 985 1063 993 955 962 1021 999 999 1025 947 962 1030 1018 1049 1015 998 1027 1010 973 982 966 990 992 1015 1009 994 1007 1017 954 1005 949 990 1011 1016 994 913 1047 978 1004 922 1034 1001 928 1051 950 1012 1053 969 1005 1058 1077 1052 1083 1012 1061 981 1008 998 1003 999 999 1081 1013 981 1050 1070 993 1026 1053 1080 991 943 985 1007 1061 1046 1034 1029 1055 1013 1003 1018 1010 991 1052 1031 974 1036 1029 1027 1036 1045 988 1015 1002 974 942 938 964 993 1006 1010 942 1033 993 1013 960 1038 977 1016 951 998 1002 1020 919 1006 1012 1012 979 963 962 997 957 926 1007 974 1022 1015 998 1005 970 955 964 1077 922 992 956 992 1012 1021 957 1104 1001 1047 1013 965 997 969 1030 991 982 1072 1040 993 998 1001 910 1016 937 995 1001 991 948 949 976 989 962 928 953 1005 1004 936 952 1023 941 993 954 994 963 975 978 1002 952 909 971 960 913 933 917 984 952 962 923 912 975 947 949 964 974 956 974 964 945 913 941 940 911 1048 996 985 962 940 963 892 920 935 971 1031 921 955 910 961 984 946 888 938 964 1019 946 1031 926 984 968 950 1005 983 974 959 993 942 1015 947 970 956 988 909 987 933 980 992 970 935 940 973 939 981 983 898 1024 863 971 968 975 954 937 954 960 947 978 953 962 977 997 997 980 955 970 959 917 1001 964 969 937 993 1025 921 954 988 992 1026 989 941 956 988 974 967 917 953 978 1025 937 963 991 959 970 1021 988 965 1017 990 1018 1006 941 1004 907 965 935 855 978 940 965 994 971 985 943 980 951 910 967 975 975 955 975 949 976 1022 980 945 1004 957 940 927 1020 996 993 970 993 959 904 970 964 917 992 935 964 982 941 951 931 967 980 969 973 915 933 913 966 1042 901 919 909 949 991 943 991 928 990 917 1001 949 979 950 989 942 932 960 982 920 909 936 1009 928 957 974 977 899 967 956 993 935 983 946 955 1016 896 951 1056 971 1034 993 947 931 928 979 971 995 940 948 946 949 901 945 951 988 920 941 932 932 953 964 1025 922 942 999 1026 957 1001 905 984 1005 896 956 987 948 952 968 914 981 935 945 974 994 1003 1008 949 948 911 952 974 984 987 970 967 956 990 975 969 923 901 918 949 979 932 979 964 951 993 919 995 989 1020 928 983 973 918 1005 992 947 992 981 952 949 971 936 952 979 988 978 935 905 969 990 993 977 952 993 959 1002 988 959 1029 1015 894 931 985 962 976 953 948 942 985 971 1016 914 960 971 945 1001 974 945 1012 957 982 981 977 1037 983 966 964 960 1062 1010 991 1045 990 1022 984 1027 914 983 979 1025 1018 966 968 1078 1018 1003 991 1012 1083 1018 982 1047 1097 983 1038 1052 1018 1029 1046 1069 1083 1048 1024 1050 1073 1089 1156 1084 1175 1109 1170 1145 1088 1223 1143 1208 1208 1227 1242 1270 1334 1317 1309 1396 1345 1404 1471 1418 1501 1501 1614 1660 1581 1752 1759 1828 1859 1890 1966 2065 2140 2186 2310 2278 2476 2578 2664 2698 2871 3126 3306 3408 3681 3965 4163 4446 4601 4872 5055 5348 5614 5851 5934 6128 5983 5950 6058 5959 5883 5728 5721 5492 5203 5040 4819 4705 4407 4100 3927 3723 3417 3206 2991 2710 2608 2489 2281 2135 2017 1875 1755 1656 1569 1510 1473 1374 1407 1347 1315 1242 1225 1220 1200 1186 1100 1194 1125 1150 1070 1072 1056 983 1046 1049 1054 1051 1009 1016 985 1062 1031 1008 1039 1022 1035 1005 988 970 1029 1021 968 1015 964 1056 1016 985 1001 985 1002 947 981 918 990 949 990 968 985 1008 974 997 989 994 922 999 975 953 945 950 1038 976 938 964 981 936 961 971 922 939 973 924 993 950 997 943 950 928 980 924 995 947 928 938 914 953 965 951 938 933 1035 1029 961 1008 973 927 946 925 961 920 923 968 934 959 939 927 923 955 975 950 923 940 932 963 881 918 925 973 975 923 965 910 1016 940 979 962 973 976 967 965 989 957 992 981 1005 989 955 917 981 947 934 984 996 997 897 940 960 1025 1004 977 962 892 973 942 939 967 983 995 957 981 995 929 976 988 948 945 1035 952 984 965 942 951 891 948 957 950 878 942 1002 959 922 1016 1005 966 1021 1022 975 992 951 924 952 966 968 950 999 988 980 980 951 953 964 943 968 978 983 945 924 939 923 965 966 940 931 921 956 935 968 940 995 966 921 947 955 988 888 991 952 938 925 962 963 928 982 925 982 954 935 910 965 1012 934 1008 925 920 889 909 973 955 920 965 965 1009 877 949 929 936 971 975 955 1008 959 974 960 905 956 923 914 984 998 993 890 940 956 910 941 911 925 860 991 943 922 999 963 960 962 970 956 968 931 942 1008 948 899 876 923 965 920 1006 940 934 934 933 1022 921 931 950 932 928 996 909 946 908 935 907 955 937 975 917 965 927 951 954 960 909 936 933 918 910 964 872 913 918 921 959 982 932 945 926 951 919 898 927 971 890 937 936 950 938 960 928 935 980 909 943 900 965 900 920 1017 877 941 934 976 955 929 934 915 936 961 925 907 934 947 963 951 917 920 1015 886 928 947 896 975 889 910 914 909 990 976 1006 933 912 937 913 917 941 926 979 934 891 904 915 948 913 936 924 939 971 883 971 948 1002 934 870 891 980 964 943 970 941 957 962 940 982 905 933 926 984 947 936 884 927 971 911 952 931 917 928 920 928 1015 934 927 954 945 949 955 920 961 929 992 942 940 967 940 977 994 954 976 955 907 891 980 903 948 941 952 896 929 969 974 952 970 935 1001 910 942 967 973 913 975 935 922 962 877 949 967 964 940 994 973 1011 911 1002 947 960 975 1027 994 993 962 1029 978 978 1024 936 988 987 942 948 953 942 881 937 969 978 966 917 996 995 977 1010 998 1022 951 1036 981 926 936 961 1001 968 987 970 952 959 968 1008 951 961 891 963 1004 976 977 975 962 906 925 913 959 973 913 955 967 1030 890 1002 927 940 970 931 991 997 936 938 962 983 954 963 1003 948 921 988 966 938 961 955 988 980 917 985 961 995 885 956 1016 935 966 937 985 976 927 943 948 998 964 925 965 963 969 921 915 963 978 979 976 1010 920 1023 964 1046 927 1009 920 1010 905 940 967 1061 903 982 984 1006 993 969 945 1018 947 961 1009 928 931 993 922 939 949 998 927 937 911 901 910 870 892 970 961 927 941 914 923 936 920 891 936 973 917 940 932 921 909 929 971 954 982 925 935 942 918 978 927 927 936 923 911 963 973 910 936 971 929 970 908 907 975 928 973 936 954 910 976 949 933 910 954 908 935 936 938 909 882 922 967 960 938 957 937 900 955 951 910 981 923 978 938 901 940 934 917 976 965 910 906 924 975 921 939 949 928 921 967 922 971 920 979 950 931 897 943 984 883 917 917 969 921 904 1002 952 954 938 917 924 931 929 966 913 966 938 950 974 911 917 900 924 952 936 924 865 915 974 970 951 968 927 953 913 963 927 939 945 883 939 981 914 955 928 953 936 923 934 905 963 917 943 980 905 915 936 962 973 918 975 961 991 957 940 955 927 948 909 906 985 913 914 992 936 970 938 932 913 940 933 954 904 952 923 927 996 942 946 915 961 945 932 941 963 927 968 977 937 928 948 963 934 959 935 915 948 900 975 975 906 1026 1002 960 973 937 846 928 931 905 883 965 943 936 914 960 977 929 909 967 943 935 956 939 909 996 918 962 939 917 908 959 933 910 921 928 1001 893 871 946 924 905 912 966 980 976 923 946 1023 978 991 980 1013 917 866 966 968 952 950 985 932 906 950 926 954 975 941 979 906 956 937 897 974 942 922 971 969 1022 933 1034 945 985 923 946 977 955 988 945 939 983 861 926 982 940 949 975 936 957 926 883 948 943 878 949 956 988 910 879 917 893 975 895 1007 963 875 967 967 984 964 877 924 995 981 929 937 942 942 862 932 949 946 960 936 971 933 892 955 975 932 946 885 977 992 946 980 984 926 951 990 960 908 934 938 1001 945 907 965 950 991 969 937 962 979 947 938 935 982 898 938 963 901 967 924 948 928 936 941 909 900 882 981 953 975 984 945 959 832 971 874 910 871 985 923 935 927 955 934 939 919 925 933 967 911 889 929 953 939 876 934 945 923 921 957 994 962 921 945 914 967 898 896 987 983 945 917 914 923 898 980 975 883 991 976 956 962 978 973 925 943 966 942 953 960 973 977 988 965 931 954 945 936 936 977 894 896 934 943 994 952 942 918 898 915 931 923 971 936 963 909 947 947 913 924 926 942 937 917 912 980 960 927 905 962 988 951 885 938 959 935 925 920 942 934 866 905 940 840 927 963 970 908 932 911 976 920 900 903 928 908 938 951 905 941 912 973 898 875 906 918 912 971 969 1005 952 885 973 956 918 950 890 978 932 991 919 940 923 935 925 882 964 914 938 894 961 997 977 946 945 977 943 911 911 971 955 977 884 960 890 921 878 997 945 960 979 888 949 991 875 961 984 939 921 936 901 955 946 959 940 890 917 981 905 919 952 919 901 938 915 960 955 913 1004 938 907 950 937 935 899 896 995 905 929 934 937 925 928 936 950 966 939 946 951 938 886 858 870 959 954 931 920 938 945 959 960 990 874 903 913 943 966 987 956 957 909 938 988 962 953 890 938 938 863 941 971 883 912 864 920 947 922 881 959 959 926 912 942 962 955 899 969 947 920 893 870 922 931 940 912 989 885 954 918 947 962 955 939 948 896 947 946 945 923 910 908 963 933 965 932 942 987 909 923 946 966 896 957 970 932 866 996 960 937 917 951 911 899 892 905 914 912 922 950 951 926 890 952 921 953 949 885 901 914 984 937 940 901 867 945 973 915 893 939 950 894 906 874 919 963 914 904 933 878 914 895 938 914 888 892 946 936 962 918 942 914 914 921 955 906 939 932 909 933 927 903 913 989 966 947 909 942 945 963 896 934 908 911 945 891 925 973 994 929 891 905 920 924 934 875 890 885 920 888 920 1025 976 889 928 901 876 894 952 915 938 968 911 862 917 929 938 906 905 931 915 959 963 863 927 898 945 942 921 933 911 911 911 961 965 895 851 931 928 940 883 874 909 921 945 927 937 911 928 908 961 942 919 983 963 899 950 946 950 970 949 914 945 937 967 900 967 955 927 908 933 977 934 912 971 937 945 969 961 994 970 941 963 1015 935 937 969 911 900 912 946 897 950 934 928 922 914 918 884 926 915 904 947 901 947 908 928 947 960 947 927 903 994 883 973 993 874 1010 925 885 942 900 882 868 947 893 952 947 895 899 912 915 893 923 946 901 932 918 962 957 984 970 904 1004 962 954 933 940 934 928 954 914 927 923 907 912 964 941 914 929 912 956 923 998 924 974 964 936 911 896 946 908 909 914 907 949 920 1013 917 911 977 908 905 963 956 937 926 961 893 939 1024 911 915 992 863 896 945 925 924 884 931 925 969 911 959 932 954 923 891 934 962 931 919 928 910 900 938 922 952 898 892 920 903 893 926 926 892 920 898 1007 965 955 903 924 975 894 915 957 949 897 905 948 966 927 908 952 934 961 979 928 880 910 858 926 917 973 898 981 948 905 927 945 918 923 869 959 912 924 963 918 931 942 947 940 913 857 913 981 938 950 981 1005 912 985 922 970 904 1002 961 951 943 954 985 956 933 954 914 948 952 896 923 915 954 924 965 974 893 927 908 952 868 931 862 927 893 927 939 1015 900 966 854 957 921 874 925 956 932 892 924 951 899 950 912 895 915 914 926 953 945 832 907 996 918 932 980 971 915 922 947 975 884 891 945 938 963 940 904 992 956 954 946 948 924 901 922 977 921 871 904 957 921 913 865 956 933 938 928 898 912 889 904 977 942 901 951 950 947 915 918 993 892 934 934 914 875 924 915 979 915 893 960 963 945 949 968 906 956 998 905 962 896 950 931 910 935 936 936 949 929 969 895 943 872 951 929 963 928 895 878 923 906 926 948 918 922 977 1005 957 964 960 892 922 941 968 955 937 962 855 919 943 920 917 950 908 899 920 933 940 953 923 922 936 998 962 890 998 940 931 918 976 919 922 899 907 936 949 996 919 969 1001 990 934 964 939 976 876 955 969 909 996 941 917 959 932 932 924 970 886 980 950 879 928 964 975 889 946 919 929 933 923 943 919 963 952 938 919 914 989 956 974 919 911 994 969 864 872 905 985 945 864 893 922 917 959 967 976 919 900 942 971 922 977 1006 945 914 976 895 949 954 960 921 894 915 926 907 962 946 973 952 911 965 949 890 913 991 939 926 922 925 936 948 954 960 937 939 949 955 911 961 947 928 911 961 874 898 939 968 915 946 924 886 920 941 939 899 904 920 897 948 955 880 954 934 920 921 909 897 953 948 963 975 883 919 949 975 957 915 910 957 909 931 908 960 985 963 943 939 953 892 945 950 934 886 922 965 940 919 900 923 936 874 922 952 933 927 922 910 919 974 945 883 941 919 901 931 888 903 992 927 870 931 926 885 918 897 968 936 942 929 934 962 928 854 945 940 943 941 947 981 857 954 1012 906 915 947 898 932 938 934 922 921 900 927 908 969 975 982 939 886 982 925 940 897 949 960 915 970 923 938 935 989 993 939 962 891 888 969 990 999 938 946 934 940 946 901 927 1009 907 939 963 920 904 939 966 870 965 971 945 900 964 934 964 1020 917 936 940 920 918 989 957 1033 968 940 974 935 938 983 943 928 965 932 981 961 984 941 938 906 985 904 991 922 979 951 982 921 957 992 979 975 983 940 1004 963 1001 942 964 1033 956 982 1007 978 949 926 1021 938 953 974 978 927 1020 1066 934 949 928 978 976 1013 998 1021 994 1017 1008 1053 1011 1054 988 1006 1016 1070 1083 1084 1049 1111 1038 1041 1101 1001 1087 1093 1114 1128 1126 1074 1243 1162 1134 1128 1204 1172 1242 1140 1235 1236 1178 1153 1309 1191 1231 1247 1382 1223 1301 1258 1337 1371 1355 1346 1447 1446 1372 1396 1459 1493 1498 1438 1526 1468 1492 1567 1549 1570 1574 1539 1703 1795 1851 1812 1910 1957 2006 1996 2115 2150 2244 2369 2443 2470 2493 2594 2675 2653 2644 2700 2709 2662 2723 2622 2538 2571 2463 2413 2456 2312 2237 2220 2217 2222 2206 2127 2075 1990 1918 1903 1903 1834 1792 1717 1748 1590 1602 1537 1549 1413 1438 1358 1363 1294 1219 1206 1202 1227 1191 1162 1109 1069 1102 1056 1051 1032 1068 983 1025 1016 996 993 1049 1032 1021 940 1016 924 1022 1029 1006 1001 988 1024 1012 962 994 967 1022 963 973 937 1006 1052 940 973 995 991 995 951 1008 943 991 931 964 954 921 955 979 997 937 953 920 997 942 959 914 955 980 953 1006 962 933 926 949 931 955 899 903 1003 949 939 952 931 984 904 892 962 1024 886 976 934 936 918 908 945 975 886 977 976 927 945 917 990 901 907 891 949 937 935 956 959 926 965 901 969 935 915 903 892 996 901 950 961 949 933 881 924 903 872 969 917 937 969 884 908 942 962 915 946 964 888 966 925 959 924 940 905 969 893 910 956 918 866 924 911 957 868 936 942 980 970 920 908 922 885 900 952 907 886 949 899 965 937 951 952 952 879 900 919 899 974 903 938 918 929 909 866 943 959 869 941 903 927 935 965 918 924 975 901 963 956 896 918 964 976 939 911 952 915 875 931 1009 1003 918 940 963 926 909 875 871 907 906 935 931 925 888 918 920 949 934 904 929 948 926 904 978 946 948 948 864 952 895 954 926 952 934 978 919 971 914 945 957 974 950 987 909 966 912 992 989 920 953 953 997 939 967 936 920 976 891 925 961 938 928 936 939 937 917 962 962 969 941 920 824 962 897 956 905 978 897 943 926 945 949 878 927 961 863 922 943 1039 881 898 936 928 878 977 965 906 912 938 952 914 949 921 937 897 897 932 900 938 932 980 994 966 897 926 933 935 938 918 886 932 906 957 960 1006 871 906 966 940 922 936 990 938 894 925 900 952 906 948 947 918 919 893 877 937 959 963 904 956 964 877 921 983 895 987 897 908 933 900 945 917 933 953 909 922 955 939 911 900 936 945 942 915 886 920 998 938 870 905 931 971 954 897 894 920 876 933 907 983 975 897 876 976 880 934 907 966 936 880 895 936 939 918 934 942 949 932 932 905 919 975 921 906 914 922 917 955 896 884 969 921 919 946 906 925 918 911 923 960 921 868 905 925 908 931 932 974 935 903 938 992 933 976 924 897 931 914 909 893 912 932 937 878 896 842 983 947 929 927 979 925 905 946 955 950 914 934 955 913 941 922 949 954 898 872 967 847 942 999 974 905 992 922 995 937 980 891 893 948 984 966 1006 950 933 950 965 962 896 847 917 963 947 937 955 948 905 907 1027 934 985 923 996 977 981 900 952 912 910 870 937 899 954 905 923 941 811 911 941 874 939 932 931 878 960 955 900 938 952 901 917 912 926 917 961 926 907 934 942 948 970 919 998 929 956 961 1016 923 907 945 940 967 949 950 989 892 898 945 994 980 918 933 952 948 993 974 1035 971 971 957 921 919 913 949 1006 892 932 964 970 928 949 959 1041 1008 941 993 987 934 983 907 1021 881 894 919 1011 943 961 945 1033 888 948 939 946 934 987 900 982 943 966 891 892 960 951 961 911 908 940 938 945 966 934 861 1012 962 918 926 937 949 932 900 984 981 964 948 971 971 941 895 940 955 907 985 965 926 976 940 969 976 912 928 929 1004 957 948 923 953 970 964 946 988 927 935 886 955 993 927 979 936 957 928 919 923 985 940 943 945 912 906 952 950 985 992 924 978 926 956 975 952 984 841 935 978 920 948 987 948 910 928 914 995 951 960 945 996 942 934 982 961 985 909 932 1012 951 899 939 964 1010 911 922 952 983 996 943 914 952 971 926 959 926 927 921 942 912 966 947 933 957 891 906 943 940 945 945 968 968 904 940 921 957 950 921 1010 971 966 948 957 933 987 943 908 961 967 965 868 910 923 969 954 912 949 964 934 919 966 891 967 982 898 919 945 899 948 872 950 884 899 951 1012 928 919 903 951 968 913 933 924 901 931 909 938 945 923 913 978 943 941 901 962 981 955 872 952 1015 951 904 907 989 956 911 915 901 926 967 927 929 921 947 977 949 914 973 928 970 974 951 931 936 937 977 946 965 969 937 897 956 940 949 909 950 959 948 892 957 943 941 994 957 963 960 909 997 882 912 932 966 939 983 903 946 936 959 946 1036 1012 967 924 1023 940 967 977 932 1031 945 897 974 985 981 895 957 1072 962 903 966 985 954 979 1002 990 940 968 969 1036 971 937 997 941 950 961 956 991 976 924 956 951 953 931 989 975 939 909 941 966 1012 931 988 984 940 962 1094 984 950 988 982 1001 942 954 1010 979 963 935 936 926 942 939 1023 978 947 918 964 1008 991 957 1049 973 938 967 915 992 1015 999 955 934 1002 938 1026 999 1002 961 936 955 964 974 980 990 964 937 970 956 1022 1032 976 953 1008 913 977 963 964 937 976 955 973 982 1001 1003 1001 1047 994 1002 1086 882 1030 969 987 1034 1024 991 971 909 1007 995 998 1003 1030 976 993 955 985 990 974 1009 917 988 974 940 1007 1029 967 957 977 995 970 979 935 980 947 963 962 927 966 992 938 1049 976 948 953 898 1001 968 981 941 989 925 1025 894 965 925 989 945 942 968 943 951 928 979 951 890 969 954 969 969 996 1003 977 945 979 970 900 895 984 1017 983 936 935 980 936 896 935 921 939 991 980 956 942 938 979 976 907 933 940 950 975 877 933 909 904 933 935 928 962 851 973 967 974 953 979 923 951 984 987 997 929 954 963 950 917 956 954 977 941 905 970 927 858 927 920 947 908 950 939 896 909 968 925 961 908 1020 987 971 943 939 936 1001 952 998 1013 865 997 973 981 900 1011 937 966 964 983 896 996 917 900 951 970 943 973 934 996 918 997 898 997 979 971 924 920 965 953 943 991 911 1027 953 970 923 911 865 951 917 982 961 912 969 985 959 1047 941 926 942 947 929 931 925 998 940 961 988 1019 976 965 913 955 945 967 947 953 968 935 927 985 933 993 896 882 936 940 959 978 947 968 954 974 963 992 1023 960 926 990 945 979 974 1003 924 980 963 966 941 937 996 964 913 996 969 1010 974 962 917 1054 951 914 976 1021 897 938 892 969 977 997 935 969 965 929 966 964 962 894 915 969 947 925 943 983 947 942 983 1039 968 966 1013 1001 911 913 962 983 900 932 946 956 910 985 961 1032 935 964 962 973 932 1036 945 959 921 927 947 917 909 981 927 955 908 942 969 993 931 912 1019 941 897 947 1001 963 964 940 937 1019 929 945 933 1013 970 946 940 979 935 1022 942 899 886 946 987 1041 971 965 987 954 1040 939 1033 996 925 983 961 1064 966 971 940 1019 975 1008 994 995 956 900 940 1010 964 979 973 1003 975 945 927 1017 979 961 1016 993 989 912 971 993 970 991 995 1041 999 936 1035 1008 1048 937 932 1023 973 935 967 960 938 989 899 1005 975 978 993 1005 1012 953 968 980 966 975 938 994 1016 964 976 934 1017 1033 979 963 945 915 968 976 1018 966 975 1002 961 1013 945 948 1019 1013 953 1069 964 943 910 912 1049 1008 975 949 941 928 893 984 948 1004 953 975 1029 942 1011 919 955 963 953 964 962 988 996 1003 1006 976 918 1021 947 997 941 990 1023 983 937 1004 945 948 955 921 997 955 984 1053 954 995 932 976 992 988 978 994 975 1030 988 984 991 947 990 998 961 967 987 1038 1040 1018 981 953 1007 947 990 985 960 1073 1005 1041 954 1009 977 978 1004 1019 1032 1029 1022 1089 1012 962 999 1110 941 1093 1012 1087 994 1002 1022 1004 968 1072 1004 1013 970 1064 959 1062 1009 1007 1032 981 1029 1049 1056 1029 1022 1086 1017 1073 1030 1175 1061 1102 1044 1070 1038 1123 1006 1091 1143 1079 1067 1164 1059 1130 1087 1077 1131 1130 1047 1105 1131 1126 1106 1145 1151 1100 1105 1125 1178 1219 1115 1086 1194 1179 1172 1248 1217 1194 1131 1263 1174 1204 1194 1243 1124 1229 1196 1311 1263 1278 1238 1315 1185 1257 1264 1287 1246 1311 1294 1333 1236 1320 1277 1427 1329 1362 1386 1416 1430 1408 1358 1478 1480 1496 1361 1493 1521 1577 1500 1675 1604 1616 1657 1767 1615 1637 1676 1774 1836 1828 1828 2023 1863 1901 1912 2007 1955 1963 2017 2076 2048 2031 2037 2082 2141 2078 1996 2079 2028 2009 1970 2108 2084 1949 1891 1982 2068 1979 1840 1982 1843 1854 1862 1960 1835 1829 1778 1801 1698 1801 1611 1740 1762 1628 1582 1644 1600 1545 1544 1639 1586 1506 1416 1512 1468 1400 1405 1396 1410 1293 1320 1399 1261 1275 1217 1270 1264 1246 1201 1218 1162 1140 1145 1208 1107 1168 1111 1048 1153 999 1109 1059 1092 1061 1007 1094 1087 1022 1006 1048 1031 1013 1066 1078 1044 989 1026 1074 1052 1039 956 1092 1045 1039 1020 1063 1044 1063 1012 1055 990 1009 953 1123 1061 1022 970 1061 1055 963 951 1004 981 985 961 1034 946 981 961 970 1006 966 965 1005 987 968 965 1022 991 1041 1012 1006 979 965 928 1027 1016 1017 974 940 915 951 925 1055 961 1009 1033 901 989 990 1019 996 997 959 971 966 966 943 1054 966 989 937 948 988 1022 924 965 980 935 940 980 900 957 1006 926 978 980 935 1009 983 941 935 968 952 978 925 928 1030 928 949 956 961 897 942 956 959 963 940 937 983 951 967 978 978 1007 991 907 980 984 926 1080 883 942 928 962 992 976 935 1018 914 994 906 925 911 968 971 982 955 964 974 927 980 913 998 1003 929 990 900 940 954 946 962 925 923 999 948 1013 989 976 974 964 933 960 915 935 938 935 943 962 968 964 927 918 926 936 992 968 1029 974 929 949 1025 974 966 881 994 963 910 964 1001 929 955 989 946 974 876 983 1017 965 939 943 1005 974 961 1005 925 985 1012 975 962 926 962 956 943 996 1002 983 985 980 903 1020 994 876 953 920 994 953 1015 899 939 933 980 1004 996 950 962 1002 1027 970 913 927 957 985 919 962 965 1011 948 983 993 990 924 970 1005 959 976 940 1038 914 955 952 997 936 942 973 1010 988 923 943 963 964 955 969 974 947 951 983 974 992 946 980 987 971 981 1042 999 963 1005 975 997 1011 971 1065 952 976 953 1001 979 970 988 1011 988 995 1052 1049 1011 964 968 987 966 1059 942 1042 1001 1004 1019 1004 967 1021 1030 997 999 1040 1042 1115 1031 1003 999 1110 1096 1033 975 1020 1111 985 1064 1068 1026 1019 1061 1068 971 1055 1047 1034 1048 1054 1055 1066 1037 1026 1056 1097 1077 1017 1111 1070 1051 1094 1097 1117 1088 966 1098 1070 1034 1050 1164 1094 1058 1124 1227 1030 1080 1047 1188 1108 1122 1034 1160 1074 1088 1080 1166 1079 1060 1022 1177 1145 1036 1075 1184 1081 1032 1079 1124 1023 1063 1132 1076 1114 1097 1075 1138 1117 1035 1100 1236 1068 1105 1084 1246 1067 1018 1128 1164 1120 1119 1160 1196 1107 1105 1135 1238 1120 1068 1075 1256 1202 1089 1077 1196 1134 1064 1115 1161 1163 1072 1050 1255 1107 1119 1069 1156 1154 1146 1030 1150 1073 1122 1135 1214 1116 1103 1072 1166 1164 1147 1066 1202 1172 1146 1088 1201 1181 1144 1075 1132 1074 1179 1091 1178 1174 1150 1126 1281 1134 1132 1091 1173 1105 1171 1105 1164 1115 1187 1129 1180 1137 1121 1092 1229 1150 1110 1104 1243 1136 1114 1104 1161 1100 1199 1147 1223 1133 1210 1116 1153 1129 1149 1247 1285 1105 1177 1117 1222 1137 1182 1205 1279 1174 1168 1214 1250 1236 1159 1137 1250 1243 1188 1273 1273 1228 1206 1238 1272 1283 1269 1236 1252 1188 1165 1248 1237 1178 1201 1258 1234 1174 1163 1134 1199 1193 1231 1194 1187 1161 1228 1122 1178 1094 1185 1151 1231 1150 1150 1124 1175 1083 1161 1087 1129 1064 1199 1095 1094 1120 1176 1108 1135 985 1097 1117 1171 1068 1140 1061 1051 1061 1135 1041 1082 1048 1070 1016 1063 1038 1144 965 1044 1064 1034 1027 1050 998 1055 1044 1056 1006 1124 1009 1013 1096 1013 1053 1060 1037 1027 1003 1069 989 1055 1046 1017 1017 1040 1029 1011 1053 1002 1011 1008 953 1006 1006 1087 1072 1026 997 1051 956 1019 1060 1039 969 1009 993 1092 1007 1003 1004 1078 965 1046 1046 1059 967 997 927 1055 1019 1036 1003 1076 995 998 974 1062 1094 1025 1023 1044 997 1009 947 1047 1018 1055 1059 1032 1018 1026 1005 1020 964 1044 996 1019 953 1069 990 1116 985 994 971 1110 1049 1054 1039 1100 1006 1056 947 1059 999 1005 967 1031 995 1016 995 1090 1018 1035 1016 1035 973 1042 891 1020 985 990 990 973 993 988 992 997 929 1009 901 962 988 938 1036 974 904 979 909 998 956 947 974 976 973 931 956 981 955 940 897 968 904 940 922 974 990 963 945 920 947 922 914 1012 965 927 947 992 956 925 947 989 961 978 990 1021 913 942 983 957 989 992 1006 927 949 951 974 975 941 935 979 1030 960 1031 945 980 938 1039 1041 980 923 1041 1001 1059 973 994 999 1040 962 1039 1004 1032 1012 1056 981 1050 964 1065 967 1080 925 1054 977 1077 968 1058 1031 1089 971 1012 955 1080 975 1054 965 1059 965 1021 1019 1015 945 970 975 1003 980 999 1020 1005 1008 971 957 1038 951 1009 1019 996 1041 994 1030 1029 959 960 963 1034 1021 994 1044 985 991 987 1005 983 983 932 976 985 1046 1046 1048 971 1037 982 1063 940 975 1008 989 1034 996 970 1059 1018 991 982 992 1081 984 994 1021 1010 1007 991 1054 1068 969 1109 1032 1069 1003 1036 1031 1049 970 1025 1039 1042 977 1063 1061 1030 1086 1031 993 1038 1054 1035 1051 1074 999 1056 1008 1066 980 1052 1117 1081 998 1070 1030 1053 1019 1023 1050 1056 982 1042 1011 1066 1025 1061 1007 1070 1038 1009 1010 1095 1091 994 1029 996 984 961 1050 1059 989 928 990 1010 997 977 1052 1022 935 954 1093 979 956 998 1010 935 963 1015 1018 1031 945 967 1046 960 925 1067 1024 957 956 981 967 983 968 974 1030 967 952 965 908 1055 961 973 1008 997 991 973 1016 976 1016 973 1040 1027 1002 977 1008 1067 975 1066 973 1072 995 988 1032 1054 1054 959 1012 982 984 979 997 1044 940 994 1027 1068 980 950 970 1008 1033 940 993 989 939 946 948 1049 1006 977 1015 983 969 1009 1041 1013 989 935 946 977 1051 978 1017 955 925 982 955 976 948 979 1033 978 1022 984 1048 899 987 1021 1048 996 987 976 957 952 969 966 1009 1007 950 923 1011 937 974 968 982 1002 961 1005 980 1030 964 931 978 945 959 923 1035 968 984 968 987 946 906 989 964 924 898 947 982 982 998 987 978 966 966 866 957 991 1006 929 947 985 1009 1032 946 927 966 959 947 953 904 917 953 937 1010 1006 907 987 919 908 955 996 999 897 978 941 929 931 1024 1003 1015 1021 1049 1002 1005 987 990 1042 955 920 1033 978 949 959 961 977 913 968 957 987 1037 1039 1019 1036 1007 945 927 1016 1023 1038 1010 1013 989 961 964 994 1019 957 936 994 957 985 949 992 1064 996 1022 989 1021 975 999 1017 990 1015 964 1067 967 997 966 981 1015 960 1002 991 1019 971 970 1018 947 997 1009 975 963 987 989 1042 982 997 982 1002 1064 946 1022 1030 1001 964 992 1015 976 989 1035 1024 1031 1004 918 1051 999 946 955 1047 971 1009 998 1018 988 1033 1012 995 961 985 961 996 993 969 973 1035 1013 945 911 952 1023 943 968 1026 974 923 948 1012 1034 970 959 965 963 905 1040 1016 993 1051 980 989 1023 1004 1017 975 975 1006 1029 976 988 1027 951 998 1050 1006 1016 948 1020 1016 870 1040 933 973 997 971 991 1006 957 965 1041 981 1003 984 967 919 925 1056 945 950 997 1030 975 962 991 989 999 931 924 922 925 947 943 1011 949 937 968 973 903 971 965 971 960 960 949 959 914 919 950 941 937 925 921 951 936 966 931 963 949 914 949 959 981 910 1008 923 947 911 950 914 1004 1007 950 927 965 882 1001 907 897 891 976 894 919 937 918 959 883 948 924 951 949 955 956 953 997 914 950 943</intensities>
			</dataPoints>
		</scan>
	</xrdMeasurement>
</xrdMeasurements>