File: Data availability/00_STD_IN718_HT1X.xrdml
<?xml version="1.0" encoding="UTF-8"?>
<xrdMeasurements xmlns="http://www.xrdml.com/XRDMeasurement/1.6" xmlns:xsi="http://www.w3.org/2001/XMLSchema-instance" xsi:schemaLocation="http://www.xrdml.com/XRDMeasurement/1.6 http://www.xrdml.com/XRDMeasurement/1.6/XRDMeasurement.xsd" status="Completed">
	<comment>
		<entry>Configuration=reflection - transmission spinner, Owner=User-1, Creation date=10/26/2007 2:30:26 PM</entry>
		<entry>Goniometer=PW3050/60 (Theta/Theta); Minimum step size 2Theta:0.001; Minimum step size Omega:0.001</entry>
		<entry>Sample stage=Reflection-Transmission Spinner PW3064/60; Minimum step size Phi:0.1</entry>
		<entry>Diffractometer system=XPERT-PRO</entry>
		<entry>Measurement program=C:\PANalytical\Data Collector\Programs\00_STD_IN718.xrdmp, Identifier={28380439-0F33-476B-A426-78B1F912C0F4}</entry>
		<entry>Batch program=C:\PANalytical\Data Collector\Programs\00_patch_IN718.xrdmp, Identifier={F6DE2FCD-A5A5-4E67-9A26-000A1AE4801D}</entry>
	</comment>
	<sample type="To be analyzed">
		<id></id>
		<name></name>
		<preparedBy></preparedBy>
	</sample>
	<xrdMeasurement measurementType="Scan" status="Completed" sampleMode="Reflection">
		<comment>
			<entry>20-130 angle .004 step 30s </entry>
			<entry>PHD Lower Level = 5.34 (keV), PHD Upper Level = 11.09 (keV)</entry>
		</comment>
		<usedWavelength intended="K-Alpha 1">
			<kAlpha1 unit="Angstrom">1.7890100</kAlpha1>
			<kAlpha2 unit="Angstrom">1.7929000</kAlpha2>
			<kBeta unit="Angstrom">1.6208300</kBeta>
			<ratioKAlpha2KAlpha1>0.5000</ratioKAlpha2KAlpha1>
		</usedWavelength>
		<incidentBeamPath>
			<radius unit="mm">240.00</radius>
			<xRayTube id="1010042" name="Empyrean Co LFF (9430 033 7600x) DK417097">
				<tension unit="kV">40.0</tension>
				<current unit="mA">45.0</current>
				<anodeMaterial>Co</anodeMaterial>
				<focus type="Line">
					<length unit="mm">12.0</length>
					<width unit="mm">0.4</width>
					<takeOffAngle unit="deg">6.0</takeOffAngle>
				</focus>
			</xRayTube>
			<filter id="20010003" name="Beta-filter Iron">
				<material>Fe</material>
				<thickness unit="mm">0.016</thickness>
			</filter>
			<sollerSlit id="21010002" name="Soller slits 0.04 rad.">
				<opening unit="rad">0.0400</opening>
			</sollerSlit>
			<mask id="22080002" name="Fixed incident beam mask 10 mm">
				<width unit="mm">6.60</width>
			</mask>
			<antiScatterSlit id="22010003" name="Fixed slit 1°" xsi:type="fixedAntiScatterSlitType">
				<height unit="mm">1.52</height>
			</antiScatterSlit>
			<divergenceSlit id="22010004" name="Fixed slit 1/2°" xsi:type="fixedDivergenceSlitType">
				<distanceToSample unit="mm">140.00</distanceToSample>
				<height unit="mm">0.76</height>
			</divergenceSlit>
		</incidentBeamPath>
		<sampleMovement xsi:type="spinningSampleMovementType">
			<spinnerRevolutionTime unit="seconds">4.0</spinnerRevolutionTime>
		</sampleMovement>
		<diffractedBeamPath>
			<radius unit="mm">240.00</radius>
			<antiScatterSlit id="22090004" name="AS slit 5.5 mm (X'Celerator)" xsi:type="fixedAntiScatterSlitType">
				<height unit="mm">5.50</height>
			</antiScatterSlit>
			<sollerSlit id="21010002" name="Soller slits 0.04 rad.">
				<opening unit="rad">0.0400</opening>
			</sollerSlit>
			<detector id="7010013" name="X'Celerator detector" xsi:type="rtmsDetectorType">
				<phd>
					<lowerLevel unit="%">38.5</lowerLevel>
					<upperLevel unit="%">80.0</upperLevel>
				</phd>
				<mode>Scanning</mode>
				<activeLength unit="deg">2.022</activeLength>
			</detector>
		</diffractedBeamPath>
		<scan appendNumber="0" mode="Continuous" scanAxis="Gonio" status="Completed">
			<header>
				<startTimeStamp>2020-02-20T02:46:13-08:00</startTimeStamp>
				<endTimeStamp>2020-02-20T04:38:00-08:00</endTimeStamp>
				<author>
					<name>User</name>
				</author>
				<source>
					<applicationSoftware version="5.4">Data Collector</applicationSoftware>
					<instrumentControlSoftware version="2.2D 20160920">XPERT-PRO</instrumentControlSoftware>
					<instrumentID>0000000011030022</instrumentID>
				</source>
			</header>
			<dataPoints>
				<positions axis="2Theta" unit="deg">
					<startPosition>20.00008891</startPosition>
					<endPosition>129.99783913</endPosition>
				</positions>
				<positions axis="Omega" unit="deg">
					<startPosition>10.00004445</startPosition>
					<endPosition>64.99891957</endPosition>
				</positions>
				<positions axis="Phi" unit="deg">
					<commonPosition>205.6</commonPosition>
				</positions>
				<commonCountingTime unit="seconds">30.250</commonCountingTime>
				<intensities 1129 1114 1175 1125 1145 1171 1192 1195 1178 1153 1188 1161 1167 1151 1129 1181 1184 1162 1134 1164 1234 1149 1156 1139 1210 1242 1087 1107 1122 1132 1151 1176 1075 1170 1257 1160 1221 1199 1154 1219 1157 1138 1156 1214 1131 1180 1158 1092 1168 1109 1115 1133 1129 1109 1138 1139 1125 1149 1156 1220 1231 1133 1150 1194 1107 1182 1144 1110 1093 1181 1166 1119 1187 1133 1194 1152 1158 1160 1233 1140 1130 1185 1154 1095 1139 1162 1174 1205 1186 1151 1137 1159 1079 1173 1140 1150 1123 1131 1154 1156 1152 1112 1122 1151 1159 1114 1066 1124 1142 1092 1131 1119 1130 1126 1090 1136 1081 1160 1115 1207 1089 1159 1117 1179 1095 1109 1152 1154 1149 1149 1142 1103 1076 1144 1153 1123 1124 1130 1184 1174 1156 1123 1192 1117 1136 1112 1133 1145 1135 1179 1154 1104 1125 1154 1094 1117 1129 1156 1153 1103 1129 1104 1161 1214 1101 1157 1145 1115 1130 1117 1133 1174 1083 1176 1133 1145 1137 1105 1130 1130 1091 1123 1151 1160 1161 1128 1114 1135 1131 1154 1175 1108 1068 1096 1203 1090 1131 1210 1156 1105 1122 1106 1109 1162 1168 1142 1081 1101 1104 1074 1149 1145 1123 1150 1143 1107 1083 1165 1146 1096 1136 1131 1121 1066 1100 1143 1074 1108 1129 1119 1134 1116 1136 1209 1123 1168 1074 1160 1106 1159 1066 1110 1077 1105 1120 1143 1076 1136 1187 1054 1200 1117 1150 1048 1051 1077 1089 1093 1102 1117 1073 1080 1031 1063 1072 1087 1119 1084 1115 1062 1121 1084 1108 1032 1096 1087 1086 1112 1125 1030 1107 1135 1124 1093 1091 1112 1101 1086 1042 1068 1115 1041 1097 1102 1086 1084 1056 1114 1074 1119 1128 1136 1073 1067 1091 1104 1121 1061 1069 1092 1077 1086 1093 1136 1118 1079 1094 1087 1124 1097 1092 1098 1094 1050 1104 1044 1087 1114 1042 1027 1154 1010 1061 1166 1137 1034 1070 1079 1107 1105 1050 1056 1093 1084 1084 1086 1056 1123 1034 1134 1068 1081 1108 1082 1039 1061 1098 1055 1042 1078 1131 1112 1108 1076 1045 1063 1072 1110 1081 1100 1084 1102 1053 1058 1115 1011 1061 1016 1078 1022 1063 1096 1142 1158 995 1135 1042 1025 1011 1103 1055 1102 1048 1077 1052 1097 1093 1095 1019 990 1039 1075 1087 1088 1026 1125 1059 1049 1126 1062 1008 1061 1079 1102 1026 1017 1048 1039 1064 1095 1079 1052 1070 1034 983 1053 1050 1109 1088 1072 1053 1007 1079 968 1051 1089 1031 1052 1024 1107 1083 1034 1054 1080 987 1081 963 1042 1022 1023 1048 1107 1023 995 1054 1072 1073 1036 1049 1078 1079 1005 1069 1098 1041 1082 1063 1016 1102 1065 1042 1039 1061 1053 1006 998 1008 975 997 1010 1068 1062 1053 1038 1067 1065 975 1076 1009 1049 1023 1070 1109 1025 1083 1030 1073 1006 1038 1055 994 999 1068 1098 1101 1035 1065 1006 1029 1058 1009 1013 991 982 1098 1034 1007 1040 1135 1032 1072 1004 1030 1058 1059 1053 1064 1067 1049 994 1036 1050 1018 1031 1047 1052 1096 1055 1069 979 1019 1098 980 1021 1050 1053 1125 1029 1062 1082 1045 1048 994 1034 1082 996 1004 1012 1041 1033 1042 1123 1067 1040 1047 1047 1066 1081 1067 1070 1027 1037 1018 1044 1063 1056 982 1079 1056 984 1050 1021 1037 1032 1067 1021 998 1004 1073 1024 1042 1056 1036 1083 1003 1038 1103 1061 1056 1060 1046 1035 1075 1037 1029 976 1054 1006 1044 1063 1101 1033 1002 1045 1035 1046 1034 1015 1081 1015 1049 1042 1076 1050 1009 1016 1042 1021 1072 1029 1068 1006 1064 1022 1056 1022 1045 987 1062 1023 1048 1022 1040 1046 1056 1018 1081 980 987 999 1042 1007 1033 961 1003 1066 1051 1051 1029 1047 1066 1045 1042 1004 1018 1040 1062 1046 1051 1072 1031 1059 1006 1080 1019 1012 985 1051 1001 1065 1020 1068 1051 1020 1003 1026 999 1045 1035 1047 1055 959 1064 967 1009 989 973 1027 991 1024 945 999 1001 1032 1039 987 1041 1055 996 1016 979 1048 1013 1032 1032 984 962 1009 1069 951 1024 1050 1022 973 1010 1038 997 960 1084 1021 1053 1007 1008 1061 1001 991 968 1013 1019 1034 1021 984 1002 1009 981 1037 1042 978 998 1050 1052 956 1055 1050 1021 1015 1040 941 1006 1010 1006 1020 977 1067 1022 1032 1038 995 980 1018 977 980 985 1026 1003 1001 1040 974 1010 1002 1022 955 1018 1021 1030 1023 1032 966 1011 964 1052 973 979 1004 970 983 1009 923 1052 1006 1051 992 988 1035 1004 994 1015 1009 1025 1009 949 927 941 996 1064 1007 1002 1013 1042 1084 994 1062 1038 1023 987 1044 959 1004 1001 999 1008 1034 980 1007 1018 1062 996 991 1024 974 964 1042 953 1007 942 1023 1058 1064 965 981 1044 1034 1038 1001 1020 999 1024 1019 1015 1020 1047 988 1017 1015 1005 1001 1007 1040 978 966 983 1041 1029 1056 1135 1012 1087 982 1090 1024 1006 1040 1032 983 1024 1089 1007 1019 979 1037 1020 1026 1036 1033 1056 1060 1047 1024 1020 1068 1035 1030 1029 1048 1007 950 997 1020 1008 994 1038 1031 1016 1044 1040 1063 936 1037 998 1042 999 988 1013 1039 1026 1047 987 1005 1001 967 1054 971 1036 988 1095 1054 927 1041 1131 1037 954 967 1029 1045 1055 1045 1011 1066 1023 943 1002 1069 1013 1040 1037 1056 1063 1081 995 1100 1007 1026 1049 1101 1047 1069 1051 1046 1004 1011 1064 1042 1020 1021 1076 1008 1015 1038 1005 1045 1042 1013 1041 1045 991 964 989 1038 1032 1012 1046 1046 1024 979 985 1006 1037 1097 1052 1025 1013 1023 1073 1003 1013 1011 1030 1040 1096 992 1046 978 1048 1027 973 977 1036 993 1053 1003 1003 1023 1015 1003 1023 1055 1058 1006 1012 979 979 975 1058 1026 1045 1039 990 1007 1063 1062 1037 1035 1001 988 1055 1016 971 980 1027 1092 1044 1041 989 1027 1023 1052 1019 968 946 1009 1021 1001 1030 989 1033 975 1015 1036 1005 961 1068 1064 1021 1007 1068 994 981 1047 993 988 1041 995 1002 1031 1045 1025 982 1033 1009 1013 1005 1011 1018 1017 1012 1024 979 1038 1018 969 987 965 984 1104 1072 1061 980 1072 1076 987 1004 1017 1008 1007 983 1053 951 1026 1024 1003 1027 1061 961 953 997 1004 1022 1010 1019 1005 1015 954 976 1077 1039 977 1001 994 1019 1032 987 973 1031 1080 1030 1003 996 1020 1020 1029 952 1004 1064 1032 977 1034 989 1005 966 1054 1031 979 997 966 1007 1058 995 967 1021 1016 989 950 1032 1006 990 1010 990 1025 913 970 991 966 998 1025 1023 1002 1009 965 996 1060 985 1041 1039 1015 1039 1074 968 973 967 1029 999 1023 1015 970 977 1001 1046 982 1054 979 1005 938 1011 999 974 993 1023 949 1021 997 987 1016 1005 993 1008 1001 1006 977 924 935 977 969 913 976 1025 973 963 1040 1046 1011 991 974 992 1009 1051 1021 1026 982 1048 1003 990 1005 975 1052 1064 1002 1011 979 1009 995 1011 975 1040 1032 994 1048 1011 966 1005 1034 1021 987 992 1007 971 990 1032 1030 1013 970 931 1011 1002 1050 1029 984 997 1010 968 1011 967 1021 1006 1003 932 1049 1010 928 1034 1008 1049 999 1010 970 1011 1010 1033 1019 1023 981 1060 1027 981 926 989 1020 1027 1039 1026 1029 1047 975 997 1036 975 1005 1044 1032 976 1002 1064 932 1007 973 1069 945 973 1025 993 957 977 1051 968 985 946 1022 1060 945 981 1072 1006 1021 975 1035 982 1015 987 1053 1004 1016 1039 1030 975 976 960 983 1002 979 1005 1010 973 1035 1021 1037 1016 995 991 991 1030 953 1041 978 1032 954 957 1049 1040 956 965 973 1002 1018 992 1015 957 990 968 1045 1035 979 926 1036 1042 969 1016 993 1035 1032 967 995 1006 1017 1036 1066 1050 1021 979 1001 1046 950 988 1002 1010 957 1024 993 1027 987 1012 943 1048 917 992 1002 942 1007 1009 1010 997 997 995 965 1006 937 984 987 978 926 994 999 997 1034 1004 982 948 983 992 1016 1041 950 1003 1002 1019 977 938 1033 1004 992 968 959 980 976 985 1033 917 938 1004 948 1045 922 985 1033 1031 989 995 1009 950 969 1023 1056 937 1034 975 1012 1031 962 975 975 989 969 1008 914 1059 921 959 996 1031 1013 1026 1016 976 949 964 979 990 971 955 976 1006 1078 969 984 953 985 1058 960 942 999 982 949 911 1023 934 990 937 949 1038 924 946 953 1026 980 1033 978 1003 992 1030 1041 1002 968 1029 933 1025 1001 987 966 923 1008 959 963 980 947 1007 928 987 1040 1008 1012 942 982 1011 978 1011 962 1013 950 1008 999 993 977 1042 999 985 950 963 940 987 932 1016 1038 964 1046 992 942 964 969 982 935 976 897 955 911 993 994 967 971 1054 967 1012 970 967 942 978 921 977 999 951 943 957 1005 970 932 987 1015 1029 1002 1012 974 960 1018 1033 1007 995 1024 1017 1003 967 976 953 943 1004 943 998 957 1018 943 1003 948 1013 1027 966 1002 1055 905 935 1054 969 946 987 968 999 962 990 959 990 977 1012 950 1020 1019 937 959 942 924 981 952 1002 999 996 984 941 1029 987 1006 1031 948 979 934 1001 1015 938 982 1015 971 915 1015 1036 1011 953 933 1012 926 981 945 974 1005 971 983 957 1030 950 981 1056 979 966 970 1017 996 988 920 997 997 968 965 976 1011 937 1016 985 983 948 991 956 1004 953 938 977 941 949 1020 998 953 1003 975 1002 968 983 1001 978 920 906 1013 981 964 938 990 977 971 1024 1021 1008 954 935 968 949 1024 936 995 959 978 968 998 963 945 1010 992 992 956 1031 937 1042 959 931 987 991 970 957 1003 975 943 984 979 927 941 994 995 992 931 949 969 997 924 988 998 1011 1022 938 963 962 938 973 941 960 997 937 994 957 946 969 940 973 982 960 911 966 965 934 999 991 984 985 1016 941 1033 983 955 1016 995 977 993 1042 920 984 973 980 988 1011 967 938 951 966 1003 1012 1022 1010 1007 1018 996 1018 1018 898 1010 987 945 940 1001 973 927 982 917 927 971 1020 934 989 955 942 992 940 937 961 968 966 943 1030 963 991 1025 985 946 949 1006 1098 989 1026 1002 984 949 989 954 946 956 952 918 1046 1027 948 950 1006 922 957 913 1002 929 947 952 1017 942 899 926 976 919 1016 917 984 942 995 977 987 950 1002 969 969 1029 983 967 968 1016 956 936 977 952 964 924 977 917 975 993 971 948 926 934 961 977 1001 965 953 952 970 974 995 951 1009 913 964 967 995 992 976 955 905 953 1050 936 954 999 963 924 968 975 1029 952 941 942 1027 947 945 918 945 942 979 1015 1002 1002 953 920 975 969 985 992 1040 935 1013 984 980 942 976 1004 1012 1013 989 974 943 959 1002 969 961 950 996 963 922 939 948 963 926 936 949 929 1016 1042 967 991 999 1006 914 950 969 964 946 983 975 1012 985 921 988 983 1035 950 990 952 931 1010 991 970 960 1039 923 948 961 971 956 979 926 946 951 1017 976 983 969 970 974 1008 963 980 1033 1027 982 1026 982 1015 1038 1059 992 990 1006 971 1008 1004 983 1006 946 921 978 1011 922 973 955 993 981 1049 1007 989 974 969 1022 993 940 1034 942 985 971 984 953 967 941 977 960 994 1007 973 967 1022 973 1013 956 992 997 1010 1037 955 949 993 971 997 989 936 988 1017 1013 1047 1001 1009 935 976 1003 969 1023 1013 955 963 919 1009 1046 1007 960 1010 960 978 953 969 983 1010 940 974 998 969 966 994 1038 1032 961 999 959 963 982 940 1001 922 927 965 983 1022 989 936 984 1017 966 951 978 1002 1046 991 1040 955 1004 977 1037 1009 1015 1022 971 991 1044 1001 947 1012 1023 1051 1025 1007 1016 991 1058 1013 998 1049 1010 1011 1058 1038 1010 1040 1015 984 1020 1002 987 987 993 1027 937 992 1047 993 959 1006 1005 961 1005 979 979 939 967 997 1010 974 989 965 980 960 1003 954 1010 997 939 993 976 1049 978 949 991 978 912 909 1062 997 1022 954 989 941 982 966 1011 978 968 973 979 990 947 968 1035 1005 943 929 948 1032 1019 1013 1006 1006 1001 1009 964 921 980 1010 1024 941 1007 976 1007 1054 966 981 975 987 1018 975 1020 1013 942 976 974 1012 946 900 1039 989 980 1018 935 980 952 1013 906 995 983 962 975 975 1002 977 950 1007 1019 982 998 951 956 963 982 952 988 953 1022 997 1025 1009 984 992 996 925 1016 1034 926 1024 927 1003 980 969 965 1009 1010 933 984 968 922 874 1059 963 886 996 1003 960 974 1039 1002 997 949 1038 1009 1023 965 1076 970 999 993 998 1033 1081 1067 994 1020 1025 998 1073 964 1016 1044 1077 1004 1048 1091 1105 1021 1134 1026 1050 1061 1058 1109 1052 1056 1125 1134 1023 1051 1101 1020 1006 1117 1069 1102 1066 1062 1037 1083 1055 1081 1070 1023 1007 1050 1105 1146 1061 1060 1134 1109 1052 1157 1105 1039 1106 1077 1104 1029 1056 1107 1093 1039 1147 1072 1142 1148 1150 1111 1197 1192 1149 1173 1213 1237 1284 1233 1308 1253 1318 1319 1314 1319 1401 1473 1553 1639 1770 1878 2176 2465 2896 3281 3987 4841 5921 6822 7182 6564 5767 5026 4277 3997 3752 4048 4388 4348 4153 3707 3210 2709 2286 1985 1669 1666 1547 1420 1458 1370 1286 1371 1301 1232 1264 1286 1233 1207 1128 1160 1111 1202 1129 1180 1153 1119 1149 1129 1090 1100 1062 1076 1106 1050 1060 1082 1068 1082 1009 1069 989 1027 1016 1038 1017 1004 1063 1048 1006 1068 998 976 1044 1007 1015 995 1002 989 957 980 989 1048 1045 1062 952 1055 962 981 994 998 984 971 933 1027 939 993 1032 945 913 970 951 993 1008 1008 1009 931 957 987 981 962 954 934 971 1031 994 989 934 987 978 984 948 969 974 1033 967 995 1006 913 973 1006 945 923 1036 996 978 976 976 1033 990 952 981 953 960 973 956 1023 977 957 1005 1025 951 989 966 1017 1016 968 994 1007 975 1016 994 969 970 1002 1008 973 927 1019 975 1058 1019 988 1001 995 961 973 996 1034 974 968 951 1115 982 1018 979 1031 1058 1041 1074 1039 1089 1070 1047 1094 1087 1062 1073 1092 1102 1149 1154 1154 1131 1098 1173 1145 1118 1114 1142 1136 1133 1186 1153 1086 1157 1123 1106 1202 1081 1094 1117 1034 1082 1046 1103 1087 1087 1017 1097 1083 1132 1105 1088 1060 1058 1074 1119 1042 1091 1019 1034 1048 1061 1101 1119 1148 1026 1142 1158 1151 1175 1216 1211 1179 1227 1277 1184 1259 1303 1187 1233 1340 1216 1239 1197 1255 1305 1245 1161 1191 1139 1115 1191 1163 1124 1150 1208 1137 1118 1070 1022 1098 1083 1073 1081 976 1018 950 1044 1032 1005 1009 1032 983 941 971 976 955 973 991 989 976 982 1064 976 970 957 1012 928 941 985 953 952 966 980 1006 936 970 940 922 959 888 953 951 1013 895 1021 965 957 938 963 984 985 974 937 950 934 936 973 913 987 909 935 931 935 954 999 960 962 943 933 911 923 1013 974 954 936 936 924 974 985 990 953 1009 1010 943 913 982 959 1011 925 945 1003 908 929 955 979 949 928 929 954 935 946 945 981 892 966 895 1017 1001 975 955 1018 946 1024 957 984 961 924 990 966 945 1022 966 942 963 961 1030 919 973 967 952 950 960 931 959 915 964 940 867 979 939 924 1021 956 990 994 966 935 935 956 957 1007 960 888 968 966 1008 969 933 1011 981 995 989 999 1021 943 950 994 908 954 970 911 978 982 973 924 963 926 1015 981 1006 923 941 968 995 991 996 974 954 920 969 975 991 980 938 918 975 932 925 954 984 961 956 934 1031 935 914 996 1019 990 975 995 1020 953 910 943 1005 941 991 988 980 941 991 931 965 988 999 1025 1013 978 1012 1033 1002 999 980 977 977 924 946 945 1007 968 1003 982 952 1017 1027 925 970 946 920 954 956 977 1033 1012 978 965 979 1038 992 1042 979 998 1004 946 983 982 981 941 924 975 991 987 1034 1022 1015 974 1006 1003 988 988 991 969 1038 999 1019 968 1049 956 970 964 1045 980 995 926 1025 1049 1002 1017 1016 1047 1012 1046 1027 1064 998 993 1005 934 984 999 1015 1036 1003 1072 1072 1042 1020 1060 1021 1075 1063 1038 1133 968 1055 1060 1065 1088 1101 1033 1027 994 1041 1125 1007 1093 1124 1024 1080 1110 1122 1129 1151 1097 1160 1213 1115 1165 1157 1149 1124 1180 1140 1128 1135 1171 1201 1181 1217 1206 1175 1202 1190 1167 1248 1194 1266 1288 1250 1259 1292 1331 1253 1311 1289 1272 1274 1333 1249 1326 1326 1376 1421 1387 1360 1499 1458 1519 1503 1537 1574 1632 1694 1704 1778 1906 1958 2052 2209 2402 2592 2856 3076 3420 3841 4265 5005 5508 5942 6613 7347 7424 7539 7454 7131 6869 6293 6043 5645 5388 5122 5170 5121 4893 4603 4325 4005 3569 3172 2958 2538 2361 2065 1989 1829 1778 1692 1644 1571 1562 1478 1524 1439 1500 1361 1376 1363 1421 1292 1335 1362 1333 1319 1299 1317 1281 1204 1214 1227 1237 1190 1213 1267 1179 1164 1152 1182 1189 1196 1178 1164 1138 1182 1153 1133 1114 1059 1076 1111 1046 1091 1023 1093 1107 1061 1070 1021 1058 1042 1067 1035 1090 974 1075 1011 1064 996 1053 1031 1065 968 989 1039 978 968 1004 974 964 951 962 1029 980 946 1012 1033 970 981 995 949 1008 962 963 998 968 971 937 929 1027 918 974 1001 1017 981 978 1002 985 969 923 981 1039 948 980 978 931 979 943 961 1018 957 992 964 1012 892 978 920 921 979 936 965 956 931 962 976 945 929 984 966 971 962 1056 938 933 943 1018 971 937 964 962 926 940 1003 977 987 982 1015 963 947 989 915 936 870 938 943 879 948 1023 1003 925 915 959 895 985 950 917 938 945 933 954 936 987 956 932 977 975 975 889 960 939 929 964 992 925 949 957 950 936 956 937 948 974 1024 933 933 971 904 925 949 945 941 1006 946 975 910 939 993 935 933 973 938 907 931 983 940 929 920 946 961 945 953 918 941 981 963 940 964 1010 960 923 947 935 947 1031 1005 955 925 968 941 904 977 935 983 920 893 988 942 935 907 961 995 927 980 889 957 945 949 975 915 924 991 978 925 943 937 983 921 942 928 910 980 908 973 923 970 904 947 970 943 941 914 882 1023 917 923 968 918 925 909 909 961 940 915 1020 929 939 907 931 946 954 954 957 950 907 934 906 984 943 936 943 991 982 940 920 962 945 912 912 977 965 915 987 907 919 964 923 884 917 937 912 935 915 1032 912 956 962 960 954 963 959 923 940 922 974 901 948 937 924 948 954 949 948 921 959 943 915 917 933 970 912 966 979 969 917 938 946 937 951 898 915 935 880 954 940 924 971 965 946 980 936 923 966 905 910 937 941 890 913 864 945 953 967 928 896 927 908 960 929 915 898 903 988 915 907 942 892 945 985 960 921 987 947 970 866 977 903 917 936 924 939 860 978 969 992 987 886 910 895 893 959 955 982 948 919 955 921 924 864 905 946 900 969 913 881 1013 911 915 977 890 977 920 928 889 999 919 945 957 967 906 955 892 937 991 888 950 973 943 911 943 969 924 946 948 995 914 917 984 933 881 896 961 926 957 955 895 952 927 963 942 946 896 957 932 978 894 938 999 966 968 907 923 948 943 987 955 977 948 947 947 956 971 962 932 933 956 932 910 927 951 874 925 927 981 949 928 959 895 935 965 931 876 932 960 982 908 935 891 970 937 890 936 906 862 988 915 977 920 940 901 953 924 987 920 918 905 982 926 957 915 968 949 941 967 917 973 951 939 927 911 975 945 891 935 1002 951 927 954 992 869 953 925 934 932 901 1006 990 888 869 983 908 900 885 990 971 941 1012 909 1050 952 941 925 1010 967 970 964 951 868 959 982 921 994 917 990 905 911 956 888 942 909 945 926 920 975 940 929 947 896 959 937 865 935 961 1024 920 985 942 937 911 925 1019 982 978 939 980 971 947 912 906 1004 915 933 939 1011 936 928 945 957 979 992 898 894 965 928 896 951 927 937 943 1027 931 905 961 923 990 933 931 983 960 923 911 924 901 974 939 1004 947 974 1011 966 980 923 991 949 955 991 942 957 979 947 983 1004 955 950 946 942 992 937 948 967 999 908 1019 912 942 936 933 925 932 934 889 922 942 973 901 936 884 948 981 877 908 938 898 959 890 912 971 1015 963 994 949 956 957 960 966 975 950 913 929 931 901 935 935 927 904 1005 909 914 967 926 922 940 959 953 915 983 975 950 929 951 963 911 935 950 959 914 970 933 934 950 967 989 904 952 915 937 953 954 945 903 960 943 1018 970 950 897 896 923 900 934 931 898 963 978 939 965 919 965 906 961 952 923 954 905 932 924 967 923 933 945 948 991 947 982 965 932 906 987 1006 957 909 1050 1010 970 947 943 962 956 981 931 970 996 920 997 969 895 931 1009 928 995 982 946 924 990 1003 1009 1030 1036 969 956 922 932 1004 1045 919 965 936 946 1007 947 954 1013 968 988 983 993 965 1030 973 991 937 965 1004 951 924 976 960 994 998 932 971 955 977 947 922 927 985 982 985 938 923 935 981 921 992 993 980 884 980 997 965 946 934 996 1021 991 970 955 973 970 962 943 987 1046 1011 1015 945 907 1024 1017 1032 1031 1008 994 967 1015 959 928 964 992 960 955 929 970 948 1033 974 1005 963 947 943 909 924 1004 954 1005 964 994 951 935 926 999 969 934 950 928 979 966 929 945 1012 921 927 966 953 946 940 992 969 969 946 1047 922 948 957 969 970 938 929 980 987 933 952 987 1017 1049 925 953 962 982 953 948 945 928 950 907 936 903 1012 896 960 931 973 937 893 971 923 933 919 921 898 950 893 943 932 905 903 904 906 932 955 897 878 984 917 955 942 962 936 974 914 1009 934 919 927 903 1002 896 895 871 976 957 970 910 960 895 870 948 963 960 950 925 962 943 903 934 880 948 907 908 894 948 946 956 918 899 956 947 900 917 915 910 906 923 968 970 888 880 876 896 1023 923 974 1002 837 883 924 950 908 914 910 892 919 891 923 951 953 917 871 910 989 969 969 890 922 947 943 924 919 928 961 918 923 917 1020 919 912 968 937 952 896 908 931 879 842 945 925 941 881 970 922 901 867 921 932 901 879 910 927 886 896 978 911 977 934 921 956 949 961 903 899 876 934 874 917 921 963 957 909 939 939 913 941 891 884 904 938 911 931 898 948 928 939 883 893 934 920 912 882 920 929 906 995 966 920 995 976 888 962 897 939 899 947 931 940 959 988 949 977 963 962 884 895 940 881 929 940 948 906 900 938 931 918 907 897 919 928 950 946 980 997 947 903 904 980 938 980 948 926 909 943 933 914 892 939 950 940 929 910 990 953 919 843 921 933 975 924 933 963 904 907 945 907 955 954 931 934 908 910 908 889 908 877 961 920 932 909 923 971 964 929 977 914 937 929 936 970 945 898 952 945 878 909 899 951 872 927 932 980 927 889 925 926 937 917 949 959 877 936 868 935 890 914 909 908 964 903 933 912 924 954 858 999 950 943 921 964 984 925 904 946 904 911 932 969 935 899 894 960 962 899 924 996 959 1011 924 905 955 984 939 948 945 912 948 962 962 903 974 940 967 946 932 964 950 961 907 971 1006 935 934 936 956 910 979 940 920 951 881 974 988 936 951 959 974 933 929 949 939 991 936 921 959 951 959 934 912 977 941 907 952 979 964 970 961 952 957 957 966 973 928 956 961 981 933 950 970 895 921 993 974 949 907 936 1007 955 928 976 976 961 894 967 942 946 956 914 935 926 999 996 1006 956 935 951 996 934 927 935 966 1001 993 983 997 970 942 924 998 954 962 975 955 941 918 946 995 974 983 941 1006 925 965 928 994 969 934 906 1049 971 1026 1006 1034 922 997 926 980 952 951 933 973 961 962 951 933 1011 976 920 950 932 956 922 992 963 967 901 937 950 996 864 939 886 932 974 960 963 953 943 932 971 982 941 940 977 998 991 999 903 915 931 932 945 927 896 925 926 980 953 990 904 894 897 1007 948 937 878 928 924 933 875 913 922 900 922 951 931 926 999 973 981 857 921 941 925 915 914 890 931 893 911 970 854 921 913 991 941 951 894 998 898 905 922 943 929 874 840 936 882 885 920 968 957 894 913 943 928 844 924 896 964 925 899 956 933 848 914 896 917 867 897 906 976 943 852 912 846 922 840 931 912 932 987 885 874 918 871 962 920 900 912 992 920 938 923 929 974 925 960 892 964 922 991 953 924 979 903 917 909 963 934 900 965 905 900 981 910 931 976 947 888 934 889 960 946 914 880 927 1003 979 937 990 892 897 926 889 957 866 920 893 907 907 955 913 911 942 929 915 987 904 924 915 984 945 895 977 940 938 933 904 922 955 914 963 907 961 955 928 941 954 893 961 979 953 948 957 987 966 934 1021 864 994 947 917 975 936 934 926 968 922 989 979 877 956 937 948 917 977 950 946 979 888 914 912 962 981 973 900 917 895 910 939 920 850 998 1013 982 911 977 943 931 935 899 952 925 899 965 952 910 920 810 928 936 952 905 920 867 950 880 906 889 821 860 906 953 876 917 947 882 921 934 885 925 885 869 968 824 918 910 921 943 908 885 936 896 904 923 926 928 892 976 886 907 810 894 840 870 945 876 959 925 892 918 896 919 922 883 981 928 863 904 924 836 929 961 941 894 939 899 891 893 917 942 933 880 910 957 886 878 952 935 970 963 888 937 885 921 933 912 881 939 915 920 896 932 933 929 889 885 900 922 896 897 923 977 954 937 920 915 940 920 851 921 901 983 905 921 954 928 948 896 923 906 933 924 890 917 943 899 968 885 956 907 888 954 941 947 963 924 977 918 891 922 990 913 904 918 942 871 942 857 900 925 925 921 920 879 933 940 918 959 905 879 862 926 904 935 914 953 934 847 874 898 879 945 855 895 912 891 911 980 917 878 907 885 890 881 949 878 938 905 904 954 919 897 881 881 864 912 954 907 906 889 897 880 879 965 885 925 911 871 908 897 835 910 868 900 935 912 983 891 880 904 901 937 923 968 969 978 889 950 953 900 889 911 889 900 897 924 917 910 917 914 948 871 919 936 915 991 883 925 934 922 907 892 920 890 931 899 872 918 934 945 979 895 937 900 989 913 877 975 913 891 880 952 979 906 896 897 907 904 866 904 918 924 892 919 919 946 894 932 896 927 921 915 908 952 945 903 890 956 872 898 871 892 861 878 904 918 893 954 943 923 891 860 942 948 967 932 943 924 897 933 948 892 924 948 904 963 843 864 921 965 894 900 920 957 861 894 925 914 890 879 898 851 895 897 935 929 890 914 943 961 911 929 928 899 905 901 917 946 900 996 876 931 915 932 939 898 912 911 925 895 936 923 978 941 882 879 940 951 927 896 919 953 899 929 913 941 925 900 994 923 899 912 903 956 954 911 911 941 931 984 932 989 931 947 929 941 953 899 949 878 870 985 970 983 897 891 995 974 949 963 953 994 959 945 945 919 980 976 949 993 949 975 940 900 927 965 955 923 982 961 922 978 961 938 953 964 961 960 998 901 1004 921 966 951 955 992 923 934 945 978 965 969 1034 946 946 997 1005 962 948 968 945 935 900 907 942 967 931 974 892 948 913 925 987 936 947 997 994 947 988 904 997 997 951 907 981 909 921 928 914 947 982 992 957 974 985 911 984 951 933 994 990 1005 936 973 1027 981 962 980 1050 947 921 962 982 1010 1016 950 935 1051 990 1047 980 988 974 953 1021 1033 998 1018 1047 1064 1024 1003 1056 1024 1047 1077 1094 1031 1030 1025 1032 1104 1073 1050 1104 1091 1210 1054 1149 1159 1147 1190 1160 1238 1220 1327 1355 1422 1413 1543 1553 1750 1868 2014 2112 2182 2153 2347 2232 2210 2111 2085 1950 1819 1828 1777 1662 1569 1613 1601 1623 1613 1692 1769 1738 1751 1786 1690 1742 1735 1710 1529 1502 1439 1426 1315 1334 1271 1320 1220 1223 1252 1233 1160 1174 1174 1129 1112 1068 1152 1129 1106 1086 1082 1151 996 1041 1061 1097 1053 1072 1080 1047 1006 1063 1006 970 1049 1061 997 1026 991 993 943 1008 1026 963 917 1009 979 998 1029 961 963 931 974 978 982 968 994 959 975 961 976 977 898 946 977 962 936 1009 957 961 949 945 959 962 924 947 909 937 911 935 893 919 918 1007 936 973 936 891 964 939 909 921 909 945 917 942 953 959 923 951 884 931 893 869 899 978 882 954 911 985 962 951 943 915 894 973 939 941 931 968 925 937 929 931 934 995 917 984 886 928 866 924 895 998 897 963 952 922 932 929 889 870 901 911 906 933 913 989 933 914 920 973 936 900 948 895 920 933 880 942 955 969 879 964 942 927 934 917 990 928 962 925 906 905 868 928 900 840 927 928 939 909 931 945 908 895 978 924 945 912 961 936 920 891 899 918 976 900 941 931 908 918 907 923 964 910 891 918 905 875 939 935 923 874 909 891 918 951 974 903 957 954 874 1012 955 838 898 863 900 919 923 937 963 867 932 951 903 907 923 959 917 896 901 969 947 918 892 977 892 927 997 926 906 819 932 904 861 943 908 919 904 938 881 915 963 879 919 919 957 937 889 956 962 919 965 922 907 897 905 931 963 835 966 889 941 874 912 890 962 933 905 967 882 861 950 938 968 960 905 892 917 924 954 962 920 960 948 904 988 951 981 907 934 907 883 937 992 837 971 948 967 934 950 935 907 939 883 917 982 855 864 922 914 917 926 918 963 932 900 903 885 890 910 872 952 932 906 924 945 919 926 885 956 918 928 872 979 913 949 928 974 903 877 898 931 895 971 920 955 959 892 880 946 919 941 955 919 884 904 920 967 943 928 942 933 957 941 927 922 993 966 912 982 921 984 885 917 890 903 924 1013 921 1005 932 939 904 974 911 915 941 927 976 940 911 970 939 988 893 954 967 1021 978 957 985 969 880 910 931 939 920 909 911 1026 898 921 905 964 941 917 942 946 945 971 882 985 918 965 881 1018 948 898 936 961 861 885 969 918 920 909 885 878 907 940 910 904 960 953 966 927 925 963 924 920 933 984 940 925 956 946 941 931 924 897 921 947 970 917 937 913 959 923 921 918 906 941 947 893 940 922 922 909 912 925 894 856 984 905 867 983 912 934 976 964 923 890 933 981 941 963 967 903 920 862 978 952 932 975 963 920 945 920 1005 979 969 926 933 938 1016 917 933 942 912 976 908 996 923 966 886 998 990 979 998 912 987 971 1004 953 913 946 1004 968 973 968 922 953 987 979 953 924 939 999 945 962 929 1002 932 922 937 928 961 885 956 956 937 964 927 945 983 992 969 932 961 976 969 942 964 978 987 981 918 994 1048 1030 963 968 946 929 993 938 1003 957 996 996 985 959 911 917 996 957 957 951 975 976 948 954 994 846 991 959 956 937 988 947 947 998 968 935 992 994 978 1001 966 939 978 1034 993 969 929 976 966 963 893 980 962 959 898 978 959 903 922 947 922 962 913 981 909 942 955 994 940 901 927 966 984 926 855 968 959 929 891 960 974 952 895 954 954 948 928 894 942 928 885 942 969 936 934 974 953 1006 903 949 932 926 913 1009 952 955 948 900 959 935 901 938 964 968 938 954 964 892 918 926 949 988 936 948 943 957 966 946 977 909 898 1005 888 953 927 966 975 991 995 948 901 975 921 885 906 962 996 914 996 940 928 973 879 1006 897 971 901 900 959 966 878 981 959 891 946 895 839 937 967 943 982 917 896 1019 919 904 913 955 955 890 929 950 919 934 969 910 936 896 976 893 951 965 956 938 962 1002 926 871 931 891 914 924 901 1017 938 868 921 904 926 956 933 929 890 910 933 959 906 956 943 966 909 915 987 971 938 929 900 922 871 998 917 934 957 894 942 924 994 893 959 924 904 925 935 890 908 915 926 923 914 987 989 959 928 943 977 924 920 953 945 909 960 981 979 897 945 954 940 918 914 966 938 936 966 915 918 950 911 969 954 868 914 920 933 936 923 913 975 911 945 939 1013 1001 899 1046 943 876 950 893 957 933 910 943 996 935 969 962 984 901 1006 934 962 951 987 952 982 924 920 975 957 898 995 946 945 971 954 903 923 934 954 968 962 921 968 941 1051 948 939 898 971 914 965 893 929 937 923 935 977 953 1007 886 983 905 929 950 1017 1003 941 931 961 925 1018 964 911 948 925 914 998 959 962 904 936 927 952 937 946 951 905 891 929 947 933 921 975 960 992 977 947 918 970 1010 898 935 879 974 957 961 963 914 919 979 927 911 961 964 956 956 992 928 920 881 922 907 988 925 975 929 963 855 970 877 918 949 937 983 941 935 983 927 965 961 975 965 952 973 957 973 933 880 1012 994 922 942 985 982 914 935 983 947 934 1017 927 971 985 907 996 967 921 910 1001 919 933 922 938 985 893 932 974 931 939 979 959 933 976 937 961 905 938 931 955 971 971 960 915 966 900 950 941 883 900 904 896 869 960 919 900 932 918 988 941 897 915 919 967 932 988 946 932 909 922 915 963 915 913 974 953 901 936 915 979 941 905 926 921 948 926 974 982 901 948 919 914 948 920 961 911 965 938 948 931 999 937 931 983 998 957 947 926 892 849 918 974 973 959 973 918 950 926 912 932 956 971 988 964 914 908 917 952 995 934 996 937 928 915 971 919 908 906 939 909 939 967 967 920 945 917 960 951 996 962 923 928 934 908 933 932 947 938 836 939 898 927 934 920 938 992 879 897 914 861 952 923 951 918 992 943 928 919 991 906 967 946 934 935 960 889 953 904 941 955 966 895 954 960 905 969 936 871 964 947 983 860 935 951 922 949 937 947 937 968 934 956 941 927 957 921 940 911 915 953 933 895 911 957 911 928 914 896 926 905 950 937 947 953 900 940 928 961 915 888 979 908 884 889 984 973 931 892 967 932 995 914 959 974 966 980 912 926 989 950 943 910 938 911 914 877 998 881 889 953 913 929 954 894 953 919 946 943 989 955 950 935 928 911 879 926 983 963 938 897 954 1003 896 877 881 999 1013 948 965 971 959 894 943 923 961 925 947 907 1030 943 961 965 937 934 947 969 934 883 935 921 968 946 952 921 961 929 940 960 936 966 966 966 974 919 934 924 913 989 977 954 1001 933 989 971 957 889 999 971 940 989 973 923 945 1019 948 985 1006 1001 979 952 990 954 969 886 979 974 964 922 955 954 936 874 989 929 990 976 977 983 950 952 892 974 945 940 1019 945 982 907 962 1047 937 934 954 971 938 941 1005 919 948 995 956 964 969 931 1016 942 910 1064 952 967 997 985 969 888 974 959 973 942 945 977 968 949 946 988 1001 926 921 1020 1029 940 973 953 993 1009 924 997 974 932 1020 1027 1002 1005 1072 941 955 1026 966 984 967 1031 994 952 955 1032 996 1003 950 1048 921 966 998 1041 990 981 977 1029 988 992 1002 987 1017 949 1024 936 1005 977 963 983 906 938 970 980 981 997 979 968 1019 1011 996 998 1007 957 940 1046 941 961 987 977 1011 1021 936 1045 974 951 952 978 959 956 937 1033 1001 968 1007 1064 969 981 1013 1015 977 971 1036 947 948 1004 983 1003 1026 1035 955 968 1020 1035 931 991 1056 969 1011 987 1052 979 925 1036 983 1048 1011 1037 1059 1083 1009 1024 1047 980 1065 963 1040 1033 1068 1061 1083 1040 1038 1079 1069 1082 1055 1041 1128 1076 1062 1107 1075 1110 1049 1074 1084 1065 1090 1114 1083 1076 1145 1090 1103 1061 1078 1179 1091 1149 1120 1168 1105 1142 1124 1197 1106 1094 1220 1179 1140 1126 1124 1186 1166 1177 1179 1203 1211 1200 1200 1163 1135 1167 1090 1251 1137 1224 1237 1174 1210 1165 1231 1187 1233 1160 1197 1284 1275 1246 1208 1330 1270 1262 1318 1301 1337 1334 1373 1398 1393 1372 1419 1420 1425 1525 1470 1525 1640 1709 1676 1840 1807 1965 1926 2096 2215 2326 2425 2570 2702 2733 2965 2948 3133 3115 3139 3266 3156 3153 3079 3039 2953 2829 2806 2642 2641 2510 2395 2334 2266 2307 2333 2216 2231 2224 2286 2369 2274 2369 2304 2267 2352 2323 2416 2304 2341 2288 2377 2210 2247 2117 2125 2062 1906 1901 1868 1748 1696 1760 1597 1616 1662 1542 1503 1541 1496 1507 1412 1471 1365 1387 1363 1363 1360 1373 1287 1271 1283 1356 1334 1279 1244 1291 1288 1275 1223 1329 1196 1222 1201 1228 1250 1157 1286 1170 1210 1259 1173 1231 1124 1158 1218 1144 1162 1088 1125 1109 1140 1151 1067 1076 1185 1103 1108 1086 1074 1120 1069 1119 1100 1022 1088 1030 1087 1092 1103 1024 1087 1077 948 1003 1038 1081 1064 1030 1023 1063 994 1024 997 1034 1054 1060 1032 1018 965 998 1023 1042 1024 1036 996 984 999 1046 1059 1015 981 1021 1039 967 989 990 952 1016 1013 977 954 996 1037 991 1011 1007 1050 1084 977 995 939 968 984 967 978 918 1003 991 950 945 1017 969 937 973 1010 995 981 1035 1040 996 947 981 962 925 935 990 948 920 906 984 1013 968 1020 988 959 990 1004 990 979 974 1001 957 971 963 946 959 973 1032 966 1012 987 923 911 896 931 961 912 941 988 989 942 920 956 948 993 954 989 980 975 954 996 960 953 953 947 913 1004 908 1012 897 953 883 1004 942 938 956 983 903 955 974 969 933 1001 977 962 957 937 892 945 971 918 966 949 957 1027 956 1048 989 965 895 955 985 946 955 950 1002 965 942 961 950 963 963 998 913 1039 941 1016 980 970 920 965 881 991 956 919 943 980 937 959 947 904 935 936 905 957 970 995 917 1009 960 942 922 997 960 946 982 991 938 980 948 961 914 954 946 1009 953 967 917 976 933 957 924 955 912 971 996 941 938 973 967 1007 945 967 959 989 949 935 975 918 926 1046 886 996 912 951 948 957 1037 941 985 959 961 919 945 926 908 1018 999 956 985 928 975 984 979 968 924 1007 1037 1013 962 974 991 951 947 921 999 967 977 985 957 965 987 997 960 983 929 961 990 918 945 941 961 933 967 945 969 838 982 964 943 1025 987 1001 954 954 921 1003 931 939 970 1030 936 932 982 1026 964 1019 980 976 961 957 964 954 947 976 982 921 948 931 977 969 937 974 951 1031 1027 954 967 993 1007 993 931 950 966 1029 939 1013 1024 998 991 981 1019 937 971 978 957 1030 942 1027 979 1013 961 921 1029 992 988 1030 954 946 962 992 973 950 993 967 1016 955 1038 943 943 1019 939 975 976 951 941 937 977 1013 957 998 1004 975 923 960 970 950 1008 927 1027 997 966 1033 1011 896 947 1002 989 978 957 980 977 939 965 1015 981 947 919 974 993 1032 894 964 961 945 985 981 1004 941 1013 934 953 913 950 997 976 1021 953 963 967 952 1012 995 968 942 979 1003 1021 931 947 962 969 948 1022 1005 945 1038 922 979 970 991 912 978 991 990 1017 1015 1007 955 946 1009 997 995 1009 1032 938 961 914 995 991 998 939 954 990 1031 999 1033 981 965 965 997 1050 1021 968 1006 975 1036 1024 1021 1008 1110 1042 1048 1075 1125 1089 1135 1112 1087 1152 1137 1185 1159 1176 1148 1144 1118 1082 1118 1091 1101 1111 1105 1081 1078 1070 1063 1058 1017 1114 1027 1050 1020 1045 1084 1091 1068 1079 1115 1137 1102 1079 1076 1093 1082 1094 1152 1049 1074 1082 1123 1103 1037 1029 1055 1027 1066 1015 1025 1108 1025 981 987 1066 945 1019 1034 1024 1034 975 1032 997 1007 1010 991 1001 946 985 929 968 978 940 990 1017 994 984 987 1068 948 991 1047 1020 1004 938 925 968 981 979 962 1009 935 969 988 953 936 969 956 1006 966 1027 969 970 969 957 912 978 921 966 995 918 973 1025 990 950 965 971 954 945 988 991 922 938 1005 938 936 1013 950 928 977 942 952 947 995 965 950 909 1035 1016 979 988 933 966 933 967 948 965 978 981 1008 971 926 998 954 933 977 960 947 1009 998 1001 928 971 968 938 974 1020 948 1001 943 967 1016 1046 913 948 953 936 937 956 983 924 929 983 991 947 953 954 920 893 955 928 940 989 1012 932 924 904 919 947 946 946 935 962 928 1048 922 942 918 959 967 956 950 910 982 929 924 914 957 945 956 987 929 992 921 946 950 977 960 968 968 1007 981 979 948 963 974 1012 974 940 990 921 994 856 1018 945 949 979 956 967 1011 980 953 999 927 929 957 970 907 950 974 992 914 950 904 977 992 999 959 973 968 936 980 883 942 961 883 960 955 941 914 954 919 969 918 945 976 960 913 949 941 940 905 895 928 965 933 1023 998 989 933 903 933 965 949 915 912 969 964 939 922 999 905 971 960 956 920 946 898 981 935 921 936 964 910 914 877 981 957 901 946 929 858 974 955 952 919 893 948 929 908 925 1016 1007 866 949 968 961 943 991 956 955 884 876 947 955 928 904 909 1017 904 935 940 956 910 881 959 870 931 914 997 956 898 946 962 966 936 923 984 996 915 929 954 880 901 937 931 1032 919 938 987 999 927 948 891 984 923 948 938 942 876 929 981 967 931 948 912 982 886 952 934 940 862 938 894 989 867 927 918 1008 907 907 943 1027 914 941 970 896 951 907 983 910 909 945 1025 949 895 975 1027 927 914 897 965 951 942 889 990 896 957 875 996 965 982 949 961 939 946 934 911 929 934 912 985 957 900 935 942 983 915 879 911 865 963 971 940 1005 923 948 929 909 1017 935 974 951 966 996 967 943 935 954 920 936 961 883 935 889 980 933 933 946 957 936 946 906 939 927 946 989 982 927 950 993 1006 1003 939 954 897 982 909 931 1007 933 948 949 989 913 969 909 956 911 984 995 956 948 914 938 968 954 1015 999 922 908 970 951 940 985 956 942 977 978 941 943 1001 914 974 1001 907 949 1013 966 946 893 953 913 978 974 957 992 936 931 928 891 934 904 936 949 965 957 892 971 1016 961 919 994 875 941 961 989 931 1005 961 995 953 915 960 945 959 927 923 948 935 929 1010 949 939 936 932 939 945 994 951 959 875 933 941 964 949 936 1006 914 952 975 948 888 979 912 963 996 964 918 1004 919 973 964 982 970 974 964 981 1011 1034 950 965 896 899 927 936 951 948 953 967 954 955 919 989 957 921 904 905 970 918 905 957 1002 932 1018 988 983 947 965 957 991 903 945 968 961 946 950 945 1009 900 976 998 928 973 892 932 947 900 905 940 959 918 950 900 882 936 965 908 918 923 966 976 937 875 950 898 897 952 879 961 903 889 975 932 914 896 912 957 990 943 946 955 957 959 970 879 970 945 999 959 920 942 905 961 953 909 878 941 894 864 946 964 982 928 917 975 936 934 997 943 932 951 866 963 981 968 912 921 943 943 893 926 925 922 952 953 939 931 952 947 909 932 912 941 973 917 897 884 901 971 949 963 953 955 973 904 948 938 971 924 906 989 931 890 911 950 935 971 896 918 928 973 892 947 973 949 937 892 912 951 981 929 940 956 869 975 931 847 921 894 940 933 942 934 885 941 950 932 920 903 925 981 941 949 891 947 884 951 974 884 905 917 963 904 895 913 932 928 990 948 927 966 892 948 892 955 935 908 921 935 935 1007 913 904 915 945 878 901 938 917 924 929 945 929 962 911 1001 905 970 935 974 918 947</intensities>
			</dataPoints>
		</scan>
	</xrdMeasurement>
</xrdMeasurements>